NAMESPACE                     LAST SEEN   TYPE      REASON                                   OBJECT                                                             MESSAGE
kube-system                   41m         Normal    LeaderElection                           lease/kube-scheduler                                               gke-a4ad5f791ee9462391e0-79d6-e40e-vm_870923bb-78b5-42d0-9f07-a021a4782a15 became leader
kube-system                   41m         Normal    LeaderElection                           lease/kube-controller-manager                                      gke-a4ad5f791ee9462391e0-79d6-e40e-vm_6ff69537-8dd2-4104-8aec-73f64f335494 became leader
kube-system                   41m         Normal    LeaderElection                           lease/addon-manager                                                gke-a4ad5f791ee9462391e0-79d6-e40e-vm_c87ea6ce-21c9-45b6-9145-0957ae15b6cd became leader
kube-system                   41m         Normal    ScalingReplicaSet                        deployment/kube-dns                                                Scaled up replica set kube-dns-78d5d95979 from 0 to 1
kube-system                   41m         Warning   FailedCreate                             replicaset/kube-dns-78d5d95979                                     Error creating: insufficient quota to match these scopes: [{PriorityClass In [system-node-critical system-cluster-critical]}]
kube-system                   40m         Warning   FailedScheduling                         pod/kube-dns-78d5d95979-p2v8j                                      no nodes available to schedule pods
kube-system                   41m         Normal    SuccessfulCreate                         replicaset/kube-dns-78d5d95979                                     Created pod: kube-dns-78d5d95979-p2v8j
gke-managed-cim               41m         Warning   FailedCreate                             statefulset/kube-state-metrics                                     Create Pod kube-state-metrics-0 in StatefulSet kube-state-metrics failed error: pods "kube-state-metrics-0" is forbidden: error looking up service account gke-managed-cim/kube-state-metrics: serviceaccount "kube-state-metrics" not found
gke-managed-cim               38m         Normal    SuccessfulCreate                         statefulset/kube-state-metrics                                     Create Pod kube-state-metrics-0 in StatefulSet kube-state-metrics successful
gke-managed-cim               40m         Warning   FailedScheduling                         pod/kube-state-metrics-0                                           no nodes available to schedule pods
kube-system                   41m         Normal    LeaderElection                           lease/clustermetrics                                               gke-a4ad5f791ee9462391e0-79d6-e40e-vm became leader
kube-system                   41m         Normal    SuccessfulCreate                         replicaset/event-exporter-gke-7dc55f4f5f                           Created pod: event-exporter-gke-7dc55f4f5f-6k5kj
kube-system                   40m         Warning   FailedScheduling                         pod/event-exporter-gke-7dc55f4f5f-6k5kj                            no nodes available to schedule pods
kube-system                   41m         Normal    ScalingReplicaSet                        deployment/event-exporter-gke                                      Scaled up replica set event-exporter-gke-7dc55f4f5f from 0 to 1
kube-system                   40m         Normal    LeaderElection                           lease/gcp-controller-manager                                       gke-a4ad5f791ee9462391e0-79d6-e40e-vm became leader
kube-system                   40m         Normal    LeaderElection                           lease/gke-common-webhook-lock                                      gke-a4ad5f791ee9462391e0-79d6-e40e-vm_77ad0 became leader
kube-system                   40m         Normal    LeaderElection                           lease/cluster-autoscaler                                           gke-a4ad5f791ee9462391e0-79d6-e40e-vm became leader
kube-system                   40m         Normal    LeaderElection                           lease/cloud-provider-extraction-migration-pt2                      gke-a4ad5f791ee9462391e0-79d6-e40e-vm_401fb704-7fb4-4b3f-bc82-adbfe8338c22 became leader
kube-system                   40m         Normal    LeaderElection                           lease/cloud-controller-manager                                     gke-a4ad5f791ee9462391e0-79d6-e40e-vm_401fb704-7fb4-4b3f-bc82-adbfe8338c22 became leader
gke-managed-volumepopulator   40m         Normal    LeaderElection                           lease/gke-volume-populator-leader                                  gke-a4ad5f791ee9462391e0-79d6-e40e-vm became leader
kube-system                   40m         Warning   FailedScheduling                         pod/konnectivity-agent-5446844985-k8xgt                            no nodes available to schedule pods
kube-system                   40m         Normal    SuccessfulCreate                         replicaset/konnectivity-agent-5446844985                           Created pod: konnectivity-agent-5446844985-k8xgt
kube-system                   40m         Normal    ScalingReplicaSet                        deployment/konnectivity-agent                                      Scaled up replica set konnectivity-agent-5446844985 from 0 to 1
kube-system                   40m         Warning   FailedScheduling                         pod/konnectivity-agent-autoscaler-685569f784-wxl9g                 no nodes available to schedule pods
kube-system                   40m         Normal    SuccessfulCreate                         replicaset/konnectivity-agent-autoscaler-685569f784                Created pod: konnectivity-agent-autoscaler-685569f784-wxl9g
kube-system                   40m         Normal    ScalingReplicaSet                        deployment/konnectivity-agent-autoscaler                           Scaled up replica set konnectivity-agent-autoscaler-685569f784 from 0 to 1
kube-system                   40m         Normal    ScalingReplicaSet                        deployment/kube-dns-autoscaler                                     Scaled up replica set kube-dns-autoscaler-5dc7b666d8 from 0 to 1
kube-system                   40m         Normal    SuccessfulCreate                         replicaset/kube-dns-autoscaler-5dc7b666d8                          Created pod: kube-dns-autoscaler-5dc7b666d8-wp4pz
kube-system                   40m         Warning   FailedScheduling                         pod/kube-dns-autoscaler-5dc7b666d8-wp4pz                           no nodes available to schedule pods
kube-system                   40m         Warning   FailedScheduling                         pod/l7-default-backend-58ffbbd58-wvskg                             no nodes available to schedule pods
kube-system                   40m         Normal    LeaderElection                           lease/cluster-kubestore                                            gke-a4ad5f791ee9462391e0-79d6-e40e-vm became leader
kube-system                   40m         Normal    ScalingReplicaSet                        deployment/l7-default-backend                                      Scaled up replica set l7-default-backend-58ffbbd58 from 0 to 1
kube-system                   40m         Normal    SuccessfulCreate                         replicaset/l7-default-backend-58ffbbd58                            Created pod: l7-default-backend-58ffbbd58-wvskg
kube-system                   40m         Normal    LeaderElection                           lease/maintenance-controller                                       gke-a4ad5f791ee9462391e0-79d6-e40e-vm_a01c0799-4feb-4d7c-a271-a5ebb4d980d5 became leader
kube-system                   40m         Normal    LeaderElection                           lease/l4-lb-controller-gce-lock                                    gke-a4ad5f791ee9462391e0-79d6-e40e-vm_4d300 became leader
kube-system                   40m         Normal    LeaderElection                           lease/ingress-gce-neg-lock                                         gke-a4ad5f791ee9462391e0-79d6-e40e-vm_f3536 became leader
kube-system                   40m         Normal    LeaderElection                           lease/ingress-gce-lock                                             gke-a4ad5f791ee9462391e0-79d6-e40e-vm_3290c became leader
gmp-system                    40m         Normal    ScalingReplicaSet                        deployment/gmp-operator                                            Scaled up replica set gmp-operator-6875fdf876 from 0 to 1
gmp-system                    40m         Warning   FailedScheduling                         pod/gmp-operator-6875fdf876-rlwlh                                  no nodes available to schedule pods
gmp-system                    40m         Normal    SuccessfulCreate                         replicaset/gmp-operator-6875fdf876                                 Created pod: gmp-operator-6875fdf876-rlwlh
gmp-system                    39m         Normal    SuccessfulCreate                         statefulset/alertmanager                                           Create Pod alertmanager-0 in StatefulSet alertmanager successful
gmp-system                    40m         Warning   FailedScheduling                         pod/rule-evaluator-79c78c4fd5-4q9kw                                no nodes available to schedule pods
gmp-system                    40m         Warning   FailedScheduling                         pod/alertmanager-0                                                 no nodes available to schedule pods
gmp-system                    40m         Normal    ScalingReplicaSet                        deployment/rule-evaluator                                          Scaled up replica set rule-evaluator-79c78c4fd5 from 0 to 1
gmp-system                    40m         Normal    SuccessfulCreate                         replicaset/rule-evaluator-79c78c4fd5                               Created pod: rule-evaluator-79c78c4fd5-4q9kw
kube-system                   40m         Normal    ScalingReplicaSet                        deployment/metrics-server-v1.35.1                                  Scaled up replica set metrics-server-v1.35.1-6559d8569d from 0 to 1
kube-system                   40m         Warning   FailedCreate                             replicaset/metrics-server-v1.35.1-6559d8569d                       Error creating: pods "metrics-server-v1.35.1-6559d8569d-" is forbidden: error looking up service account kube-system/metrics-server: serviceaccount "metrics-server" not found
kube-system                   40m         Normal    SuccessfulCreate                         replicaset/metrics-server-v1.35.1-6559d8569d                       Created pod: metrics-server-v1.35.1-6559d8569d-c2m47
kube-system                   40m         Warning   FailedScheduling                         pod/metrics-server-v1.35.1-6559d8569d-c2m47                        no nodes available to schedule pods
kube-system                   40m         Normal    LeaderElection                           lease/addon-resizer                                                gke-a4ad5f791ee9462391e0-79d6-e40e-vm became leader
kube-system                   40m         Normal    ScalingReplicaSet                        deployment/metrics-server-v1.35.1                                  Scaled up replica set metrics-server-v1.35.1-78f45667d from 0 to 1
kube-system                   40m         Normal    SuccessfulCreate                         replicaset/metrics-server-v1.35.1-78f45667d                        Created pod: metrics-server-v1.35.1-78f45667d-ptnww
kube-system                   40m         Warning   FailedScheduling                         pod/metrics-server-v1.35.1-78f45667d-ptnww                         no nodes available to schedule pods
kube-system                   40m         Warning   FailedScheduling                         pod/antrea-controller-horizontal-autoscaler-5f556bf8c6-w4z9q       no nodes available to schedule pods
kube-system                   40m         Normal    SuccessfulCreate                         replicaset/antrea-controller-horizontal-autoscaler-5f556bf8c6      Created pod: antrea-controller-horizontal-autoscaler-5f556bf8c6-w4z9q
kube-system                   40m         Normal    ScalingReplicaSet                        deployment/antrea-controller-horizontal-autoscaler                 Scaled up replica set antrea-controller-horizontal-autoscaler-5f556bf8c6 from 0 to 1
kube-system                   40m         Normal    Scheduled                                pod/netd-drwst                                                     Successfully assigned kube-system/netd-drwst to gke-portable-voting-default-pool-2393733d-3flq
kube-system                   40m         Normal    Scheduled                                pod/anetd-2r7gz                                                    Successfully assigned kube-system/anetd-2r7gz to gke-portable-voting-default-pool-2393733d-3flq
gmp-system                    40m         Normal    Scheduled                                pod/collector-f27hc                                                Successfully assigned gmp-system/collector-f27hc to gke-portable-voting-default-pool-2393733d-3flq
kube-system                   40m         Normal    SuccessfulCreate                         daemonset/netd                                                     Created pod: netd-drwst
gmp-system                    40m         Normal    SuccessfulCreate                         daemonset/collector                                                Created pod: collector-f27hc
kube-system                   40m         Normal    SuccessfulCreate                         daemonset/gke-metrics-agent                                        Created pod: gke-metrics-agent-wrvtz
default                       40m         Normal    Synced                                   node/gke-portable-voting-default-pool-2393733d-3flq                Node synced successfully
kube-system                   40m         Normal    SuccessfulCreate                         daemonset/fluentbit-gke                                            Created pod: fluentbit-gke-lbhr6
kube-system                   40m         Normal    Scheduled                                pod/gke-metrics-agent-wrvtz                                        Successfully assigned kube-system/gke-metrics-agent-wrvtz to gke-portable-voting-default-pool-2393733d-3flq
kube-system                   40m         Normal    Scheduled                                pod/node-local-dns-6t5fg                                           Successfully assigned kube-system/node-local-dns-6t5fg to gke-portable-voting-default-pool-2393733d-3flq
kube-system                   40m         Normal    SuccessfulCreate                         daemonset/anetd                                                    Created pod: anetd-2r7gz
kube-system                   40m         Warning   FailedScheduling                         pod/konnectivity-agent-5446844985-k8xgt                            0/1 nodes are available: 1 node(s) had untolerated taint(s). no new claims to deallocate, preemption: 0/1 nodes are available: 1 Preemption is not helpful for scheduling.
default                       40m         Warning   ContainerdStart                          node/gke-portable-voting-default-pool-2393733d-3flq                Starting containerd.service...
default                       40m         Warning   ReadOnlyFileSystemDetected               node/gke-portable-voting-default-pool-2393733d-3flq
kube-system                   40m         Normal    Scheduled                                pod/fluentbit-gke-lbhr6                                            Successfully assigned kube-system/fluentbit-gke-lbhr6 to gke-portable-voting-default-pool-2393733d-3flq
kube-system                   40m         Warning   FailedScheduling                         pod/antrea-controller-horizontal-autoscaler-5f556bf8c6-w4z9q       0/1 nodes are available: 1 node(s) had untolerated taint(s). no new claims to deallocate, preemption: 0/1 nodes are available: 1 Preemption is not helpful for scheduling.
default                       40m         Warning   DockerStart                              node/gke-portable-voting-default-pool-2393733d-3flq                Starting docker.service...
default                       40m         Warning   NodeRegistrationCheckerStart             node/gke-portable-voting-default-pool-2393733d-3flq                Thu Aug 20 10:11:00 UTC 2026 - ** Starting Node Registration Checker **
default                       40m         Warning   KubeletStart                             node/gke-portable-voting-default-pool-2393733d-3flq                Started kubelet.service.
default                       40m         Warning   NodeSysctlChange                         node/gke-portable-voting-default-pool-2393733d-3flq                Node condition SysctlChanged is now: True, reason: NodeSysctlChange, message: "{\"unmanaged\": {\"kernel.cad_pid\": \"1\"}}"
kube-system                   40m         Normal    SuccessfulCreate                         daemonset/node-local-dns                                           Created pod: node-local-dns-6t5fg
kube-system                   39m         Warning   FailedScheduling                         pod/event-exporter-gke-7dc55f4f5f-6k5kj                            0/1 nodes are available: 1 node(s) had untolerated taint(s). no new claims to deallocate, preemption: 0/1 nodes are available: 1 Preemption is not helpful for scheduling.
gke-managed-cim               39m         Warning   FailedScheduling                         pod/kube-state-metrics-0                                           0/1 nodes are available: 1 node(s) had untolerated taint(s). no new claims to deallocate, preemption: 0/1 nodes are available: 1 Preemption is not helpful for scheduling.
default                       39m         Normal    RegisteredNode                           node/gke-portable-voting-default-pool-2393733d-3flq                Node gke-portable-voting-default-pool-2393733d-3flq event: Registered Node gke-portable-voting-default-pool-2393733d-3flq in Controller
kube-system                   39m         Warning   FailedScheduling                         pod/konnectivity-agent-autoscaler-685569f784-wxl9g                 0/1 nodes are available: 1 node(s) had untolerated taint(s). no new claims to deallocate, preemption: 0/1 nodes are available: 1 Preemption is not helpful for scheduling.
default                       41m         Normal    NodeAllocatableEnforced                  node/gke-portable-voting-default-pool-2393733d-3flq                Updated Node Allocatable limit across pods
default                       40m         Normal    NodeHasNoDiskPressure                    node/gke-portable-voting-default-pool-2393733d-3flq                Node gke-portable-voting-default-pool-2393733d-3flq status is now: NodeHasNoDiskPressure
default                       41m         Normal    Starting                                 node/gke-portable-voting-default-pool-2393733d-3flq                Starting kubelet.
kube-system                   39m         Warning   FailedScheduling                         pod/metrics-server-v1.35.1-6559d8569d-c2m47                        0/1 nodes are available: 1 node(s) had untolerated taint(s). no new claims to deallocate, preemption: 0/1 nodes are available: 1 Preemption is not helpful for scheduling.
default                       40m         Normal    NodeHasSufficientPID                     node/gke-portable-voting-default-pool-2393733d-3flq                Node gke-portable-voting-default-pool-2393733d-3flq status is now: NodeHasSufficientPID
default                       40m         Normal    NodeHasSufficientMemory                  node/gke-portable-voting-default-pool-2393733d-3flq                Node gke-portable-voting-default-pool-2393733d-3flq status is now: NodeHasSufficientMemory
default                       41m         Warning   InvalidDiskCapacity                      node/gke-portable-voting-default-pool-2393733d-3flq                invalid capacity 0 on image filesystem
kube-system                   39m         Warning   FailedScheduling                         pod/kube-dns-autoscaler-5dc7b666d8-wp4pz                           0/1 nodes are available: 1 node(s) had untolerated taint(s). no new claims to deallocate, preemption: 0/1 nodes are available: 1 Preemption is not helpful for scheduling.
gmp-system                    39m         Warning   FailedScheduling                         pod/gmp-operator-6875fdf876-rlwlh                                  0/1 nodes are available: 1 node(s) had untolerated taint(s). no new claims to deallocate, preemption: 0/1 nodes are available: 1 Preemption is not helpful for scheduling.
kube-system                   39m         Normal    LeaderElection                           lease/external-resizer-pd-csi-storage-gke-io                       gke-a4ad5f791ee9462391e0-79d6-e40e-vm became leader
gmp-system                    39m         Warning   FailedScheduling                         pod/rule-evaluator-79c78c4fd5-4q9kw                                0/1 nodes are available: 1 node(s) had untolerated taint(s). no new claims to deallocate, preemption: 0/1 nodes are available: 1 Preemption is not helpful for scheduling.
kube-system                   39m         Warning   FailedMount                              pod/node-local-dns-6t5fg                                           MountVolume.SetUp failed for volume "config-volume" : object "kube-system"/"node-local-dns" not registered
gmp-system                    39m         Warning   FailedScheduling                         pod/alertmanager-0                                                 0/1 nodes are available: 1 node(s) had untolerated taint(s). no new claims to deallocate, preemption: 0/1 nodes are available: 1 Preemption is not helpful for scheduling.
kube-system                   39m         Normal    LeaderElection                           lease/external-attacher-leader-pd-csi-storage-gke-io               gke-a4ad5f791ee9462391e0-79d6-e40e-vm became leader
kube-system                   39m         Normal    LeaderElection                           lease/pd-csi-storage-gke-io                                        1787220640589-1996-pd-csi-storage-gke-io became leader
gmp-system                    39m         Warning   NetworkNotReady                          pod/collector-f27hc                                                network is not ready: container runtime network not ready: NetworkReady=false reason:NetworkPluginNotReady message:Network plugin returns error: cni plugin not initialized
gmp-system                    39m         Warning   FailedMount                              pod/collector-f27hc                                                MountVolume.SetUp failed for volume "config" : object "gmp-system"/"collector" not registered
gmp-system                    39m         Warning   FailedMount                              pod/collector-f27hc                                                MountVolume.SetUp failed for volume "collection-secret" : object "gmp-system"/"collection" not registered
gmp-system                    39m         Warning   FailedMount                              pod/collector-f27hc                                                MountVolume.SetUp failed for volume "kube-api-access-4hhpt" : object "gmp-system"/"kube-root-ca.crt" not registered
kube-system                   39m         Warning   FailedScheduling                         pod/metrics-server-v1.35.1-78f45667d-ptnww                         0/1 nodes are available: 1 node(s) had untolerated taint(s). no new claims to deallocate, preemption: 0/1 nodes are available: 1 Preemption is not helpful for scheduling.
kube-system                   39m         Warning   NetworkNotReady                          pod/node-local-dns-6t5fg                                           network is not ready: container runtime network not ready: NetworkReady=false reason:NetworkPluginNotReady message:Network plugin returns error: cni plugin not initialized
kube-system                   39m         Warning   FailedMount                              pod/node-local-dns-6t5fg                                           MountVolume.SetUp failed for volume "kube-dns-config" : object "kube-system"/"kube-dns" not registered
kube-system                   39m         Warning   FailedMount                              pod/node-local-dns-6t5fg                                           MountVolume.SetUp failed for volume "nodelocaldns-metrics-collector-config-map-vol" : object "kube-system"/"nodelocaldns-metrics-collector-config-map" not registered
kube-system                   39m         Warning   FailedScheduling                         pod/kube-dns-78d5d95979-p2v8j                                      0/1 nodes are available: 1 node(s) had untolerated taint(s). no new claims to deallocate, preemption: 0/1 nodes are available: 1 Preemption is not helpful for scheduling.
kube-system                   39m         Normal    Pulled                                   pod/netd-drwst                                                     Container image "europe-west3-artifactregistry.gcr.io/gke-release/gke-release/netd-init:v0.10.12-gke.16@sha256:7c17ea472a942f1c612d26e240c15c79d9d0e9d4339010983785563559a11cdc" already present on machine and can be accessed by the pod
kube-system                   39m         Normal    Pulled                                   pod/anetd-2r7gz                                                    Container image "europe-west3-artifactregistry.gcr.io/gke-release/gke-release/anet/cni-writer:v0.1.40-gke.0@sha256:67f53cef809fb894cad4b99137539fe57f46a6a1e0346b1cd1f598fd92801093" already present on machine and can be accessed by the pod
kube-system                   39m         Normal    SuccessfulCreate                         daemonset/pdcsi-node                                               Created pod: pdcsi-node-nc9f9
kube-system                   39m         Warning   FailedMount                              pod/pdcsi-node-nc9f9                                               MountVolume.SetUp failed for volume "pdcsi-metrics-collector-config-map-vol" : configmap "pdcsi-metrics-collector-config-map" not found
kube-system                   39m         Normal    Scheduled                                pod/pdcsi-node-nc9f9                                               Successfully assigned kube-system/pdcsi-node-nc9f9 to gke-portable-voting-default-pool-2393733d-3flq
kube-system                   39m         Normal    Pulled                                   pod/anetd-2r7gz                                                    Container image "europe-west3-artifactregistry.gcr.io/gke-release/gke-release/cilium/cilium:v1.18.7-gke1.35-gke.14@sha256:2170ed688661e1b038eaed32840e7d207a13589471bd7251ccc0c184cbb1eb3f" already present on machine and can be accessed by the pod
kube-system                   39m         Normal    Pulling                                  pod/pdcsi-node-nc9f9                                               Pulling image "europe-west3-artifactregistry.gcr.io/gke-release/gke-release/gcp-compute-persistent-disk-csi-driver:v1.23.1-gke.20@sha256:fc65b739e47e804ec6c93f4a2a8d8a2dbcaa2c1dd91f082fdb0c4266856d12ce"
kube-system                   39m         Normal    Pulling                                  pod/gke-metrics-agent-wrvtz                                        Pulling image "europe-west3-artifactregistry.gcr.io/gke-release/gke-release/node_token_broker/init:gke_node_token_broker_init_20260312.00_p0@sha256:d31f982e00598633fd2e94787f76894e29e80a3d87f5e15eacfc42b40e866de8"
kube-system                   39m         Normal    Pulled                                   pod/fluentbit-gke-lbhr6                                            Successfully pulled image "europe-west3-artifactregistry.gcr.io/gke-release/gke-release/node_token_broker/init:gke_node_token_broker_init_20260222.00_p0@sha256:f1538ec13c7dbe0e95cd5aab7a25c29280d41a3909d86d400b43d66b54642da8" in 880ms (880ms including waiting). Image size: 2927935 bytes.
kube-system                   39m         Normal    Created                                  pod/netd-drwst                                                     Container created
kube-system                   39m         Normal    Started                                  pod/netd-drwst                                                     Container started
kube-system                   39m         Normal    Pulled                                   pod/netd-drwst                                                     Container image "europe-west3-artifactregistry.gcr.io/gke-release/gke-release/node_token_broker/init:gke_node_token_broker_init_20251007.00_p0@sha256:638afa0822ed4c4aad9ff9f8528667a9d04dd5e1c7b1c251e9344ca7dd4aad68" already present on machine and can be accessed by the pod
kube-system                   39m         Normal    Created                                  pod/netd-drwst                                                     Container created
kube-system                   39m         Normal    Created                                  pod/anetd-2r7gz                                                    Container created
kube-system                   39m         Normal    Pulling                                  pod/fluentbit-gke-lbhr6                                            Pulling image "europe-west3-artifactregistry.gcr.io/gke-release/gke-release/node_token_broker/init:gke_node_token_broker_init_20260222.00_p0@sha256:f1538ec13c7dbe0e95cd5aab7a25c29280d41a3909d86d400b43d66b54642da8"
kube-system                   39m         Normal    Started                                  pod/anetd-2r7gz                                                    Container started
kube-system                   39m         Normal    Created                                  pod/anetd-2r7gz                                                    Container created
kube-system                   39m         Warning   FailedScheduling                         pod/l7-default-backend-58ffbbd58-wvskg                             0/1 nodes are available: 1 node(s) had untolerated taint(s). no new claims to deallocate, preemption: 0/1 nodes are available: 1 Preemption is not helpful for scheduling.
kube-system                   39m         Normal    Started                                  pod/fluentbit-gke-lbhr6                                            Container started
kube-system                   39m         Normal    Started                                  pod/netd-drwst                                                     Container started
kube-system                   39m         Normal    Created                                  pod/fluentbit-gke-lbhr6                                            Container created
kube-system                   39m         Normal    Started                                  pod/anetd-2r7gz                                                    Container started
kube-system                   39m         Normal    Created                                  pod/gke-metrics-agent-wrvtz                                        Container created
kube-system                   39m         Normal    Pulled                                   pod/gke-metrics-agent-wrvtz                                        Successfully pulled image "europe-west3-artifactregistry.gcr.io/gke-release/gke-release/node_token_broker/init:gke_node_token_broker_init_20260312.00_p0@sha256:d31f982e00598633fd2e94787f76894e29e80a3d87f5e15eacfc42b40e866de8" in 1.067s (1.067s including waiting). Image size: 2929568 bytes.
kube-system                   39m         Normal    Started                                  pod/gke-metrics-agent-wrvtz                                        Container started
kube-system                   39m         Normal    Pulled                                   pod/anetd-2r7gz                                                    Container image "europe-west3-artifactregistry.gcr.io/gke-release/gke-release/node_token_broker/init:gke_node_token_broker_init_20251010.00_p0@sha256:3615589424e94c68f8cee5d50c27c5a8b1a1f50ab5dc175a14e8540db7c80e8e" already present on machine and can be accessed by the pod
gmp-system                    39m         Normal    Scheduled                                pod/alertmanager-0                                                 Successfully assigned gmp-system/alertmanager-0 to gke-portable-voting-default-pool-2393733d-3flq
kube-system                   39m         Normal    Scheduled                                pod/event-exporter-gke-7dc55f4f5f-6k5kj                            Successfully assigned kube-system/event-exporter-gke-7dc55f4f5f-6k5kj to gke-portable-voting-default-pool-2393733d-3flq
kube-system                   39m         Normal    Pulling                                  pod/fluentbit-gke-lbhr6                                            Pulling image "europe-west3-artifactregistry.gcr.io/gke-release/gke-release/gke-distroless/bash:gke_distroless_20260615.00_p0@sha256:b98f4278dc5123fbad96c54ba8301c512d32f4716528ab30faea15108c68c52e"
gmp-system                    39m         Normal    Scheduled                                pod/gmp-operator-6875fdf876-rlwlh                                  Successfully assigned gmp-system/gmp-operator-6875fdf876-rlwlh to gke-portable-voting-default-pool-2393733d-3flq
kube-system                   39m         Normal    Scheduled                                pod/antrea-controller-horizontal-autoscaler-5f556bf8c6-w4z9q       Successfully assigned kube-system/antrea-controller-horizontal-autoscaler-5f556bf8c6-w4z9q to gke-portable-voting-default-pool-2393733d-3flq
kube-system                   39m         Normal    Pulling                                  pod/gke-metrics-agent-wrvtz                                        Pulling image "europe-west3-artifactregistry.gcr.io/gke-release/gke-release/gke-metrics-agent:1.16.1-gke.3@sha256:4cc4daca02a5928dd1c38b03ff421c9b3bca9cbc1249ccf69f8acfe3948ac1df"
gmp-system                    39m         Normal    Scheduled                                pod/rule-evaluator-79c78c4fd5-4q9kw                                Successfully assigned gmp-system/rule-evaluator-79c78c4fd5-4q9kw to gke-portable-voting-default-pool-2393733d-3flq
kube-system                   39m         Normal    Scheduled                                pod/konnectivity-agent-5446844985-k8xgt                            Successfully assigned kube-system/konnectivity-agent-5446844985-k8xgt to gke-portable-voting-default-pool-2393733d-3flq
kube-system                   39m         Normal    Scheduled                                pod/kube-dns-autoscaler-5dc7b666d8-wp4pz                           Successfully assigned kube-system/kube-dns-autoscaler-5dc7b666d8-wp4pz to gke-portable-voting-default-pool-2393733d-3flq
kube-system                   39m         Normal    Scheduled                                pod/konnectivity-agent-autoscaler-685569f784-wxl9g                 Successfully assigned kube-system/konnectivity-agent-autoscaler-685569f784-wxl9g to gke-portable-voting-default-pool-2393733d-3flq
gke-managed-cim               39m         Normal    Scheduled                                pod/kube-state-metrics-0                                           Successfully assigned gke-managed-cim/kube-state-metrics-0 to gke-portable-voting-default-pool-2393733d-3flq
kube-system                   39m         Normal    Scheduled                                pod/l7-default-backend-58ffbbd58-wvskg                             Successfully assigned kube-system/l7-default-backend-58ffbbd58-wvskg to gke-portable-voting-default-pool-2393733d-3flq
kube-system                   39m         Normal    Scheduled                                pod/metrics-server-v1.35.1-6559d8569d-c2m47                        Successfully assigned kube-system/metrics-server-v1.35.1-6559d8569d-c2m47 to gke-portable-voting-default-pool-2393733d-3flq
kube-system                   39m         Normal    Scheduled                                pod/metrics-server-v1.35.1-78f45667d-ptnww                         Successfully assigned kube-system/metrics-server-v1.35.1-78f45667d-ptnww to gke-portable-voting-default-pool-2393733d-3flq
kube-system                   39m         Normal    Pulled                                   pod/netd-drwst                                                     Container image "europe-west3-artifactregistry.gcr.io/gke-release/gke-release/netd:v0.10.12-gke.16@sha256:cb62348b061dc61180a3879c13c7cf1d3176312a167196776cf829e5c90c86c9" already present on machine and can be accessed by the pod
kube-system                   39m         Normal    Scheduled                                pod/kube-dns-78d5d95979-p2v8j                                      Successfully assigned kube-system/kube-dns-78d5d95979-p2v8j to gke-portable-voting-default-pool-2393733d-3flq
gmp-system                    39m         Warning   FailedMount                              pod/alertmanager-0                                                 MountVolume.SetUp failed for volume "config" : secret "alertmanager" not found
gmp-system                    39m         Warning   FailedMount                              pod/rule-evaluator-79c78c4fd5-4q9kw                                MountVolume.SetUp failed for volume "config" : configmap "rule-evaluator" not found
gmp-system                    39m         Warning   FailedMount                              pod/rule-evaluator-79c78c4fd5-4q9kw                                MountVolume.SetUp failed for volume "rules" : configmap "rules-generated" not found
gmp-system                    39m         Warning   FailedMount                              pod/rule-evaluator-79c78c4fd5-4q9kw                                MountVolume.SetUp failed for volume "rules-secret" : secret "rules" not found
kube-system                   39m         Normal    Created                                  pod/netd-drwst                                                     Container created
kube-system                   39m         Normal    Created                                  pod/anetd-2r7gz                                                    Container created
kube-system                   39m         Normal    Created                                  pod/fluentbit-gke-lbhr6                                            Container created
kube-system                   39m         Normal    Pulled                                   pod/netd-drwst                                                     Container image "europe-west3-artifactregistry.gcr.io/gke-release/gke-release/gke-metrics-collector:20251007_2300_RC0@sha256:0d590a9fb5339909d425b2eede28ac05cc76346092cbe82602c7618f047c25f0" already present on machine and can be accessed by the pod
kube-system                   39m         Normal    Started                                  pod/netd-drwst                                                     Container started
kube-system                   39m         Normal    Created                                  pod/netd-drwst                                                     Container created
gmp-system                    39m         Warning   FailedMount                              pod/collector-f27hc                                                MountVolume.SetUp failed for volume "config" : configmap "collector" not found
kube-system                   39m         Normal    Started                                  pod/anetd-2r7gz                                                    Container started
gmp-system                    39m         Warning   FailedMount                              pod/collector-f27hc                                                MountVolume.SetUp failed for volume "collection-secret" : secret "collection" not found
kube-system                   39m         Normal    Pulled                                   pod/fluentbit-gke-lbhr6                                            Successfully pulled image "europe-west3-artifactregistry.gcr.io/gke-release/gke-release/gke-distroless/bash:gke_distroless_20260615.00_p0@sha256:b98f4278dc5123fbad96c54ba8301c512d32f4716528ab30faea15108c68c52e" in 3.106s (3.106s including waiting). Image size: 18877251 bytes.
kube-system                   39m         Normal    LeaderElection                           lease/external-snapshotter-leader-pd-csi-storage-gke-io            gke-a4ad5f791ee9462391e0-79d6-e40e-vm became leader
kube-system                   39m         Normal    Pulled                                   pod/anetd-2r7gz                                                    Container image "europe-west3-artifactregistry.gcr.io/gke-release/gke-release/cilium/cilium:v1.18.7-gke1.35-gke.14@sha256:2170ed688661e1b038eaed32840e7d207a13589471bd7251ccc0c184cbb1eb3f" already present on machine and can be accessed by the pod
kube-system                   39m         Normal    Started                                  pod/fluentbit-gke-lbhr6                                            Container started
kube-system                   39m         Normal    Pulled                                   pod/anetd-2r7gz                                                    Container image "europe-west3-artifactregistry.gcr.io/gke-release/gke-release/gke-metrics-collector:20251009_2300_RC0@sha256:4c8e8cc4f739fc539e35c1581af031232d8885ee10f28484cb2085f5dfbb2b7d" already present on machine and can be accessed by the pod
kube-system                   39m         Normal    Started                                  pod/netd-drwst                                                     Container started
kube-system                   39m         Normal    Pulling                                  pod/fluentbit-gke-lbhr6                                            Pulling image "europe-west3-artifactregistry.gcr.io/gke-release/gke-release/fluent-bit:v0.0.422-gke.2@sha256:4b5df304074c9f2842f16ef4869c0ec253c2d91d6478e5aa42d2f8dce9146b45"
kube-system                   39m         Normal    Created                                  pod/anetd-2r7gz                                                    Container created
kube-system                   39m         Normal    Started                                  pod/anetd-2r7gz                                                    Container started
kube-system                   39m         Normal    Pulling                                  pod/konnectivity-agent-5446844985-k8xgt                            Pulling image "europe-west3-artifactregistry.gcr.io/gke-release/gke-release/node_token_broker/init:gke_node_token_broker_init_20251019.00_p0@sha256:2e1549e4692726aecc70364a1d6700cf276db2d9b4da90179284ca8de168c976"
kube-system                   39m         Normal    Pulling                                  pod/antrea-controller-horizontal-autoscaler-5f556bf8c6-w4z9q       Pulling image "europe-west3-artifactregistry.gcr.io/gke-release/gke-release/cluster-proportional-autoscaler:v1.10.2-gke.24@sha256:1d07b99750cfa777b55d7a66e73c4e4241dca6b215715478deb5793263a91527"
kube-system                   39m         Normal    Created                                  pod/anetd-2r7gz                                                    Container created
gke-managed-cim               39m         Normal    Created                                  pod/kube-state-metrics-0                                           Container created
kube-system                   39m         Normal    Pulling                                  pod/kube-dns-78d5d95979-p2v8j                                      Pulling image "europe-west3-artifactregistry.gcr.io/gke-release/gke-release/node_token_broker/init:gke_node_token_broker_init_20260412.00_p0@sha256:10a31e4c4338b37a10dbf4dfeaabd58a95b711e59abb740de628c32748184831"
gke-managed-cim               39m         Normal    Pulled                                   pod/kube-state-metrics-0                                           Container image "europe-west3-artifactregistry.gcr.io/gke-release/gke-release/node_token_broker/init:gke_node_token_broker_init_20260410.00_p0@sha256:48b18ce5260a479f47611fdff76075e816422c28dce0cab772ba627c508159b4" already present on machine and can be accessed by the pod
kube-system                   39m         Warning   Unhealthy                                pod/anetd-2r7gz                                                    Startup probe failed: Get "http://127.0.0.1:9879/healthz": dial tcp 127.0.0.1:9879: connect: connection refused
kube-system                   39m         Normal    Started                                  pod/anetd-2r7gz                                                    Container started
gke-managed-cim               39m         Normal    Started                                  pod/kube-state-metrics-0                                           Container started
kube-system                   39m         Normal    Pulling                                  pod/l7-default-backend-58ffbbd58-wvskg                             Pulling image "europe-west3-artifactregistry.gcr.io/gke-release/gke-release/ingress-gce-404-server-with-metrics:v1.38.7@sha256:bce3b45becb05edaf0fbac1159453a3a1e4d6407be41347f9a8f0114a1b61487"
kube-system                   39m         Normal    Pulling                                  pod/metrics-server-v1.35.1-6559d8569d-c2m47                        Pulling image "europe-west3-artifactregistry.gcr.io/gke-release/gke-release/metrics-server:v0.8.0-gke.23@sha256:208c1ced1b6a551a067e526b616caf0e0da8fa98a60b3d22e9177c86563d17d0"
gmp-system                    39m         Normal    Pulling                                  pod/gmp-operator-6875fdf876-rlwlh                                  Pulling image "europe-west3-artifactregistry.gcr.io/gke-release/gke-release/prometheus-engine/operator:v0.18.1-gke.2@sha256:d025fbed450a8c9849188630878834a18fcffb7c2916798be1308bea930fe838"
kube-system                   39m         Normal    Pulling                                  pod/konnectivity-agent-autoscaler-685569f784-wxl9g                 Pulling image "europe-west3-artifactregistry.gcr.io/gke-release/gke-release/cluster-proportional-autoscaler:v1.10.3-gke.8@sha256:437ad59d9fe3b37db75e0c1f5d74fe227abbba720bde166f52f3d71096b69aaf"
kube-system                   39m         Normal    Pulling                                  pod/kube-dns-autoscaler-5dc7b666d8-wp4pz                           Pulling image "europe-west3-artifactregistry.gcr.io/gke-release/gke-release/cluster-proportional-autoscaler:v1.10.3-gke.2@sha256:608476c370ab6d23cf62b3cb470b0480c446ff43fc6fa48959aa5d90f235722e"
kube-system                   39m         Normal    Pulling                                  pod/event-exporter-gke-7dc55f4f5f-6k5kj                            Pulling image "europe-west3-artifactregistry.gcr.io/gke-release/gke-release/node_token_broker/init:gke_node_token_broker_init_20260716.00_p0@sha256:134942efd2defb12c04345e6713ea73613466b7b281d2800c287b51c55ec0b00"
kube-system                   39m         Normal    Pulling                                  pod/node-local-dns-6t5fg                                           Pulling image "europe-west3-artifactregistry.gcr.io/gke-release/gke-release/node_token_broker/init:gke_node_token_broker_init_20260422.00_p0@sha256:4ceac22ea251c0996e6f58165c9b79b44bd98de251a4b38ffaf072a89974671c"
kube-system                   39m         Normal    Pulling                                  pod/metrics-server-v1.35.1-78f45667d-ptnww                         Pulling image "europe-west3-artifactregistry.gcr.io/gke-release/gke-release/metrics-server:v0.8.0-gke.23@sha256:208c1ced1b6a551a067e526b616caf0e0da8fa98a60b3d22e9177c86563d17d0"
kube-system                   39m         Normal    Created                                  pod/gke-metrics-agent-wrvtz                                        Container created
kube-system                   39m         Normal    Pulled                                   pod/gke-metrics-agent-wrvtz                                        Successfully pulled image "europe-west3-artifactregistry.gcr.io/gke-release/gke-release/gke-metrics-agent:1.16.1-gke.3@sha256:4cc4daca02a5928dd1c38b03ff421c9b3bca9cbc1249ccf69f8acfe3948ac1df" in 6.998s (10.083s including waiting). Image size: 31395961 bytes.
gke-managed-cim               39m         Normal    Pulling                                  pod/kube-state-metrics-0                                           Pulling image "europe-west3-artifactregistry.gcr.io/gke-release/gke-release/kube-state-metrics:v2.14.0-gke.58@sha256:04af0a0c7c400073ade2a5cb1b452df7ec3af5b55fba5718dc13b1629ed73a7d"
kube-system                   39m         Warning   FailedScheduling                         pod/konnectivity-agent-5446844985-c46v8                            0/1 nodes are available: 1 node(s) were unschedulable. no new claims to deallocate, preemption: 0/1 nodes are available: 1 Preemption is not helpful for scheduling.
kube-system                   39m         Normal    SuccessfulCreate                         replicaset/antrea-controller-horizontal-autoscaler-5f556bf8c6      Created pod: antrea-controller-horizontal-autoscaler-5f556bf8c6-pr5xs
kube-system                   39m         Warning   FailedScheduling                         pod/antrea-controller-horizontal-autoscaler-5f556bf8c6-pr5xs       0/1 nodes are available: 1 node(s) were unschedulable. no new claims to deallocate, preemption: 0/1 nodes are available: 1 Preemption is not helpful for scheduling.
gmp-system                    39m         Warning   FailedScheduling                         pod/gmp-operator-6875fdf876-vzg2n                                  0/1 nodes are available: 1 node(s) were unschedulable. no new claims to deallocate, preemption: 0/1 nodes are available: 1 Preemption is not helpful for scheduling.
kube-system                   39m         Warning   FailedScheduling                         pod/kube-dns-78d5d95979-t7tnw                                      0/1 nodes are available: 1 node(s) were unschedulable. no new claims to deallocate, preemption: 0/1 nodes are available: 1 Preemption is not helpful for scheduling.
gmp-system                    39m         Normal    SuccessfulCreate                         replicaset/gmp-operator-6875fdf876                                 Created pod: gmp-operator-6875fdf876-vzg2n
kube-system                   39m         Normal    SuccessfulCreate                         replicaset/konnectivity-agent-5446844985                           Created pod: konnectivity-agent-5446844985-c46v8
kube-system                   39m         Warning   FailedScheduling                         pod/konnectivity-agent-autoscaler-685569f784-vb7c2                 0/1 nodes are available: 1 node(s) were unschedulable. no new claims to deallocate, preemption: 0/1 nodes are available: 1 Preemption is not helpful for scheduling.
kube-system                   39m         Normal    Started                                  pod/gke-metrics-agent-wrvtz                                        Container started
kube-system                   39m         Warning   FailedScheduling                         pod/event-exporter-gke-7dc55f4f5f-fdvkm                            0/1 nodes are available: 1 node(s) were unschedulable. no new claims to deallocate, preemption: 0/1 nodes are available: 1 Preemption is not helpful for scheduling.
gmp-system                    39m         Normal    SuccessfulCreate                         replicaset/rule-evaluator-79c78c4fd5                               Created pod: rule-evaluator-79c78c4fd5-gws5x
gmp-system                    39m         Warning   FailedScheduling                         pod/rule-evaluator-79c78c4fd5-gws5x                                0/1 nodes are available: 1 node(s) were unschedulable. no new claims to deallocate, preemption: 0/1 nodes are available: 1 Preemption is not helpful for scheduling.
kube-system                   39m         Normal    Pulled                                   pod/gke-metrics-agent-wrvtz                                        Container image "europe-west3-artifactregistry.gcr.io/gke-release/gke-release/gke-metrics-agent:1.16.1-gke.3@sha256:4cc4daca02a5928dd1c38b03ff421c9b3bca9cbc1249ccf69f8acfe3948ac1df" already present on machine and can be accessed by the pod
kube-system                   39m         Normal    SuccessfulCreate                         replicaset/event-exporter-gke-7dc55f4f5f                           Created pod: event-exporter-gke-7dc55f4f5f-fdvkm
kube-system                   39m         Normal    SuccessfulCreate                         replicaset/kube-dns-autoscaler-5dc7b666d8                          Created pod: kube-dns-autoscaler-5dc7b666d8-cq7fg
kube-system                   39m         Normal    Created                                  pod/gke-metrics-agent-wrvtz                                        Container created
kube-system                   39m         Normal    Started                                  pod/gke-metrics-agent-wrvtz                                        Container started
kube-system                   39m         Warning   FailedScheduling                         pod/l7-default-backend-58ffbbd58-gr22t                             0/1 nodes are available: 1 node(s) were unschedulable. no new claims to deallocate, preemption: 0/1 nodes are available: 1 Preemption is not helpful for scheduling.
kube-system                   39m         Warning   FailedScheduling                         pod/kube-dns-autoscaler-5dc7b666d8-cq7fg                           0/1 nodes are available: 1 node(s) were unschedulable. no new claims to deallocate, preemption: 0/1 nodes are available: 1 Preemption is not helpful for scheduling.
kube-system                   39m         Normal    SuccessfulCreate                         replicaset/konnectivity-agent-autoscaler-685569f784                Created pod: konnectivity-agent-autoscaler-685569f784-vb7c2
kube-system                   39m         Normal    SuccessfulCreate                         replicaset/kube-dns-78d5d95979                                     Created pod: kube-dns-78d5d95979-t7tnw
kube-system                   39m         Normal    SuccessfulCreate                         replicaset/l7-default-backend-58ffbbd58                            Created pod: l7-default-backend-58ffbbd58-gr22t
kube-system                   39m         Warning   FailedScheduling                         pod/metrics-server-v1.35.1-6559d8569d-vttnf                        0/1 nodes are available: 1 node(s) were unschedulable. no new claims to deallocate, preemption: 0/1 nodes are available: 1 Preemption is not helpful for scheduling.
kube-system                   39m         Warning   FailedScheduling                         pod/metrics-server-v1.35.1-78f45667d-2k56n                         0/1 nodes are available: 1 node(s) were unschedulable. no new claims to deallocate, preemption: 0/1 nodes are available: 1 Preemption is not helpful for scheduling.
gmp-system                    39m         Warning   FailedScheduling                         pod/alertmanager-0                                                 0/1 nodes are available: 1 node(s) were unschedulable. no new claims to deallocate, preemption: 0/1 nodes are available: 1 Preemption is not helpful for scheduling.
kube-system                   39m         Normal    SuccessfulCreate                         replicaset/metrics-server-v1.35.1-6559d8569d                       Created pod: metrics-server-v1.35.1-6559d8569d-vttnf
kube-system                   39m         Normal    SuccessfulCreate                         replicaset/metrics-server-v1.35.1-78f45667d                        Created pod: metrics-server-v1.35.1-78f45667d-2k56n
kube-system                   39m         Normal    Pulling                                  pod/gke-metrics-agent-wrvtz                                        Pulling image "europe-west3-artifactregistry.gcr.io/gke-release/gke-release/gke-metrics-collector:20250807_2300_RC0@sha256:aa1ed41571fa937da61b5bcd7cf842981c7f026b516c18655bc2f3a9362b1fa5"
kube-system                   39m         Normal    UpdateRedirectService                    redirectservice/default                                            Updating redirect service (resourceVersion = 1787220740935007005)
kube-system                   39m         Normal    LeaderElection                           lease/snapshot-controller-leader                                   gke-a4ad5f791ee9462391e0-79d6-e40e-vm became leader
kube-system                   39m         Normal    Pulled                                   pod/fluentbit-gke-lbhr6                                            Successfully pulled image "europe-west3-artifactregistry.gcr.io/gke-release/gke-release/fluent-bit:v0.0.422-gke.2@sha256:4b5df304074c9f2842f16ef4869c0ec253c2d91d6478e5aa42d2f8dce9146b45" in 7.751s (12.519s including waiting). Image size: 66344763 bytes.
kube-system                   39m         Normal    Pulling                                  pod/fluentbit-gke-lbhr6                                            Pulling image "europe-west3-artifactregistry.gcr.io/gke-release/gke-release/fluent-bit-gke-exporter:v0.27.17-gke.20@sha256:67269cb89dbf9cf4e76e199a634c178eec76e74ae45694e8000893f7cae6179e"
kube-system                   39m         Normal    Started                                  pod/fluentbit-gke-lbhr6                                            Container started
kube-system                   39m         Normal    Created                                  pod/fluentbit-gke-lbhr6                                            Container created
kube-system                   39m         Normal    Created                                  pod/antrea-controller-horizontal-autoscaler-5f556bf8c6-w4z9q       Container created
kube-system                   39m         Normal    Pulled                                   pod/antrea-controller-horizontal-autoscaler-5f556bf8c6-w4z9q       Successfully pulled image "europe-west3-artifactregistry.gcr.io/gke-release/gke-release/cluster-proportional-autoscaler:v1.10.2-gke.24@sha256:1d07b99750cfa777b55d7a66e73c4e4241dca6b215715478deb5793263a91527" in 2.478s (14.578s including waiting). Image size: 13688349 bytes.
kube-system                   39m         Normal    Started                                  pod/antrea-controller-horizontal-autoscaler-5f556bf8c6-w4z9q       Container started
kube-system                   39m         Normal    Killing                                  pod/antrea-controller-horizontal-autoscaler-5f556bf8c6-w4z9q       Stopping container autoscaler
kube-system                   39m         Normal    Pulled                                   pod/konnectivity-agent-5446844985-k8xgt                            Successfully pulled image "europe-west3-artifactregistry.gcr.io/gke-release/gke-release/node_token_broker/init:gke_node_token_broker_init_20251019.00_p0@sha256:2e1549e4692726aecc70364a1d6700cf276db2d9b4da90179284ca8de168c976" in 1.623s (16.148s including waiting). Image size: 2887395 bytes.
gmp-system                    39m         Normal    NotTriggerScaleUp                        pod/rule-evaluator-79c78c4fd5-gws5x                                Pod didn't trigger scale-up:
kube-system                   39m         Normal    NotTriggerScaleUp                        pod/metrics-server-v1.35.1-6559d8569d-vttnf                        Pod didn't trigger scale-up:
kube-system                   39m         Normal    NotTriggerScaleUp                        pod/konnectivity-agent-5446844985-c46v8                            Pod didn't trigger scale-up:
kube-system                   39m         Normal    Created                                  pod/konnectivity-agent-5446844985-k8xgt                            Container created
kube-system                   39m         Normal    NotTriggerScaleUp                        pod/konnectivity-agent-autoscaler-685569f784-vb7c2                 Pod didn't trigger scale-up:
kube-system                   39m         Normal    NotTriggerScaleUp                        pod/metrics-server-v1.35.1-78f45667d-2k56n                         Pod didn't trigger scale-up:
kube-system                   39m         Normal    NotTriggerScaleUp                        pod/event-exporter-gke-7dc55f4f5f-fdvkm                            Pod didn't trigger scale-up:
kube-system                   39m         Normal    NotTriggerScaleUp                        pod/l7-default-backend-58ffbbd58-gr22t                             Pod didn't trigger scale-up:
kube-system                   39m         Normal    Pulled                                   pod/kube-dns-78d5d95979-p2v8j                                      Successfully pulled image "europe-west3-artifactregistry.gcr.io/gke-release/gke-release/node_token_broker/init:gke_node_token_broker_init_20260412.00_p0@sha256:10a31e4c4338b37a10dbf4dfeaabd58a95b711e59abb740de628c32748184831" in 1.636s (16.411s including waiting). Image size: 3374190 bytes.
kube-system                   39m         Normal    Created                                  pod/kube-dns-78d5d95979-p2v8j                                      Container created
kube-system                   39m         Normal    NotTriggerScaleUp                        pod/antrea-controller-horizontal-autoscaler-5f556bf8c6-pr5xs       Pod didn't trigger scale-up:
gmp-system                    39m         Normal    NotTriggerScaleUp                        pod/gmp-operator-6875fdf876-vzg2n                                  Pod didn't trigger scale-up:
kube-system                   39m         Normal    NotTriggerScaleUp                        pod/kube-dns-78d5d95979-t7tnw                                      Pod didn't trigger scale-up:
kube-system                   39m         Normal    Pulled                                   pod/pdcsi-node-nc9f9                                               Successfully pulled image "europe-west3-artifactregistry.gcr.io/gke-release/gke-release/gcp-compute-persistent-disk-csi-driver:v1.23.1-gke.20@sha256:fc65b739e47e804ec6c93f4a2a8d8a2dbcaa2c1dd91f082fdb0c4266856d12ce" in 25.935s (25.936s including waiting). Image size: 124338789 bytes.
gmp-system                    39m         Normal    NotTriggerScaleUp                        pod/alertmanager-0                                                 Pod didn't trigger scale-up:
kube-system                   39m         Normal    NotTriggerScaleUp                        pod/kube-dns-autoscaler-5dc7b666d8-cq7fg                           Pod didn't trigger scale-up:
kube-system                   39m         Normal    Started                                  pod/pdcsi-node-nc9f9                                               Container started
kube-system                   39m         Normal    Killing                                  pod/kube-dns-78d5d95979-p2v8j                                      Stopping container token-broker-adc-init
kube-system                   39m         Normal    Started                                  pod/kube-dns-78d5d95979-p2v8j                                      Container started
kube-system                   39m         Normal    Created                                  pod/pdcsi-node-nc9f9                                               Container created
kube-system                   39m         Normal    Pulling                                  pod/pdcsi-node-nc9f9                                               Pulling image "europe-west3-artifactregistry.gcr.io/gke-release/gke-release/gke-metrics-collector:20250311_2300_RC0@sha256:e6713a8266629d9e103f7b2c7715bf510170fe28ebe2dc341327fa5e6a0facde"
kube-system                   39m         Normal    Pulled                                   pod/l7-default-backend-58ffbbd58-wvskg                             Successfully pulled image "europe-west3-artifactregistry.gcr.io/gke-release/gke-release/ingress-gce-404-server-with-metrics:v1.38.7@sha256:bce3b45becb05edaf0fbac1159453a3a1e4d6407be41347f9a8f0114a1b61487" in 2.064s (17.586s including waiting). Image size: 7595136 bytes.
kube-system                   39m         Normal    Killing                                  pod/konnectivity-agent-5446844985-k8xgt                            Stopping container token-broker-adc-init
kube-system                   39m         Normal    Started                                  pod/konnectivity-agent-5446844985-k8xgt                            Container started
kube-system                   39m         Normal    Created                                  pod/l7-default-backend-58ffbbd58-wvskg                             Container created
kube-system                   39m         Normal    Created                                  pod/node-local-dns-6t5fg                                           Container created
kube-system                   39m         Normal    Pulled                                   pod/node-local-dns-6t5fg                                           Successfully pulled image "europe-west3-artifactregistry.gcr.io/gke-release/gke-release/node_token_broker/init:gke_node_token_broker_init_20260422.00_p0@sha256:4ceac22ea251c0996e6f58165c9b79b44bd98de251a4b38ffaf072a89974671c" in 987ms (18.505s including waiting). Image size: 3374191 bytes.
kube-system                   39m         Warning   FailedKillPod                            pod/konnectivity-agent-5446844985-k8xgt                            error killing pod: failed to "KillContainer" for "token-broker-adc-init" with KillContainerError: "rpc error: code = Unknown desc = failed to stop container \"122c29c7f6a510e813a628137fbc50a00282e2af27e658c0ea711b68bc9cef84\": ttrpc: closed"
kube-system                   39m         Normal    Started                                  pod/node-local-dns-6t5fg                                           Container started
kube-system                   39m         Normal    Started                                  pod/l7-default-backend-58ffbbd58-wvskg                             Container started
kube-system                   39m         Normal    Killing                                  pod/l7-default-backend-58ffbbd58-wvskg                             Stopping container default-http-backend
kube-system                   39m         Normal    Pulled                                   pod/konnectivity-agent-autoscaler-685569f784-wxl9g                 Successfully pulled image "europe-west3-artifactregistry.gcr.io/gke-release/gke-release/cluster-proportional-autoscaler:v1.10.3-gke.8@sha256:437ad59d9fe3b37db75e0c1f5d74fe227abbba720bde166f52f3d71096b69aaf" in 3.528s (19.279s including waiting). Image size: 13824914 bytes.
kube-system                   39m         Normal    Pulling                                  pod/node-local-dns-6t5fg                                           Pulling image "europe-west3-artifactregistry.gcr.io/gke-release/gke-release/k8s-dns-node-cache:1.26.8-gke.5@sha256:b466bc19f519bf5eb7ee278a57d33f9fdf253db8dd4e78677bd7b0373afcfea7"
kube-system                   39m         Normal    Created                                  pod/konnectivity-agent-autoscaler-685569f784-wxl9g                 Container created
kube-system                   39m         Normal    Started                                  pod/konnectivity-agent-autoscaler-685569f784-wxl9g                 Container started
kube-system                   39m         Normal    Killing                                  pod/konnectivity-agent-autoscaler-685569f784-wxl9g                 Stopping container autoscaler
kube-system                   39m         Normal    Created                                  pod/kube-dns-autoscaler-5dc7b666d8-wp4pz                           Container created
kube-system                   39m         Normal    Pulled                                   pod/kube-dns-autoscaler-5dc7b666d8-wp4pz                           Successfully pulled image "europe-west3-artifactregistry.gcr.io/gke-release/gke-release/cluster-proportional-autoscaler:v1.10.3-gke.2@sha256:608476c370ab6d23cf62b3cb470b0480c446ff43fc6fa48959aa5d90f235722e" in 3.714s (22.114s including waiting). Image size: 14214756 bytes.
kube-system                   39m         Normal    Killing                                  pod/kube-dns-autoscaler-5dc7b666d8-wp4pz                           Stopping container autoscaler
kube-system                   39m         Normal    Started                                  pod/kube-dns-autoscaler-5dc7b666d8-wp4pz                           Container started
gmp-system                    39m         Normal    Created                                  pod/gmp-operator-6875fdf876-rlwlh                                  Container created
gmp-system                    39m         Normal    Pulled                                   pod/gmp-operator-6875fdf876-rlwlh                                  Successfully pulled image "europe-west3-artifactregistry.gcr.io/gke-release/gke-release/prometheus-engine/operator:v0.18.1-gke.2@sha256:d025fbed450a8c9849188630878834a18fcffb7c2916798be1308bea930fe838" in 5.692s (24.79s including waiting). Image size: 49656818 bytes.
kube-system                   39m         Normal    Created                                  pod/event-exporter-gke-7dc55f4f5f-6k5kj                            Container created
kube-system                   39m         Normal    Pulled                                   pod/event-exporter-gke-7dc55f4f5f-6k5kj                            Successfully pulled image "europe-west3-artifactregistry.gcr.io/gke-release/gke-release/node_token_broker/init:gke_node_token_broker_init_20260716.00_p0@sha256:134942efd2defb12c04345e6713ea73613466b7b281d2800c287b51c55ec0b00" in 1.17s (25.586s including waiting). Image size: 3338535 bytes.
gmp-system                    39m         Normal    Killing                                  pod/gmp-operator-6875fdf876-rlwlh                                  Stopping container operator
gmp-system                    39m         Normal    Started                                  pod/gmp-operator-6875fdf876-rlwlh                                  Container started
kube-system                   39m         Normal    Created                                  pod/metrics-server-v1.35.1-6559d8569d-c2m47                        Container created
kube-system                   39m         Normal    Created                                  pod/metrics-server-v1.35.1-78f45667d-ptnww                         Container created
kube-system                   39m         Normal    Started                                  pod/event-exporter-gke-7dc55f4f5f-6k5kj                            Container started
kube-system                   39m         Normal    Pulled                                   pod/metrics-server-v1.35.1-6559d8569d-c2m47                        Successfully pulled image "europe-west3-artifactregistry.gcr.io/gke-release/gke-release/metrics-server:v0.8.0-gke.23@sha256:208c1ced1b6a551a067e526b616caf0e0da8fa98a60b3d22e9177c86563d17d0" in 4.658s (26.472s including waiting). Image size: 22695603 bytes.
kube-system                   39m         Normal    Pulled                                   pod/metrics-server-v1.35.1-78f45667d-ptnww                         Successfully pulled image "europe-west3-artifactregistry.gcr.io/gke-release/gke-release/metrics-server:v0.8.0-gke.23@sha256:208c1ced1b6a551a067e526b616caf0e0da8fa98a60b3d22e9177c86563d17d0" in 814ms (26.067s including waiting). Image size: 22695603 bytes.
kube-system                   39m         Normal    Killing                                  pod/event-exporter-gke-7dc55f4f5f-6k5kj                            Stopping container token-broker-adc-init
kube-system                   39m         Normal    Started                                  pod/metrics-server-v1.35.1-6559d8569d-c2m47                        Container started
kube-system                   39m         Normal    Started                                  pod/metrics-server-v1.35.1-78f45667d-ptnww                         Container started
kube-system                   39m         Normal    Killing                                  pod/metrics-server-v1.35.1-6559d8569d-c2m47                        Stopping container metrics-server
kube-system                   39m         Normal    Killing                                  pod/metrics-server-v1.35.1-78f45667d-ptnww                         Stopping container metrics-server
gke-managed-cim               39m         Normal    Pulled                                   pod/kube-state-metrics-0                                           Successfully pulled image "europe-west3-artifactregistry.gcr.io/gke-release/gke-release/kube-state-metrics:v2.14.0-gke.58@sha256:04af0a0c7c400073ade2a5cb1b452df7ec3af5b55fba5718dc13b1629ed73a7d" in 4.598s (29.697s including waiting). Image size: 15894304 bytes.
gke-managed-cim               39m         Normal    Created                                  pod/kube-state-metrics-0                                           Container created
gke-managed-cim               39m         Normal    Pulling                                  pod/kube-state-metrics-0                                           Pulling image "europe-west3-artifactregistry.gcr.io/gke-release/gke-release/gke-metrics-collector:20260113_2300_RC0@sha256:5eb81dc265af031294a413a32fde1b59d5b8480e3f131a09b5a1059294aefd99"
kube-system                   39m         Normal    Created                                  pod/gke-metrics-agent-wrvtz                                        Container created
kube-system                   39m         Normal    Pulled                                   pod/gke-metrics-agent-wrvtz                                        Successfully pulled image "europe-west3-artifactregistry.gcr.io/gke-release/gke-release/gke-metrics-collector:20250807_2300_RC0@sha256:aa1ed41571fa937da61b5bcd7cf842981c7f026b516c18655bc2f3a9362b1fa5" in 5.281s (27.658s including waiting). Image size: 25459396 bytes.
gke-managed-cim               39m         Normal    Started                                  pod/kube-state-metrics-0                                           Container started
kube-system                   39m         Normal    Started                                  pod/gke-metrics-agent-wrvtz                                        Container started
kube-system                   39m         Normal    Pulled                                   pod/fluentbit-gke-lbhr6                                            Container image "europe-west3-artifactregistry.gcr.io/gke-release/gke-release/gke-metrics-collector:20260617_2300_RC0@sha256:c8cd71f5cd9f076b55e3f1db733e6adacd6ad3cfabaa9eb467b0ece8e691d73b" already present on machine and can be accessed by the pod
kube-system                   39m         Normal    Started                                  pod/fluentbit-gke-lbhr6                                            Container started
kube-system                   39m         Normal    Pulled                                   pod/pdcsi-node-nc9f9                                               Successfully pulled image "europe-west3-artifactregistry.gcr.io/gke-release/gke-release/gke-metrics-collector:20250311_2300_RC0@sha256:e6713a8266629d9e103f7b2c7715bf510170fe28ebe2dc341327fa5e6a0facde" in 4.017s (19.807s including waiting). Image size: 25809711 bytes.
kube-system                   39m         Normal    Pulled                                   pod/fluentbit-gke-lbhr6                                            Successfully pulled image "europe-west3-artifactregistry.gcr.io/gke-release/gke-release/fluent-bit-gke-exporter:v0.27.17-gke.20@sha256:67269cb89dbf9cf4e76e199a634c178eec76e74ae45694e8000893f7cae6179e" in 4.525s (25.739s including waiting). Image size: 36248865 bytes.
kube-system                   39m         Normal    Created                                  pod/fluentbit-gke-lbhr6                                            Container created
kube-system                   39m         Normal    Created                                  pod/pdcsi-node-nc9f9                                               Container created
kube-system                   39m         Normal    Created                                  pod/fluentbit-gke-lbhr6                                            Container created
kube-system                   39m         Normal    Started                                  pod/pdcsi-node-nc9f9                                               Container started
kube-system                   39m         Normal    Pulling                                  pod/pdcsi-node-nc9f9                                               Pulling image "europe-west3-artifactregistry.gcr.io/gke-release/gke-release/csi-node-driver-registrar:v2.15.0-gke.34@sha256:b38f4e46ad46c1f83f550d695812296b8d2d6a211c3fc0633f28979b0e958516"
kube-system                   39m         Normal    Started                                  pod/fluentbit-gke-lbhr6                                            Container started
gke-managed-cim               39m         Normal    Created                                  pod/kube-state-metrics-0                                           Container created
gke-managed-cim               39m         Normal    Pulled                                   pod/kube-state-metrics-0                                           Successfully pulled image "europe-west3-artifactregistry.gcr.io/gke-release/gke-release/gke-metrics-collector:20260113_2300_RC0@sha256:5eb81dc265af031294a413a32fde1b59d5b8480e3f131a09b5a1059294aefd99" in 3.36s (7.473s including waiting). Image size: 26332537 bytes.
gke-managed-cim               39m         Normal    Killing                                  pod/kube-state-metrics-0                                           Stopping container ksm-metrics-collector
gke-managed-cim               39m         Normal    Killing                                  pod/kube-state-metrics-0                                           Stopping container kube-state-metrics
gke-managed-cim               39m         Normal    Started                                  pod/kube-state-metrics-0                                           Container started
kube-system                   39m         Warning   FailedKillPod                            pod/event-exporter-gke-7dc55f4f5f-6k5kj                            error killing pod: failed to "KillContainer" for "token-broker-adc-init" with KillContainerError: "rpc error: code = Unknown desc = failed to stop container \"11beea7779073016cd9cf8215d759e356918c7f8b7fbcfe0195c9e0c1e7276ef\": ttrpc: closed"
kube-system                   38m         Normal    Pulled                                   pod/pdcsi-node-nc9f9                                               Successfully pulled image "europe-west3-artifactregistry.gcr.io/gke-release/gke-release/csi-node-driver-registrar:v2.15.0-gke.34@sha256:b38f4e46ad46c1f83f550d695812296b8d2d6a211c3fc0633f28979b0e958516" in 4.113s (6.527s including waiting). Image size: 14461369 bytes.
kube-system                   38m         Normal    Created                                  pod/pdcsi-node-nc9f9                                               Container created
kube-system                   38m         Normal    Pulled                                   pod/node-local-dns-6t5fg                                           Successfully pulled image "europe-west3-artifactregistry.gcr.io/gke-release/gke-release/k8s-dns-node-cache:1.26.8-gke.5@sha256:b466bc19f519bf5eb7ee278a57d33f9fdf253db8dd4e78677bd7b0373afcfea7" in 8.303s (23.888s including waiting). Image size: 52897804 bytes.
kube-system                   38m         Normal    Created                                  pod/node-local-dns-6t5fg                                           Container created
kube-system                   38m         Normal    Pulling                                  pod/node-local-dns-6t5fg                                           Pulling image "europe-west3-artifactregistry.gcr.io/gke-release/gke-release/gke-metrics-collector:20260422_2300_RC0@sha256:70625564549ccc35d34e119dd3e3d5e2f841be9c309940d3ed5bb4e649a3c59f"
gke-managed-cim               38m         Normal    NotTriggerScaleUp                        pod/kube-state-metrics-0                                           Pod didn't trigger scale-up:
kube-system                   38m         Normal    Started                                  pod/node-local-dns-6t5fg                                           Container started
gke-managed-cim               38m         Warning   FailedScheduling                         pod/kube-state-metrics-0                                           0/1 nodes are available: 1 node(s) were unschedulable. no new claims to deallocate, preemption: 0/1 nodes are available: 1 Preemption is not helpful for scheduling.
kube-system                   38m         Normal    Started                                  pod/pdcsi-node-nc9f9                                               Container started
kube-system                   38m         Normal    Created                                  pod/node-local-dns-6t5fg                                           Container created
kube-system                   38m         Normal    Started                                  pod/node-local-dns-6t5fg                                           Container started
kube-system                   38m         Normal    Pulled                                   pod/node-local-dns-6t5fg                                           Successfully pulled image "europe-west3-artifactregistry.gcr.io/gke-release/gke-release/gke-metrics-collector:20260422_2300_RC0@sha256:70625564549ccc35d34e119dd3e3d5e2f841be9c309940d3ed5bb4e649a3c59f" in 2.479s (2.479s including waiting). Image size: 26354407 bytes.
kube-system                   38m         Normal    LeaderElection                           lease/service-steering.networking.gke.io                           gke-a4ad5f791ee9462391e0-79d6-e40e-vm_9ff2fde7-b56b-4cf7-a6d8-7a13f82f19ab became leader
kube-system                   38m         Normal    LeaderElection                           lease/vpa-recommender                                              gke-a4ad5f791ee9462391e0-79d6-e40e-vm became leader
gke-managed-cim               34m         Warning   FailedGetResourceMetric                  horizontalpodautoscaler/kube-state-metrics                         unable to get metric memory: unable to fetch metrics from resource metrics API: the server could not find the requested resource (get pods.metrics.k8s.io)
kube-system                   37m         Warning   NodeNotReady                             pod/netd-drwst                                                     Node is not ready
kube-system                   37m         Warning   NodeNotReady                             pod/gke-metrics-agent-wrvtz                                        Node is not ready
kube-system                   37m         Warning   NodeNotReady                             pod/pdcsi-node-nc9f9                                               Node is not ready
kube-system                   37m         Warning   NodeNotReady                             pod/fluentbit-gke-lbhr6                                            Node is not ready
kube-system                   37m         Warning   NodeNotReady                             pod/anetd-2r7gz                                                    Node is not ready
default                       37m         Normal    NodeNotReady                             node/gke-portable-voting-default-pool-2393733d-3flq                Node gke-portable-voting-default-pool-2393733d-3flq status is now: NodeNotReady
default                       37m         Normal    DeletingNode                             node/gke-portable-voting-default-pool-2393733d-3flq                Deleting node gke-portable-voting-default-pool-2393733d-3flq because it does not exist in the cloud provider
default                       37m         Normal    RemovingNode                             node/gke-portable-voting-default-pool-2393733d-3flq                Node gke-portable-voting-default-pool-2393733d-3flq event: Removing Node gke-portable-voting-default-pool-2393733d-3flq from Controller
default                       35m         Normal    NodeAllocatableEnforced                  node/gke-portable-voting-default-pool-cc21b921-hl2v                Updated Node Allocatable limit across pods
default                       35m         Normal    Starting                                 node/gke-portable-voting-default-pool-cc21b921-hl2v                Starting kubelet.
default                       35m         Warning   InvalidDiskCapacity                      node/gke-portable-voting-default-pool-cc21b921-hl2v                invalid capacity 0 on image filesystem
default                       35m         Normal    NodeHasSufficientMemory                  node/gke-portable-voting-default-pool-cc21b921-hl2v                Node gke-portable-voting-default-pool-cc21b921-hl2v status is now: NodeHasSufficientMemory
default                       35m         Normal    NodeHasNoDiskPressure                    node/gke-portable-voting-default-pool-cc21b921-hl2v                Node gke-portable-voting-default-pool-cc21b921-hl2v status is now: NodeHasNoDiskPressure
default                       35m         Normal    NodeHasSufficientPID                     node/gke-portable-voting-default-pool-cc21b921-hl2v                Node gke-portable-voting-default-pool-cc21b921-hl2v status is now: NodeHasSufficientPID
kube-system                   35m         Normal    Scheduled                                pod/node-local-dns-vmlt6                                           Successfully assigned kube-system/node-local-dns-vmlt6 to gke-portable-voting-default-pool-cc21b921-hl2v
gmp-system                    35m         Normal    SuccessfulCreate                         daemonset/collector                                                Created pod: collector-n9zbf
kube-system                   35m         Normal    SuccessfulCreate                         daemonset/gke-metrics-agent                                        Created pod: gke-metrics-agent-slgq6
gmp-system                    35m         Warning   FailedScheduling                         pod/gmp-operator-6875fdf876-vzg2n                                  0/1 nodes are available: 1 node(s) had untolerated taint(s). no new claims to deallocate, preemption: 0/1 nodes are available: 1 Preemption is not helpful for scheduling.
kube-system                   35m         Normal    SuccessfulCreate                         daemonset/netd                                                     Created pod: netd-cw88m
default                       35m         Normal    Synced                                   node/gke-portable-voting-default-pool-cc21b921-hl2v                Node synced successfully
kube-system                   35m         Normal    SuccessfulCreate                         daemonset/pdcsi-node                                               Created pod: pdcsi-node-xbn5r
kube-system                   35m         Warning   FailedScheduling                         pod/antrea-controller-horizontal-autoscaler-5f556bf8c6-pr5xs       0/1 nodes are available: 1 node(s) had untolerated taint(s). no new claims to deallocate, preemption: 0/1 nodes are available: 1 Preemption is not helpful for scheduling.
kube-system                   35m         Normal    Scheduled                                pod/fluentbit-gke-mqlk7                                            Successfully assigned kube-system/fluentbit-gke-mqlk7 to gke-portable-voting-default-pool-cc21b921-hl2v
kube-system                   35m         Warning   FailedMount                              pod/node-local-dns-vmlt6                                           MountVolume.SetUp failed for volume "nodelocaldns-metrics-collector-config-map-vol" : object "kube-system"/"nodelocaldns-metrics-collector-config-map" not registered
kube-system                   35m         Warning   FailedScheduling                         pod/konnectivity-agent-5446844985-c46v8                            0/1 nodes are available: 1 node(s) had untolerated taint(s). no new claims to deallocate, preemption: 0/1 nodes are available: 1 Preemption is not helpful for scheduling.
kube-system                   35m         Warning   FailedScheduling                         pod/l7-default-backend-58ffbbd58-gr22t                             0/1 nodes are available: 1 node(s) had untolerated taint(s). no new claims to deallocate, preemption: 0/1 nodes are available: 1 Preemption is not helpful for scheduling.
kube-system                   35m         Warning   FailedMount                              pod/node-local-dns-vmlt6                                           MountVolume.SetUp failed for volume "config-volume" : object "kube-system"/"node-local-dns" not registered
kube-system                   35m         Warning   FailedScheduling                         pod/metrics-server-v1.35.1-6559d8569d-vttnf                        0/1 nodes are available: 1 node(s) had untolerated taint(s). no new claims to deallocate, preemption: 0/1 nodes are available: 1 Preemption is not helpful for scheduling.
gke-managed-cim               35m         Warning   FailedScheduling                         pod/kube-state-metrics-0                                           0/1 nodes are available: 1 node(s) had untolerated taint(s). no new claims to deallocate, preemption: 0/1 nodes are available: 1 Preemption is not helpful for scheduling.
kube-system                   35m         Warning   FailedMount                              pod/node-local-dns-vmlt6                                           MountVolume.SetUp failed for volume "kube-dns-config" : object "kube-system"/"kube-dns" not registered
kube-system                   35m         Warning   FailedScheduling                         pod/konnectivity-agent-autoscaler-685569f784-vb7c2                 0/1 nodes are available: 1 node(s) had untolerated taint(s). no new claims to deallocate, preemption: 0/1 nodes are available: 1 Preemption is not helpful for scheduling.
kube-system                   35m         Normal    Scheduled                                pod/gke-metrics-agent-slgq6                                        Successfully assigned kube-system/gke-metrics-agent-slgq6 to gke-portable-voting-default-pool-cc21b921-hl2v
kube-system                   35m         Warning   FailedScheduling                         pod/metrics-server-v1.35.1-78f45667d-2k56n                         0/1 nodes are available: 1 node(s) had untolerated taint(s). no new claims to deallocate, preemption: 0/1 nodes are available: 1 Preemption is not helpful for scheduling.
kube-system                   35m         Normal    Scheduled                                pod/pdcsi-node-xbn5r                                               Successfully assigned kube-system/pdcsi-node-xbn5r to gke-portable-voting-default-pool-cc21b921-hl2v
kube-system                   35m         Warning   NetworkNotReady                          pod/node-local-dns-vmlt6                                           network is not ready: container runtime network not ready: NetworkReady=false reason:NetworkPluginNotReady message:Network plugin returns error: cni plugin not initialized
kube-system                   35m         Warning   FailedScheduling                         pod/kube-dns-autoscaler-5dc7b666d8-cq7fg                           0/1 nodes are available: 1 node(s) had untolerated taint(s). no new claims to deallocate, preemption: 0/1 nodes are available: 1 Preemption is not helpful for scheduling.
kube-system                   35m         Normal    SuccessfulCreate                         daemonset/anetd                                                    Created pod: anetd-bf4p6
gmp-system                    35m         Warning   FailedScheduling                         pod/rule-evaluator-79c78c4fd5-gws5x                                0/1 nodes are available: 1 node(s) had untolerated taint(s). no new claims to deallocate, preemption: 0/1 nodes are available: 1 Preemption is not helpful for scheduling.
kube-system                   35m         Warning   FailedScheduling                         pod/kube-dns-78d5d95979-t7tnw                                      0/1 nodes are available: 1 node(s) had untolerated taint(s). no new claims to deallocate, preemption: 0/1 nodes are available: 1 Preemption is not helpful for scheduling.
kube-system                   35m         Normal    SuccessfulCreate                         daemonset/node-local-dns                                           Created pod: node-local-dns-vmlt6
kube-system                   35m         Normal    SuccessfulCreate                         daemonset/fluentbit-gke                                            Created pod: fluentbit-gke-mqlk7
gmp-system                    35m         Normal    Scheduled                                pod/collector-n9zbf                                                Successfully assigned gmp-system/collector-n9zbf to gke-portable-voting-default-pool-cc21b921-hl2v
gmp-system                    35m         Warning   FailedMount                              pod/collector-n9zbf                                                MountVolume.SetUp failed for volume "config" : object "gmp-system"/"collector" not registered
gmp-system                    35m         Warning   FailedScheduling                         pod/alertmanager-0                                                 0/1 nodes are available: 1 node(s) had untolerated taint(s). no new claims to deallocate, preemption: 0/1 nodes are available: 1 Preemption is not helpful for scheduling.
kube-system                   35m         Normal    Scheduled                                pod/anetd-bf4p6                                                    Successfully assigned kube-system/anetd-bf4p6 to gke-portable-voting-default-pool-cc21b921-hl2v
default                       35m         Warning   NodeRegistrationCheckerStart             node/gke-portable-voting-default-pool-cc21b921-hl2v                Thu Aug 20 10:16:21 UTC 2026 - ** Starting Node Registration Checker **
gmp-system                    35m         Warning   NetworkNotReady                          pod/collector-n9zbf                                                network is not ready: container runtime network not ready: NetworkReady=false reason:NetworkPluginNotReady message:Network plugin returns error: cni plugin not initialized
gmp-system                    35m         Warning   FailedMount                              pod/collector-n9zbf                                                MountVolume.SetUp failed for volume "collection-secret" : object "gmp-system"/"collection" not registered
kube-system                   35m         Warning   FailedScheduling                         pod/event-exporter-gke-7dc55f4f5f-fdvkm                            0/1 nodes are available: 1 node(s) had untolerated taint(s). no new claims to deallocate, preemption: 0/1 nodes are available: 1 Preemption is not helpful for scheduling.
gmp-system                    35m         Warning   FailedMount                              pod/collector-n9zbf                                                MountVolume.SetUp failed for volume "kube-api-access-kz9k6" : object "gmp-system"/"kube-root-ca.crt" not registered
kube-system                   35m         Normal    Scheduled                                pod/netd-cw88m                                                     Successfully assigned kube-system/netd-cw88m to gke-portable-voting-default-pool-cc21b921-hl2v
kube-system                   35m         Normal    Pulling                                  pod/fluentbit-gke-mqlk7                                            Pulling image "europe-west3-artifactregistry.gcr.io/gke-release/gke-release/node_token_broker/init:gke_node_token_broker_init_20260222.00_p0@sha256:f1538ec13c7dbe0e95cd5aab7a25c29280d41a3909d86d400b43d66b54642da8"
default                       35m         Normal    RegisteredNode                           node/gke-portable-voting-default-pool-cc21b921-hl2v                Node gke-portable-voting-default-pool-cc21b921-hl2v event: Registered Node gke-portable-voting-default-pool-cc21b921-hl2v in Controller
kube-system                   35m         Normal    Pulling                                  pod/gke-metrics-agent-slgq6                                        Pulling image "europe-west3-artifactregistry.gcr.io/gke-release/gke-release/node_token_broker/init:gke_node_token_broker_init_20260312.00_p0@sha256:d31f982e00598633fd2e94787f76894e29e80a3d87f5e15eacfc42b40e866de8"
kube-system                   35m         Normal    Pulling                                  pod/pdcsi-node-xbn5r                                               Pulling image "europe-west3-artifactregistry.gcr.io/gke-release/gke-release/gcp-compute-persistent-disk-csi-driver:v1.23.1-gke.20@sha256:fc65b739e47e804ec6c93f4a2a8d8a2dbcaa2c1dd91f082fdb0c4266856d12ce"
kube-system                   35m         Normal    Pulled                                   pod/netd-cw88m                                                     Container image "europe-west3-artifactregistry.gcr.io/gke-release/gke-release/netd-init:v0.10.12-gke.16@sha256:7c17ea472a942f1c612d26e240c15c79d9d0e9d4339010983785563559a11cdc" already present on machine and can be accessed by the pod
kube-system                   35m         Normal    Pulled                                   pod/anetd-bf4p6                                                    Container image "europe-west3-artifactregistry.gcr.io/gke-release/gke-release/anet/cni-writer:v0.1.40-gke.0@sha256:67f53cef809fb894cad4b99137539fe57f46a6a1e0346b1cd1f598fd92801093" already present on machine and can be accessed by the pod
default                       35m         Warning   NodeSysctlChange                         node/gke-portable-voting-default-pool-cc21b921-hl2v                Node condition SysctlChanged is now: True, reason: NodeSysctlChange, message: "{\"unmanaged\": {\"kernel.cad_pid\": \"1\"}}"
kube-system                   35m         Normal    Started                                  pod/anetd-bf4p6                                                    Container started
default                       35m         Warning   ContainerdStart                          node/gke-portable-voting-default-pool-cc21b921-hl2v                Starting containerd.service...
kube-system                   35m         Normal    Created                                  pod/anetd-bf4p6                                                    Container created
kube-system                   35m         Normal    Pulled                                   pod/anetd-bf4p6                                                    Container image "europe-west3-artifactregistry.gcr.io/gke-release/gke-release/cilium/cilium:v1.18.7-gke1.35-gke.14@sha256:2170ed688661e1b038eaed32840e7d207a13589471bd7251ccc0c184cbb1eb3f" already present on machine and can be accessed by the pod
default                       35m         Warning   DockerStart                              node/gke-portable-voting-default-pool-cc21b921-hl2v                Starting docker.service...
default                       35m         Warning   KubeletStart                             node/gke-portable-voting-default-pool-cc21b921-hl2v                Started kubelet.service.
default                       35m         Normal    NodeReady                                node/gke-portable-voting-default-pool-cc21b921-hl2v                Node gke-portable-voting-default-pool-cc21b921-hl2v status is now: NodeReady
kube-system                   35m         Normal    Scheduled                                pod/metrics-server-v1.35.1-6559d8569d-vttnf                        Successfully assigned kube-system/metrics-server-v1.35.1-6559d8569d-vttnf to gke-portable-voting-default-pool-cc21b921-hl2v
kube-system                   35m         Normal    Scheduled                                pod/kube-dns-autoscaler-5dc7b666d8-cq7fg                           Successfully assigned kube-system/kube-dns-autoscaler-5dc7b666d8-cq7fg to gke-portable-voting-default-pool-cc21b921-hl2v
gmp-system                    35m         Warning   FailedMount                              pod/alertmanager-0                                                 MountVolume.SetUp failed for volume "config" : secret "alertmanager" not found
kube-system                   35m         Normal    Scheduled                                pod/antrea-controller-horizontal-autoscaler-5f556bf8c6-pr5xs       Successfully assigned kube-system/antrea-controller-horizontal-autoscaler-5f556bf8c6-pr5xs to gke-portable-voting-default-pool-cc21b921-hl2v
kube-system                   35m         Normal    Scheduled                                pod/konnectivity-agent-autoscaler-685569f784-vb7c2                 Successfully assigned kube-system/konnectivity-agent-autoscaler-685569f784-vb7c2 to gke-portable-voting-default-pool-cc21b921-hl2v
gmp-system                    35m         Normal    Scheduled                                pod/alertmanager-0                                                 Successfully assigned gmp-system/alertmanager-0 to gke-portable-voting-default-pool-cc21b921-hl2v
gke-managed-cim               35m         Normal    Scheduled                                pod/kube-state-metrics-0                                           Successfully assigned gke-managed-cim/kube-state-metrics-0 to gke-portable-voting-default-pool-cc21b921-hl2v
kube-system                   35m         Normal    Scheduled                                pod/metrics-server-v1.35.1-78f45667d-2k56n                         Successfully assigned kube-system/metrics-server-v1.35.1-78f45667d-2k56n to gke-portable-voting-default-pool-cc21b921-hl2v
kube-system                   35m         Normal    Scheduled                                pod/event-exporter-gke-7dc55f4f5f-fdvkm                            Successfully assigned kube-system/event-exporter-gke-7dc55f4f5f-fdvkm to gke-portable-voting-default-pool-cc21b921-hl2v
default                       35m         Warning   ReadOnlyFileSystemDetected               node/gke-portable-voting-default-pool-cc21b921-hl2v
gmp-system                    35m         Normal    Scheduled                                pod/gmp-operator-6875fdf876-vzg2n                                  Successfully assigned gmp-system/gmp-operator-6875fdf876-vzg2n to gke-portable-voting-default-pool-cc21b921-hl2v
kube-system                   35m         Normal    Scheduled                                pod/l7-default-backend-58ffbbd58-gr22t                             Successfully assigned kube-system/l7-default-backend-58ffbbd58-gr22t to gke-portable-voting-default-pool-cc21b921-hl2v
gmp-system                    35m         Warning   FailedMount                              pod/rule-evaluator-79c78c4fd5-gws5x                                MountVolume.SetUp failed for volume "rules" : configmap "rules-generated" not found
kube-system                   35m         Normal    Scheduled                                pod/konnectivity-agent-5446844985-c46v8                            Successfully assigned kube-system/konnectivity-agent-5446844985-c46v8 to gke-portable-voting-default-pool-cc21b921-hl2v
kube-system                   35m         Normal    Scheduled                                pod/kube-dns-78d5d95979-t7tnw                                      Successfully assigned kube-system/kube-dns-78d5d95979-t7tnw to gke-portable-voting-default-pool-cc21b921-hl2v
gmp-system                    35m         Normal    Scheduled                                pod/rule-evaluator-79c78c4fd5-gws5x                                Successfully assigned gmp-system/rule-evaluator-79c78c4fd5-gws5x to gke-portable-voting-default-pool-cc21b921-hl2v
gmp-system                    35m         Warning   FailedMount                              pod/rule-evaluator-79c78c4fd5-gws5x                                MountVolume.SetUp failed for volume "rules-secret" : secret "rules" not found
gmp-system                    35m         Warning   FailedMount                              pod/rule-evaluator-79c78c4fd5-gws5x                                MountVolume.SetUp failed for volume "config" : configmap "rule-evaluator" not found
kube-system                   35m         Normal    Created                                  pod/netd-cw88m                                                     Container created
kube-system                   35m         Normal    Started                                  pod/netd-cw88m                                                     Container started
kube-system                   35m         Normal    Created                                  pod/anetd-bf4p6                                                    Container created
kube-system                   35m         Normal    Pulled                                   pod/netd-cw88m                                                     Container image "europe-west3-artifactregistry.gcr.io/gke-release/gke-release/node_token_broker/init:gke_node_token_broker_init_20251007.00_p0@sha256:638afa0822ed4c4aad9ff9f8528667a9d04dd5e1c7b1c251e9344ca7dd4aad68" already present on machine and can be accessed by the pod
kube-system                   35m         Normal    Created                                  pod/fluentbit-gke-mqlk7                                            Container created
kube-system                   35m         Normal    Created                                  pod/netd-cw88m                                                     Container created
gmp-system                    35m         Warning   FailedMount                              pod/collector-n9zbf                                                MountVolume.SetUp failed for volume "collection-secret" : secret "collection" not found
kube-system                   35m         Normal    Pulled                                   pod/fluentbit-gke-mqlk7                                            Successfully pulled image "europe-west3-artifactregistry.gcr.io/gke-release/gke-release/node_token_broker/init:gke_node_token_broker_init_20260222.00_p0@sha256:f1538ec13c7dbe0e95cd5aab7a25c29280d41a3909d86d400b43d66b54642da8" in 5.329s (5.329s including waiting). Image size: 2927935 bytes.
gmp-system                    35m         Warning   FailedMount                              pod/collector-n9zbf                                                MountVolume.SetUp failed for volume "config" : configmap "collector" not found
kube-system                   35m         Normal    Started                                  pod/anetd-bf4p6                                                    Container started
kube-system                   35m         Normal    Started                                  pod/netd-cw88m                                                     Container started
kube-system                   35m         Normal    Created                                  pod/gke-metrics-agent-slgq6                                        Container created
kube-system                   35m         Normal    Started                                  pod/fluentbit-gke-mqlk7                                            Container started
kube-system                   35m         Normal    Pulled                                   pod/gke-metrics-agent-slgq6                                        Successfully pulled image "europe-west3-artifactregistry.gcr.io/gke-release/gke-release/node_token_broker/init:gke_node_token_broker_init_20260312.00_p0@sha256:d31f982e00598633fd2e94787f76894e29e80a3d87f5e15eacfc42b40e866de8" in 1.739s (6.98s including waiting). Image size: 2929568 bytes.
kube-system                   35m         Normal    Pulled                                   pod/netd-cw88m                                                     Container image "europe-west3-artifactregistry.gcr.io/gke-release/gke-release/netd:v0.10.12-gke.16@sha256:cb62348b061dc61180a3879c13c7cf1d3176312a167196776cf829e5c90c86c9" already present on machine and can be accessed by the pod
kube-system                   35m         Normal    Pulling                                  pod/fluentbit-gke-mqlk7                                            Pulling image "europe-west3-artifactregistry.gcr.io/gke-release/gke-release/gke-distroless/bash:gke_distroless_20260615.00_p0@sha256:b98f4278dc5123fbad96c54ba8301c512d32f4716528ab30faea15108c68c52e"
kube-system                   35m         Normal    Pulled                                   pod/anetd-bf4p6                                                    Container image "europe-west3-artifactregistry.gcr.io/gke-release/gke-release/node_token_broker/init:gke_node_token_broker_init_20251010.00_p0@sha256:3615589424e94c68f8cee5d50c27c5a8b1a1f50ab5dc175a14e8540db7c80e8e" already present on machine and can be accessed by the pod
kube-system                   35m         Normal    Started                                  pod/gke-metrics-agent-slgq6                                        Container started
kube-system                   35m         Normal    Created                                  pod/anetd-bf4p6                                                    Container created
kube-system                   35m         Normal    Pulling                                  pod/antrea-controller-horizontal-autoscaler-5f556bf8c6-pr5xs       Pulling image "europe-west3-artifactregistry.gcr.io/gke-release/gke-release/cluster-proportional-autoscaler:v1.10.2-gke.24@sha256:1d07b99750cfa777b55d7a66e73c4e4241dca6b215715478deb5793263a91527"
kube-system                   35m         Normal    Created                                  pod/netd-cw88m                                                     Container created
gmp-system                    35m         Normal    Pulling                                  pod/gmp-operator-6875fdf876-vzg2n                                  Pulling image "europe-west3-artifactregistry.gcr.io/gke-release/gke-release/prometheus-engine/operator:v0.18.1-gke.2@sha256:d025fbed450a8c9849188630878834a18fcffb7c2916798be1308bea930fe838"
kube-system                   35m         Normal    Started                                  pod/netd-cw88m                                                     Container started
kube-system                   35m         Normal    Started                                  pod/anetd-bf4p6                                                    Container started
kube-system                   35m         Normal    Pulling                                  pod/konnectivity-agent-autoscaler-685569f784-vb7c2                 Pulling image "europe-west3-artifactregistry.gcr.io/gke-release/gke-release/cluster-proportional-autoscaler:v1.10.3-gke.8@sha256:437ad59d9fe3b37db75e0c1f5d74fe227abbba720bde166f52f3d71096b69aaf"
kube-system                   35m         Normal    Pulling                                  pod/gke-metrics-agent-slgq6                                        Pulling image "europe-west3-artifactregistry.gcr.io/gke-release/gke-release/gke-metrics-agent:1.16.1-gke.3@sha256:4cc4daca02a5928dd1c38b03ff421c9b3bca9cbc1249ccf69f8acfe3948ac1df"
kube-system                   35m         Normal    Pulling                                  pod/konnectivity-agent-5446844985-c46v8                            Pulling image "europe-west3-artifactregistry.gcr.io/gke-release/gke-release/node_token_broker/init:gke_node_token_broker_init_20251019.00_p0@sha256:2e1549e4692726aecc70364a1d6700cf276db2d9b4da90179284ca8de168c976"
kube-system                   35m         Normal    Pulled                                   pod/netd-cw88m                                                     Container image "europe-west3-artifactregistry.gcr.io/gke-release/gke-release/gke-metrics-collector:20251007_2300_RC0@sha256:0d590a9fb5339909d425b2eede28ac05cc76346092cbe82602c7618f047c25f0" already present on machine and can be accessed by the pod
kube-system                   35m         Normal    Pulled                                   pod/fluentbit-gke-mqlk7                                            Successfully pulled image "europe-west3-artifactregistry.gcr.io/gke-release/gke-release/gke-distroless/bash:gke_distroless_20260615.00_p0@sha256:b98f4278dc5123fbad96c54ba8301c512d32f4716528ab30faea15108c68c52e" in 1.747s (1.748s including waiting). Image size: 18877251 bytes.
kube-system                   35m         Normal    Created                                  pod/netd-cw88m                                                     Container created
kube-system                   35m         Normal    Pulling                                  pod/kube-dns-78d5d95979-t7tnw                                      Pulling image "europe-west3-artifactregistry.gcr.io/gke-release/gke-release/node_token_broker/init:gke_node_token_broker_init_20260412.00_p0@sha256:10a31e4c4338b37a10dbf4dfeaabd58a95b711e59abb740de628c32748184831"
gke-managed-cim               35m         Normal    Created                                  pod/kube-state-metrics-0                                           Container created
kube-system                   35m         Normal    Pulling                                  pod/metrics-server-v1.35.1-6559d8569d-vttnf                        Pulling image "europe-west3-artifactregistry.gcr.io/gke-release/gke-release/metrics-server:v0.8.0-gke.23@sha256:208c1ced1b6a551a067e526b616caf0e0da8fa98a60b3d22e9177c86563d17d0"
kube-system                   35m         Normal    Pulling                                  pod/l7-default-backend-58ffbbd58-gr22t                             Pulling image "europe-west3-artifactregistry.gcr.io/gke-release/gke-release/ingress-gce-404-server-with-metrics:v1.38.7@sha256:bce3b45becb05edaf0fbac1159453a3a1e4d6407be41347f9a8f0114a1b61487"
gke-managed-cim               35m         Normal    Pulled                                   pod/kube-state-metrics-0                                           Container image "europe-west3-artifactregistry.gcr.io/gke-release/gke-release/node_token_broker/init:gke_node_token_broker_init_20260410.00_p0@sha256:48b18ce5260a479f47611fdff76075e816422c28dce0cab772ba627c508159b4" already present on machine and can be accessed by the pod
kube-system                   35m         Normal    Created                                  pod/fluentbit-gke-mqlk7                                            Container created
kube-system                   35m         Normal    Pulled                                   pod/anetd-bf4p6                                                    Container image "europe-west3-artifactregistry.gcr.io/gke-release/gke-release/cilium/cilium:v1.18.7-gke1.35-gke.14@sha256:2170ed688661e1b038eaed32840e7d207a13589471bd7251ccc0c184cbb1eb3f" already present on machine and can be accessed by the pod
kube-system                   35m         Normal    Started                                  pod/netd-cw88m                                                     Container started
kube-system                   35m         Normal    Pulling                                  pod/event-exporter-gke-7dc55f4f5f-fdvkm                            Pulling image "europe-west3-artifactregistry.gcr.io/gke-release/gke-release/node_token_broker/init:gke_node_token_broker_init_20260716.00_p0@sha256:134942efd2defb12c04345e6713ea73613466b7b281d2800c287b51c55ec0b00"
kube-system                   35m         Normal    Pulling                                  pod/metrics-server-v1.35.1-78f45667d-2k56n                         Pulling image "europe-west3-artifactregistry.gcr.io/gke-release/gke-release/metrics-server:v0.8.0-gke.23@sha256:208c1ced1b6a551a067e526b616caf0e0da8fa98a60b3d22e9177c86563d17d0"
kube-system                   35m         Normal    Started                                  pod/fluentbit-gke-mqlk7                                            Container started
kube-system                   35m         Normal    Pulling                                  pod/kube-dns-autoscaler-5dc7b666d8-cq7fg                           Pulling image "europe-west3-artifactregistry.gcr.io/gke-release/gke-release/cluster-proportional-autoscaler:v1.10.3-gke.2@sha256:608476c370ab6d23cf62b3cb470b0480c446ff43fc6fa48959aa5d90f235722e"
kube-system                   35m         Normal    Pulling                                  pod/node-local-dns-vmlt6                                           Pulling image "europe-west3-artifactregistry.gcr.io/gke-release/gke-release/node_token_broker/init:gke_node_token_broker_init_20260422.00_p0@sha256:4ceac22ea251c0996e6f58165c9b79b44bd98de251a4b38ffaf072a89974671c"
gke-managed-cim               35m         Normal    Started                                  pod/kube-state-metrics-0                                           Container started
kube-system                   35m         Normal    Created                                  pod/anetd-bf4p6                                                    Container created
kube-system                   35m         Normal    Created                                  pod/anetd-bf4p6                                                    Container created
gke-managed-cim               35m         Normal    Pulling                                  pod/kube-state-metrics-0                                           Pulling image "europe-west3-artifactregistry.gcr.io/gke-release/gke-release/kube-state-metrics:v2.14.0-gke.58@sha256:04af0a0c7c400073ade2a5cb1b452df7ec3af5b55fba5718dc13b1629ed73a7d"
kube-system                   35m         Normal    Started                                  pod/anetd-bf4p6                                                    Container started
kube-system                   35m         Normal    Pulling                                  pod/fluentbit-gke-mqlk7                                            Pulling image "europe-west3-artifactregistry.gcr.io/gke-release/gke-release/fluent-bit:v0.0.422-gke.2@sha256:4b5df304074c9f2842f16ef4869c0ec253c2d91d6478e5aa42d2f8dce9146b45"
kube-system                   35m         Normal    Pulled                                   pod/anetd-bf4p6                                                    Container image "europe-west3-artifactregistry.gcr.io/gke-release/gke-release/gke-metrics-collector:20251009_2300_RC0@sha256:4c8e8cc4f739fc539e35c1581af031232d8885ee10f28484cb2085f5dfbb2b7d" already present on machine and can be accessed by the pod
kube-system                   35m         Normal    Pulled                                   pod/antrea-controller-horizontal-autoscaler-5f556bf8c6-pr5xs       Successfully pulled image "europe-west3-artifactregistry.gcr.io/gke-release/gke-release/cluster-proportional-autoscaler:v1.10.2-gke.24@sha256:1d07b99750cfa777b55d7a66e73c4e4241dca6b215715478deb5793263a91527" in 3.946s (5.601s including waiting). Image size: 13688349 bytes.
kube-system                   35m         Normal    Started                                  pod/anetd-bf4p6                                                    Container started
kube-system                   35m         Normal    Started                                  pod/antrea-controller-horizontal-autoscaler-5f556bf8c6-pr5xs       Container started
kube-system                   35m         Warning   Unhealthy                                pod/anetd-bf4p6                                                    Startup probe failed: Get "http://127.0.0.1:9879/healthz": dial tcp 127.0.0.1:9879: connect: connection refused
kube-system                   35m         Normal    Created                                  pod/antrea-controller-horizontal-autoscaler-5f556bf8c6-pr5xs       Container created
gmp-system                    35m         Normal    Created                                  pod/gmp-operator-6875fdf876-vzg2n                                  Container created
gmp-system                    35m         Warning   Unhealthy                                pod/gmp-operator-6875fdf876-vzg2n                                  Readiness probe failed: Get "http://10.68.0.2:18081/readyz": dial tcp 10.68.0.2:18081: connect: connection refused
gmp-system                    35m         Normal    Started                                  pod/gmp-operator-6875fdf876-vzg2n                                  Container started
gmp-system                    35m         Normal    Pulled                                   pod/gmp-operator-6875fdf876-vzg2n                                  Successfully pulled image "europe-west3-artifactregistry.gcr.io/gke-release/gke-release/prometheus-engine/operator:v0.18.1-gke.2@sha256:d025fbed450a8c9849188630878834a18fcffb7c2916798be1308bea930fe838" in 4.225s (9.144s including waiting). Image size: 49656818 bytes.
gmp-system                    35m         Warning   Unhealthy                                pod/gmp-operator-6875fdf876-vzg2n                                  Liveness probe failed: Get "http://10.68.0.2:18081/healthz": dial tcp 10.68.0.2:18081: connect: connection refused
kube-system                   5m23s       Normal    UpdateRedirectService                    redirectservice/default                                            Updating redirect service (resourceVersion = 1787220740935007005)
kube-system                   35m         Normal    Created                                  pod/konnectivity-agent-autoscaler-685569f784-vb7c2                 Container created
kube-system                   35m         Normal    Pulled                                   pod/konnectivity-agent-autoscaler-685569f784-vb7c2                 Successfully pulled image "europe-west3-artifactregistry.gcr.io/gke-release/gke-release/cluster-proportional-autoscaler:v1.10.3-gke.8@sha256:437ad59d9fe3b37db75e0c1f5d74fe227abbba720bde166f52f3d71096b69aaf" in 2.608s (11.184s including waiting). Image size: 13824914 bytes.
kube-system                   35m         Normal    Created                                  pod/konnectivity-agent-5446844985-c46v8                            Container created
kube-system                   35m         Normal    Pulled                                   pod/konnectivity-agent-5446844985-c46v8                            Successfully pulled image "europe-west3-artifactregistry.gcr.io/gke-release/gke-release/node_token_broker/init:gke_node_token_broker_init_20251019.00_p0@sha256:2e1549e4692726aecc70364a1d6700cf276db2d9b4da90179284ca8de168c976" in 845ms (11.929s including waiting). Image size: 2887395 bytes.
kube-system                   35m         Normal    Started                                  pod/konnectivity-agent-autoscaler-685569f784-vb7c2                 Container started
kube-system                   35m         Normal    Started                                  pod/konnectivity-agent-5446844985-c46v8                            Container started
kube-system                   35m         Normal    Created                                  pod/gke-metrics-agent-slgq6                                        Container created
kube-system                   35m         Normal    Pulled                                   pod/gke-metrics-agent-slgq6                                        Successfully pulled image "europe-west3-artifactregistry.gcr.io/gke-release/gke-release/gke-metrics-agent:1.16.1-gke.3@sha256:4cc4daca02a5928dd1c38b03ff421c9b3bca9cbc1249ccf69f8acfe3948ac1df" in 5.015s (16.827s including waiting). Image size: 31395961 bytes.
kube-system                   35m         Normal    Pulling                                  pod/konnectivity-agent-5446844985-c46v8                            Pulling image "europe-west3-artifactregistry.gcr.io/gke-release/gke-release/proxy-agent:v0.35.0-gke.1@sha256:2065f91ef5b24b14f6b9da1f1eedf83895d5167918a93cb1770c1124e4ab038d"
kube-system                   35m         Normal    Started                                  pod/gke-metrics-agent-slgq6                                        Container started
kube-system                   35m         Normal    Pulled                                   pod/kube-dns-78d5d95979-t7tnw                                      Successfully pulled image "europe-west3-artifactregistry.gcr.io/gke-release/gke-release/node_token_broker/init:gke_node_token_broker_init_20260412.00_p0@sha256:10a31e4c4338b37a10dbf4dfeaabd58a95b711e59abb740de628c32748184831" in 578ms (16.859s including waiting). Image size: 3374190 bytes.
kube-system                   35m         Normal    Created                                  pod/kube-dns-78d5d95979-t7tnw                                      Container created
kube-system                   35m         Normal    Started                                  pod/kube-dns-78d5d95979-t7tnw                                      Container started
kube-system                   35m         Normal    Pulled                                   pod/gke-metrics-agent-slgq6                                        Container image "europe-west3-artifactregistry.gcr.io/gke-release/gke-release/gke-metrics-agent:1.16.1-gke.3@sha256:4cc4daca02a5928dd1c38b03ff421c9b3bca9cbc1249ccf69f8acfe3948ac1df" already present on machine and can be accessed by the pod
kube-system                   35m         Normal    Created                                  pod/gke-metrics-agent-slgq6                                        Container created
default                       35m         Normal    NodeHasSufficientPID                     node/gke-portable-voting-default-pool-cc21b921-xfjv                Node gke-portable-voting-default-pool-cc21b921-xfjv status is now: NodeHasSufficientPID
default                       35m         Normal    NodeHasNoDiskPressure                    node/gke-portable-voting-default-pool-cc21b921-xfjv                Node gke-portable-voting-default-pool-cc21b921-xfjv status is now: NodeHasNoDiskPressure
default                       35m         Normal    Starting                                 node/gke-portable-voting-default-pool-cc21b921-xfjv                Starting kubelet.
default                       35m         Normal    NodeHasSufficientMemory                  node/gke-portable-voting-default-pool-cc21b921-xfjv                Node gke-portable-voting-default-pool-cc21b921-xfjv status is now: NodeHasSufficientMemory
default                       35m         Warning   InvalidDiskCapacity                      node/gke-portable-voting-default-pool-cc21b921-xfjv                invalid capacity 0 on image filesystem
default                       35m         Normal    NodeAllocatableEnforced                  node/gke-portable-voting-default-pool-cc21b921-xfjv                Updated Node Allocatable limit across pods
kube-system                   35m         Normal    SuccessfulCreate                         daemonset/node-local-dns                                           Created pod: node-local-dns-2zchx
kube-system                   35m         Normal    Pulling                                  pod/gke-metrics-agent-slgq6                                        Pulling image "europe-west3-artifactregistry.gcr.io/gke-release/gke-release/gke-metrics-collector:20250807_2300_RC0@sha256:aa1ed41571fa937da61b5bcd7cf842981c7f026b516c18655bc2f3a9362b1fa5"
kube-system                   35m         Normal    Scheduled                                pod/anetd-zk5wc                                                    Successfully assigned kube-system/anetd-zk5wc to gke-portable-voting-default-pool-cc21b921-xfjv
kube-system                   35m         Warning   FailedMount                              pod/node-local-dns-2zchx                                           MountVolume.SetUp failed for volume "kube-dns-config" : object "kube-system"/"kube-dns" not registered
gmp-system                    35m         Normal    Scheduled                                pod/collector-hxvls                                                Successfully assigned gmp-system/collector-hxvls to gke-portable-voting-default-pool-cc21b921-xfjv
kube-system                   35m         Warning   FailedMount                              pod/node-local-dns-2zchx                                           MountVolume.SetUp failed for volume "config-volume" : object "kube-system"/"node-local-dns" not registered
kube-system                   35m         Normal    SuccessfulCreate                         daemonset/pdcsi-node                                               Created pod: pdcsi-node-vxdw7
kube-system                   35m         Normal    SuccessfulCreate                         daemonset/anetd                                                    Created pod: anetd-zk5wc
gmp-system                    35m         Normal    SuccessfulCreate                         daemonset/collector                                                Created pod: collector-hxvls
kube-system                   35m         Normal    SuccessfulCreate                         daemonset/fluentbit-gke                                            Created pod: fluentbit-gke-dwjg6
kube-system                   35m         Warning   FailedMount                              pod/node-local-dns-2zchx                                           MountVolume.SetUp failed for volume "nodelocaldns-metrics-collector-config-map-vol" : object "kube-system"/"nodelocaldns-metrics-collector-config-map" not registered
default                       35m         Normal    RegisteredNode                           node/gke-portable-voting-default-pool-cc21b921-xfjv                Node gke-portable-voting-default-pool-cc21b921-xfjv event: Registered Node gke-portable-voting-default-pool-cc21b921-xfjv in Controller
kube-system                   35m         Normal    Started                                  pod/gke-metrics-agent-slgq6                                        Container started
kube-system                   35m         Normal    SuccessfulCreate                         daemonset/gke-metrics-agent                                        Created pod: gke-metrics-agent-gmz45
kube-system                   35m         Normal    Scheduled                                pod/fluentbit-gke-dwjg6                                            Successfully assigned kube-system/fluentbit-gke-dwjg6 to gke-portable-voting-default-pool-cc21b921-xfjv
kube-system                   35m         Normal    Scheduled                                pod/netd-49hll                                                     Successfully assigned kube-system/netd-49hll to gke-portable-voting-default-pool-cc21b921-xfjv
kube-system                   35m         Normal    Pulling                                  pod/kube-dns-78d5d95979-t7tnw                                      Pulling image "europe-west3-artifactregistry.gcr.io/gke-release/gke-release/k8s-dns-kube-dns:1.26.8-gke.3@sha256:e349d527bdfe0dfd02c26b38a94311415839ea30f48ca837d08ba5d9383f77cd"
kube-system                   35m         Warning   NetworkNotReady                          pod/node-local-dns-2zchx                                           network is not ready: container runtime network not ready: NetworkReady=false reason:NetworkPluginNotReady message:Network plugin returns error: cni plugin not initialized
kube-system                   35m         Normal    Scheduled                                pod/node-local-dns-2zchx                                           Successfully assigned kube-system/node-local-dns-2zchx to gke-portable-voting-default-pool-cc21b921-xfjv
kube-system                   35m         Normal    SuccessfulCreate                         daemonset/netd                                                     Created pod: netd-49hll
kube-system                   35m         Normal    Scheduled                                pod/pdcsi-node-vxdw7                                               Successfully assigned kube-system/pdcsi-node-vxdw7 to gke-portable-voting-default-pool-cc21b921-xfjv
gmp-system                    35m         Warning   FailedMount                              pod/collector-hxvls                                                MountVolume.SetUp failed for volume "collection-secret" : object "gmp-system"/"collection" not registered
kube-system                   35m         Normal    Scheduled                                pod/gke-metrics-agent-gmz45                                        Successfully assigned kube-system/gke-metrics-agent-gmz45 to gke-portable-voting-default-pool-cc21b921-xfjv
kube-system                   35m         Normal    Pulled                                   pod/l7-default-backend-58ffbbd58-gr22t                             Successfully pulled image "europe-west3-artifactregistry.gcr.io/gke-release/gke-release/ingress-gce-404-server-with-metrics:v1.38.7@sha256:bce3b45becb05edaf0fbac1159453a3a1e4d6407be41347f9a8f0114a1b61487" in 2.587s (18.917s including waiting). Image size: 7595136 bytes.
kube-system                   35m         Normal    Started                                  pod/l7-default-backend-58ffbbd58-gr22t                             Container started
default                       35m         Normal    Synced                                   node/gke-portable-voting-default-pool-cc21b921-xfjv                Node synced successfully
gmp-system                    35m         Warning   NetworkNotReady                          pod/collector-hxvls                                                network is not ready: container runtime network not ready: NetworkReady=false reason:NetworkPluginNotReady message:Network plugin returns error: cni plugin not initialized
gmp-system                    35m         Warning   FailedMount                              pod/collector-hxvls                                                MountVolume.SetUp failed for volume "kube-api-access-8cd55" : object "gmp-system"/"kube-root-ca.crt" not registered
kube-system                   35m         Normal    Created                                  pod/l7-default-backend-58ffbbd58-gr22t                             Container created
gmp-system                    35m         Warning   FailedMount                              pod/collector-hxvls                                                MountVolume.SetUp failed for volume "config" : object "gmp-system"/"collector" not registered
kube-system                   35m         Normal    Created                                  pod/pdcsi-node-xbn5r                                               Container created
default                       35m         Warning   NodeRegistrationCheckerStart             node/gke-portable-voting-default-pool-cc21b921-xfjv                Thu Aug 20 10:16:47 UTC 2026 - ** Starting Node Registration Checker **
kube-system                   35m         Normal    Pulled                                   pod/pdcsi-node-xbn5r                                               Successfully pulled image "europe-west3-artifactregistry.gcr.io/gke-release/gke-release/gcp-compute-persistent-disk-csi-driver:v1.23.1-gke.20@sha256:fc65b739e47e804ec6c93f4a2a8d8a2dbcaa2c1dd91f082fdb0c4266856d12ce" in 31.888s (31.888s including waiting). Image size: 124338789 bytes.
kube-system                   35m         Normal    Pulled                                   pod/anetd-zk5wc                                                    Container image "europe-west3-artifactregistry.gcr.io/gke-release/gke-release/anet/cni-writer:v0.1.40-gke.0@sha256:67f53cef809fb894cad4b99137539fe57f46a6a1e0346b1cd1f598fd92801093" already present on machine and can be accessed by the pod
kube-system                   35m         Normal    Pulling                                  pod/pdcsi-node-xbn5r                                               Pulling image "europe-west3-artifactregistry.gcr.io/gke-release/gke-release/gke-metrics-collector:20250311_2300_RC0@sha256:e6713a8266629d9e103f7b2c7715bf510170fe28ebe2dc341327fa5e6a0facde"
kube-system                   35m         Normal    Pulling                                  pod/fluentbit-gke-dwjg6                                            Pulling image "europe-west3-artifactregistry.gcr.io/gke-release/gke-release/node_token_broker/init:gke_node_token_broker_init_20260222.00_p0@sha256:f1538ec13c7dbe0e95cd5aab7a25c29280d41a3909d86d400b43d66b54642da8"
kube-system                   35m         Normal    Started                                  pod/pdcsi-node-xbn5r                                               Container started
kube-system                   35m         Normal    Pulled                                   pod/netd-49hll                                                     Container image "europe-west3-artifactregistry.gcr.io/gke-release/gke-release/netd-init:v0.10.12-gke.16@sha256:7c17ea472a942f1c612d26e240c15c79d9d0e9d4339010983785563559a11cdc" already present on machine and can be accessed by the pod
default                       35m         Warning   NodeSysctlChange                         node/gke-portable-voting-default-pool-cc21b921-xfjv                Node condition SysctlChanged is now: True, reason: NodeSysctlChange, message: "{\"unmanaged\": {\"kernel.cad_pid\": \"1\"}}"
kube-system                   35m         Normal    Created                                  pod/netd-49hll                                                     Container created
kube-system                   35m         Normal    Pulled                                   pod/metrics-server-v1.35.1-6559d8569d-vttnf                        Successfully pulled image "europe-west3-artifactregistry.gcr.io/gke-release/gke-release/metrics-server:v0.8.0-gke.23@sha256:208c1ced1b6a551a067e526b616caf0e0da8fa98a60b3d22e9177c86563d17d0" in 4.055s (22.823s including waiting). Image size: 22695603 bytes.
kube-system                   35m         Normal    Pulling                                  pod/pdcsi-node-vxdw7                                               Pulling image "europe-west3-artifactregistry.gcr.io/gke-release/gke-release/gcp-compute-persistent-disk-csi-driver:v1.23.1-gke.20@sha256:fc65b739e47e804ec6c93f4a2a8d8a2dbcaa2c1dd91f082fdb0c4266856d12ce"
kube-system                   35m         Normal    Created                                  pod/metrics-server-v1.35.1-6559d8569d-vttnf                        Container created
kube-system                   35m         Normal    Created                                  pod/anetd-zk5wc                                                    Container created
kube-system                   35m         Normal    Pulling                                  pod/gke-metrics-agent-gmz45                                        Pulling image "europe-west3-artifactregistry.gcr.io/gke-release/gke-release/node_token_broker/init:gke_node_token_broker_init_20260312.00_p0@sha256:d31f982e00598633fd2e94787f76894e29e80a3d87f5e15eacfc42b40e866de8"
kube-system                   35m         Normal    Pulled                                   pod/node-local-dns-vmlt6                                           Successfully pulled image "europe-west3-artifactregistry.gcr.io/gke-release/gke-release/node_token_broker/init:gke_node_token_broker_init_20260422.00_p0@sha256:4ceac22ea251c0996e6f58165c9b79b44bd98de251a4b38ffaf072a89974671c" in 823ms (23.562s including waiting). Image size: 3374191 bytes.
kube-system                   35m         Normal    Pulled                                   pod/metrics-server-v1.35.1-78f45667d-2k56n                         Successfully pulled image "europe-west3-artifactregistry.gcr.io/gke-release/gke-release/metrics-server:v0.8.0-gke.23@sha256:208c1ced1b6a551a067e526b616caf0e0da8fa98a60b3d22e9177c86563d17d0" in 227ms (23s including waiting). Image size: 22695603 bytes.
kube-system                   35m         Normal    Created                                  pod/node-local-dns-vmlt6                                           Container created
default                       35m         Warning   ContainerdStart                          node/gke-portable-voting-default-pool-cc21b921-xfjv                Starting containerd.service...
kube-system                   35m         Normal    Created                                  pod/kube-dns-autoscaler-5dc7b666d8-cq7fg                           Container created
default                       35m         Warning   DockerStart                              node/gke-portable-voting-default-pool-cc21b921-xfjv                Starting docker.service...
kube-system                   35m         Normal    Started                                  pod/anetd-zk5wc                                                    Container started
kube-system                   35m         Normal    Pulled                                   pod/kube-dns-autoscaler-5dc7b666d8-cq7fg                           Successfully pulled image "europe-west3-artifactregistry.gcr.io/gke-release/gke-release/cluster-proportional-autoscaler:v1.10.3-gke.2@sha256:608476c370ab6d23cf62b3cb470b0480c446ff43fc6fa48959aa5d90f235722e" in 2.584s (23.141s including waiting). Image size: 14214756 bytes.
kube-system                   35m         Normal    Started                                  pod/netd-49hll                                                     Container started
kube-system                   35m         Normal    Created                                  pod/metrics-server-v1.35.1-78f45667d-2k56n                         Container created
kube-system                   35m         Normal    Started                                  pod/kube-dns-autoscaler-5dc7b666d8-cq7fg                           Container started
kube-system                   35m         Normal    Started                                  pod/metrics-server-v1.35.1-6559d8569d-vttnf                        Container started
default                       35m         Warning   KubeletStart                             node/gke-portable-voting-default-pool-cc21b921-xfjv                Started kubelet.service.
kube-system                   35m         Normal    Pulled                                   pod/netd-49hll                                                     Container image "europe-west3-artifactregistry.gcr.io/gke-release/gke-release/node_token_broker/init:gke_node_token_broker_init_20251007.00_p0@sha256:638afa0822ed4c4aad9ff9f8528667a9d04dd5e1c7b1c251e9344ca7dd4aad68" already present on machine and can be accessed by the pod
kube-system                   35m         Normal    Pulled                                   pod/anetd-zk5wc                                                    Container image "europe-west3-artifactregistry.gcr.io/gke-release/gke-release/cilium/cilium:v1.18.7-gke1.35-gke.14@sha256:2170ed688661e1b038eaed32840e7d207a13589471bd7251ccc0c184cbb1eb3f" already present on machine and can be accessed by the pod
kube-system                   35m         Normal    Started                                  pod/node-local-dns-vmlt6                                           Container started
kube-system                   35m         Normal    Pulling                                  pod/node-local-dns-vmlt6                                           Pulling image "europe-west3-artifactregistry.gcr.io/gke-release/gke-release/k8s-dns-node-cache:1.26.8-gke.5@sha256:b466bc19f519bf5eb7ee278a57d33f9fdf253db8dd4e78677bd7b0373afcfea7"
kube-system                   35m         Normal    Started                                  pod/metrics-server-v1.35.1-78f45667d-2k56n                         Container started
kube-system                   35m         Normal    Created                                  pod/event-exporter-gke-7dc55f4f5f-fdvkm                            Container created
kube-system                   35m         Normal    Pulled                                   pod/event-exporter-gke-7dc55f4f5f-fdvkm                            Successfully pulled image "europe-west3-artifactregistry.gcr.io/gke-release/gke-release/node_token_broker/init:gke_node_token_broker_init_20260716.00_p0@sha256:134942efd2defb12c04345e6713ea73613466b7b281d2800c287b51c55ec0b00" in 3.504s (26.642s including waiting). Image size: 3338535 bytes.
default                       10m         Warning   ReadOnlyFileSystemDetected               node/gke-portable-voting-default-pool-cc21b921-xfjv
kube-system                   35m         Normal    SuccessfulCreate                         replicaset/kube-dns-78d5d95979                                     Created pod: kube-dns-78d5d95979-h7bfv
default                       35m         Normal    NodeReady                                node/gke-portable-voting-default-pool-cc21b921-xfjv                Node gke-portable-voting-default-pool-cc21b921-xfjv status is now: NodeReady
kube-system                   35m         Normal    Scheduled                                pod/kube-dns-78d5d95979-h7bfv                                      Successfully assigned kube-system/kube-dns-78d5d95979-h7bfv to gke-portable-voting-default-pool-cc21b921-hl2v
kube-system                   35m         Normal    ScalingReplicaSet                        deployment/kube-dns                                                Scaled up replica set kube-dns-78d5d95979 from 1 to 2
kube-system                   35m         Normal    Started                                  pod/event-exporter-gke-7dc55f4f5f-fdvkm                            Container started
gmp-system                    35m         Normal    ScalingReplicaSet                        deployment/rule-evaluator                                          Scaled down replica set rule-evaluator-79c78c4fd5 from 1 to 0
gmp-system                    35m         Normal    SuccessfulDelete                         replicaset/rule-evaluator-79c78c4fd5                               Deleted pod: rule-evaluator-79c78c4fd5-gws5x
gmp-system                    35m         Normal    SuccessfulDelete                         statefulset/alertmanager                                           Delete Pod alertmanager-0 in StatefulSet alertmanager successful
kube-system                   35m         Normal    Pulling                                  pod/event-exporter-gke-7dc55f4f5f-fdvkm                            Pulling image "europe-west3-artifactregistry.gcr.io/gke-release/gke-release/event-exporter:event-exporter-v0.5.12-gke.13@sha256:5606eef17770435b56842f0759c47bd9a0da9dd8a61eaa7eae34aedceedf4d43"
gke-managed-cim               35m         Normal    Pulled                                   pod/kube-state-metrics-0                                           Successfully pulled image "europe-west3-artifactregistry.gcr.io/gke-release/gke-release/kube-state-metrics:v2.14.0-gke.58@sha256:04af0a0c7c400073ade2a5cb1b452df7ec3af5b55fba5718dc13b1629ed73a7d" in 3.167s (28.401s including waiting). Image size: 15894304 bytes.
kube-system                   35m         Normal    Created                                  pod/netd-49hll                                                     Container created
kube-system                   35m         Normal    Created                                  pod/anetd-zk5wc                                                    Container created
kube-system                   35m         Normal    Scheduled                                pod/konnectivity-agent-5446844985-6p5d7                            Successfully assigned kube-system/konnectivity-agent-5446844985-6p5d7 to gke-portable-voting-default-pool-cc21b921-xfjv
gke-managed-cim               35m         Normal    Created                                  pod/kube-state-metrics-0                                           Container created
gke-managed-cim               35m         Normal    Started                                  pod/kube-state-metrics-0                                           Container started
kube-system                   35m         Normal    SuccessfulCreate                         replicaset/konnectivity-agent-5446844985                           Created pod: konnectivity-agent-5446844985-6p5d7
gke-managed-cim               35m         Normal    Pulling                                  pod/kube-state-metrics-0                                           Pulling image "europe-west3-artifactregistry.gcr.io/gke-release/gke-release/gke-metrics-collector:20260113_2300_RC0@sha256:5eb81dc265af031294a413a32fde1b59d5b8480e3f131a09b5a1059294aefd99"
kube-system                   35m         Normal    Pulled                                   pod/fluentbit-gke-dwjg6                                            Successfully pulled image "europe-west3-artifactregistry.gcr.io/gke-release/gke-release/node_token_broker/init:gke_node_token_broker_init_20260222.00_p0@sha256:f1538ec13c7dbe0e95cd5aab7a25c29280d41a3909d86d400b43d66b54642da8" in 8.757s (8.777s including waiting). Image size: 2927935 bytes.
kube-system                   35m         Normal    ScalingReplicaSet                        deployment/konnectivity-agent                                      Scaled up replica set konnectivity-agent-5446844985 from 1 to 2
kube-system                   35m         Normal    Started                                  pod/netd-49hll                                                     Container started
kube-system                   35m         Normal    Created                                  pod/fluentbit-gke-dwjg6                                            Container created
kube-system                   35m         Normal    Started                                  pod/anetd-zk5wc                                                    Container started
kube-system                   35m         Normal    Pulled                                   pod/netd-49hll                                                     Container image "europe-west3-artifactregistry.gcr.io/gke-release/gke-release/netd:v0.10.12-gke.16@sha256:cb62348b061dc61180a3879c13c7cf1d3176312a167196776cf829e5c90c86c9" already present on machine and can be accessed by the pod
kube-system                   35m         Normal    Created                                  pod/gke-metrics-agent-gmz45                                        Container created
kube-system                   35m         Normal    Pulling                                  pod/fluentbit-gke-dwjg6                                            Pulling image "europe-west3-artifactregistry.gcr.io/gke-release/gke-release/gke-distroless/bash:gke_distroless_20260615.00_p0@sha256:b98f4278dc5123fbad96c54ba8301c512d32f4716528ab30faea15108c68c52e"
kube-system                   35m         Normal    Started                                  pod/fluentbit-gke-dwjg6                                            Container started
kube-system                   35m         Normal    Pulled                                   pod/anetd-zk5wc                                                    Container image "europe-west3-artifactregistry.gcr.io/gke-release/gke-release/node_token_broker/init:gke_node_token_broker_init_20251010.00_p0@sha256:3615589424e94c68f8cee5d50c27c5a8b1a1f50ab5dc175a14e8540db7c80e8e" already present on machine and can be accessed by the pod
kube-system                   35m         Normal    Created                                  pod/anetd-zk5wc                                                    Container created
kube-system                   35m         Normal    Pulled                                   pod/gke-metrics-agent-gmz45                                        Successfully pulled image "europe-west3-artifactregistry.gcr.io/gke-release/gke-release/node_token_broker/init:gke_node_token_broker_init_20260312.00_p0@sha256:d31f982e00598633fd2e94787f76894e29e80a3d87f5e15eacfc42b40e866de8" in 1.735s (10.1s including waiting). Image size: 2929568 bytes.
kube-system                   34m         Normal    Created                                  pod/konnectivity-agent-5446844985-c46v8                            Container created
kube-system                   34m         Normal    Pulled                                   pod/netd-49hll                                                     Container image "europe-west3-artifactregistry.gcr.io/gke-release/gke-release/gke-metrics-collector:20251007_2300_RC0@sha256:0d590a9fb5339909d425b2eede28ac05cc76346092cbe82602c7618f047c25f0" already present on machine and can be accessed by the pod
kube-system                   34m         Normal    Pulling                                  pod/konnectivity-agent-5446844985-6p5d7                            Pulling image "europe-west3-artifactregistry.gcr.io/gke-release/gke-release/node_token_broker/init:gke_node_token_broker_init_20251019.00_p0@sha256:2e1549e4692726aecc70364a1d6700cf276db2d9b4da90179284ca8de168c976"
kube-system                   34m         Normal    Started                                  pod/netd-49hll                                                     Container started
kube-system                   34m         Normal    Started                                  pod/gke-metrics-agent-gmz45                                        Container started
kube-system                   34m         Normal    Started                                  pod/anetd-zk5wc                                                    Container started
kube-system                   34m         Normal    Pulled                                   pod/anetd-zk5wc                                                    Container image "europe-west3-artifactregistry.gcr.io/gke-release/gke-release/cilium/cilium:v1.18.7-gke1.35-gke.14@sha256:2170ed688661e1b038eaed32840e7d207a13589471bd7251ccc0c184cbb1eb3f" already present on machine and can be accessed by the pod
kube-system                   34m         Normal    Pulled                                   pod/konnectivity-agent-5446844985-c46v8                            Successfully pulled image "europe-west3-artifactregistry.gcr.io/gke-release/gke-release/proxy-agent:v0.35.0-gke.1@sha256:2065f91ef5b24b14f6b9da1f1eedf83895d5167918a93cb1770c1124e4ab038d" in 3.43s (18.263s including waiting). Image size: 29774159 bytes.
kube-system                   34m         Normal    Created                                  pod/netd-49hll                                                     Container created
kube-system                   34m         Normal    Pulled                                   pod/fluentbit-gke-dwjg6                                            Successfully pulled image "europe-west3-artifactregistry.gcr.io/gke-release/gke-release/gke-distroless/bash:gke_distroless_20260615.00_p0@sha256:b98f4278dc5123fbad96c54ba8301c512d32f4716528ab30faea15108c68c52e" in 1.019s (1.019s including waiting). Image size: 18877251 bytes.
kube-system                   34m         Normal    Created                                  pod/netd-49hll                                                     Container created
kube-system                   34m         Normal    Pulled                                   pod/fluentbit-gke-mqlk7                                            Successfully pulled image "europe-west3-artifactregistry.gcr.io/gke-release/gke-release/fluent-bit:v0.0.422-gke.2@sha256:4b5df304074c9f2842f16ef4869c0ec253c2d91d6478e5aa42d2f8dce9146b45" in 10.528s (32.932s including waiting). Image size: 66344763 bytes.
kube-system                   34m         Normal    Started                                  pod/fluentbit-gke-dwjg6                                            Container started
kube-system                   34m         Normal    Created                                  pod/fluentbit-gke-mqlk7                                            Container created
kube-system                   34m         Normal    Started                                  pod/konnectivity-agent-5446844985-c46v8                            Container started
kube-system                   34m         Normal    Pulling                                  pod/konnectivity-agent-5446844985-c46v8                            Pulling image "europe-west3-artifactregistry.gcr.io/gke-release/gke-release/gke-metrics-collector:20260121_2300_RC0@sha256:3cbd2b897c681db94832b4e03e58e4e2168666259507ff8fb8ae43a01a3b5f5d"
kube-system                   34m         Normal    Created                                  pod/fluentbit-gke-dwjg6                                            Container created
kube-system                   34m         Normal    Pulling                                  pod/gke-metrics-agent-gmz45                                        Pulling image "europe-west3-artifactregistry.gcr.io/gke-release/gke-release/gke-metrics-agent:1.16.1-gke.3@sha256:4cc4daca02a5928dd1c38b03ff421c9b3bca9cbc1249ccf69f8acfe3948ac1df"
kube-system                   34m         Normal    Created                                  pod/anetd-zk5wc                                                    Container created
kube-system                   34m         Normal    Started                                  pod/netd-49hll                                                     Container started
kube-system                   34m         Normal    Started                                  pod/anetd-zk5wc                                                    Container started
kube-system                   34m         Normal    Pulled                                   pod/anetd-zk5wc                                                    Container image "europe-west3-artifactregistry.gcr.io/gke-release/gke-release/gke-metrics-collector:20251009_2300_RC0@sha256:4c8e8cc4f739fc539e35c1581af031232d8885ee10f28484cb2085f5dfbb2b7d" already present on machine and can be accessed by the pod
kube-system                   34m         Normal    Started                                  pod/fluentbit-gke-mqlk7                                            Container started
kube-system                   34m         Normal    Pulling                                  pod/fluentbit-gke-mqlk7                                            Pulling image "europe-west3-artifactregistry.gcr.io/gke-release/gke-release/fluent-bit-gke-exporter:v0.27.17-gke.20@sha256:67269cb89dbf9cf4e76e199a634c178eec76e74ae45694e8000893f7cae6179e"
kube-system                   34m         Normal    Created                                  pod/konnectivity-agent-5446844985-6p5d7                            Container created
kube-system                   34m         Normal    Pulled                                   pod/konnectivity-agent-5446844985-6p5d7                            Successfully pulled image "europe-west3-artifactregistry.gcr.io/gke-release/gke-release/node_token_broker/init:gke_node_token_broker_init_20251019.00_p0@sha256:2e1549e4692726aecc70364a1d6700cf276db2d9b4da90179284ca8de168c976" in 2.272s (2.272s including waiting). Image size: 2887395 bytes.
kube-system                   34m         Normal    Created                                  pod/anetd-zk5wc                                                    Container created
kube-system                   34m         Normal    Started                                  pod/konnectivity-agent-5446844985-6p5d7                            Container started
kube-system                   34m         Normal    Pulling                                  pod/fluentbit-gke-dwjg6                                            Pulling image "europe-west3-artifactregistry.gcr.io/gke-release/gke-release/fluent-bit:v0.0.422-gke.2@sha256:4b5df304074c9f2842f16ef4869c0ec253c2d91d6478e5aa42d2f8dce9146b45"
kube-system                   34m         Normal    Started                                  pod/anetd-zk5wc                                                    Container started
kube-system                   34m         Normal    Created                                  pod/kube-dns-78d5d95979-t7tnw                                      Container created
kube-system                   34m         Normal    Pulled                                   pod/kube-dns-78d5d95979-h7bfv                                      Container image "europe-west3-artifactregistry.gcr.io/gke-release/gke-release/node_token_broker/init:gke_node_token_broker_init_20260412.00_p0@sha256:10a31e4c4338b37a10dbf4dfeaabd58a95b711e59abb740de628c32748184831" already present on machine and can be accessed by the pod
kube-system                   34m         Normal    Pulled                                   pod/kube-dns-78d5d95979-t7tnw                                      Successfully pulled image "europe-west3-artifactregistry.gcr.io/gke-release/gke-release/k8s-dns-kube-dns:1.26.8-gke.3@sha256:e349d527bdfe0dfd02c26b38a94311415839ea30f48ca837d08ba5d9383f77cd" in 4.93s (19.922s including waiting). Image size: 30596335 bytes.
kube-system                   34m         Normal    Created                                  pod/kube-dns-78d5d95979-h7bfv                                      Container created
kube-system                   34m         Normal    Pulling                                  pod/node-local-dns-2zchx                                           Pulling image "europe-west3-artifactregistry.gcr.io/gke-release/gke-release/node_token_broker/init:gke_node_token_broker_init_20260422.00_p0@sha256:4ceac22ea251c0996e6f58165c9b79b44bd98de251a4b38ffaf072a89974671c"
kube-system                   34m         Normal    Pulled                                   pod/gke-metrics-agent-slgq6                                        Successfully pulled image "europe-west3-artifactregistry.gcr.io/gke-release/gke-release/gke-metrics-collector:20250807_2300_RC0@sha256:aa1ed41571fa937da61b5bcd7cf842981c7f026b516c18655bc2f3a9362b1fa5" in 4.784s (20.51s including waiting). Image size: 25459396 bytes.
kube-system                   34m         Normal    Created                                  pod/gke-metrics-agent-slgq6                                        Container created
kube-system                   34m         Normal    Started                                  pod/kube-dns-78d5d95979-t7tnw                                      Container started
gmp-system                    34m         Normal    Pulling                                  pod/collector-hxvls                                                Pulling image "europe-west3-artifactregistry.gcr.io/gke-release/gke-release/gke-distroless/bash:gke_distroless_20260715.00_p0@sha256:31d0dbad107b5a78e7c824250a9912aec521846b0813c48921d445fb204b197d"
kube-system                   34m         Normal    Started                                  pod/kube-dns-78d5d95979-h7bfv                                      Container started
kube-system                   34m         Warning   Unhealthy                                pod/anetd-zk5wc                                                    Startup probe failed: Get "http://127.0.0.1:9879/healthz": dial tcp 127.0.0.1:9879: connect: connection refused
kube-system                   34m         Normal    Pulling                                  pod/kube-dns-78d5d95979-t7tnw                                      Pulling image "europe-west3-artifactregistry.gcr.io/gke-release/gke-release/k8s-dns-dnsmasq-nanny:1.26.8-gke.3@sha256:b5a2a5d776d611873573087f2caae2655122eb6354ca33856358331a1dcb9f2a"
kube-system                   34m         Normal    Pulling                                  pod/konnectivity-agent-5446844985-6p5d7                            Pulling image "europe-west3-artifactregistry.gcr.io/gke-release/gke-release/proxy-agent:v0.35.0-gke.1@sha256:2065f91ef5b24b14f6b9da1f1eedf83895d5167918a93cb1770c1124e4ab038d"
kube-system                   34m         Normal    Started                                  pod/gke-metrics-agent-slgq6                                        Container started
kube-system                   34m         Normal    Pulled                                   pod/gke-metrics-agent-gmz45                                        Successfully pulled image "europe-west3-artifactregistry.gcr.io/gke-release/gke-release/gke-metrics-agent:1.16.1-gke.3@sha256:4cc4daca02a5928dd1c38b03ff421c9b3bca9cbc1249ccf69f8acfe3948ac1df" in 6.7s (8.829s including waiting). Image size: 31395961 bytes.
kube-system                   34m         Normal    Pulled                                   pod/kube-dns-78d5d95979-h7bfv                                      Container image "europe-west3-artifactregistry.gcr.io/gke-release/gke-release/k8s-dns-kube-dns:1.26.8-gke.3@sha256:e349d527bdfe0dfd02c26b38a94311415839ea30f48ca837d08ba5d9383f77cd" already present on machine and can be accessed by the pod
kube-system                   34m         Normal    Created                                  pod/gke-metrics-agent-gmz45                                        Container created
kube-system                   34m         Normal    Created                                  pod/kube-dns-78d5d95979-h7bfv                                      Container created
kube-system                   34m         Normal    Started                                  pod/kube-dns-78d5d95979-h7bfv                                      Container started
kube-system                   34m         Normal    Started                                  pod/gke-metrics-agent-gmz45                                        Container started
kube-system                   34m         Normal    Pulled                                   pod/gke-metrics-agent-gmz45                                        Container image "europe-west3-artifactregistry.gcr.io/gke-release/gke-release/gke-metrics-agent:1.16.1-gke.3@sha256:4cc4daca02a5928dd1c38b03ff421c9b3bca9cbc1249ccf69f8acfe3948ac1df" already present on machine and can be accessed by the pod
kube-system                   34m         Normal    Pulling                                  pod/kube-dns-78d5d95979-h7bfv                                      Pulling image "europe-west3-artifactregistry.gcr.io/gke-release/gke-release/k8s-dns-dnsmasq-nanny:1.26.8-gke.3@sha256:b5a2a5d776d611873573087f2caae2655122eb6354ca33856358331a1dcb9f2a"
kube-system                   34m         Normal    Started                                  pod/pdcsi-node-xbn5r                                               Container started
kube-system                   34m         Normal    Pulling                                  pod/pdcsi-node-xbn5r                                               Pulling image "europe-west3-artifactregistry.gcr.io/gke-release/gke-release/csi-node-driver-registrar:v2.15.0-gke.34@sha256:b38f4e46ad46c1f83f550d695812296b8d2d6a211c3fc0633f28979b0e958516"
kube-system                   34m         Normal    Created                                  pod/pdcsi-node-xbn5r                                               Container created
kube-system                   34m         Normal    Pulled                                   pod/pdcsi-node-xbn5r                                               Successfully pulled image "europe-west3-artifactregistry.gcr.io/gke-release/gke-release/gke-metrics-collector:20250311_2300_RC0@sha256:e6713a8266629d9e103f7b2c7715bf510170fe28ebe2dc341327fa5e6a0facde" in 6.023s (22.676s including waiting). Image size: 25809711 bytes.
kube-system                   34m         Normal    Created                                  pod/gke-metrics-agent-gmz45                                        Container created
kube-system                   34m         Normal    Started                                  pod/gke-metrics-agent-gmz45                                        Container started
kube-system                   34m         Normal    Pulling                                  pod/gke-metrics-agent-gmz45                                        Pulling image "europe-west3-artifactregistry.gcr.io/gke-release/gke-release/gke-metrics-collector:20250807_2300_RC0@sha256:aa1ed41571fa937da61b5bcd7cf842981c7f026b516c18655bc2f3a9362b1fa5"
kube-system                   34m         Normal    Started                                  pod/node-local-dns-vmlt6                                           Container started
kube-system                   4m45s       Normal    UpdateRedirectService                    redirectservice/default                                            Updating redirect service (resourceVersion = 1787220740935007005)
kube-system                   34m         Normal    Created                                  pod/node-local-dns-vmlt6                                           Container created
kube-system                   34m         Normal    Pulling                                  pod/node-local-dns-vmlt6                                           Pulling image "europe-west3-artifactregistry.gcr.io/gke-release/gke-release/gke-metrics-collector:20260422_2300_RC0@sha256:70625564549ccc35d34e119dd3e3d5e2f841be9c309940d3ed5bb4e649a3c59f"
kube-system                   34m         Normal    Pulled                                   pod/node-local-dns-vmlt6                                           Successfully pulled image "europe-west3-artifactregistry.gcr.io/gke-release/gke-release/k8s-dns-node-cache:1.26.8-gke.5@sha256:b466bc19f519bf5eb7ee278a57d33f9fdf253db8dd4e78677bd7b0373afcfea7" in 8.128s (21.594s including waiting). Image size: 52897804 bytes.
kube-system                   34m         Normal    Created                                  pod/event-exporter-gke-7dc55f4f5f-fdvkm                            Container created
kube-system                   34m         Normal    Started                                  pod/event-exporter-gke-7dc55f4f5f-fdvkm                            Container started
kube-system                   34m         Normal    Pulling                                  pod/event-exporter-gke-7dc55f4f5f-fdvkm                            Pulling image "europe-west3-artifactregistry.gcr.io/gke-release/gke-release/prometheus-to-sd:v0.12.4-gke.17@sha256:36bac51a639457b58b840088d23513eaf4ee0c3fcfcf0e0fe655434a78ee6745"
kube-system                   34m         Normal    Pulled                                   pod/event-exporter-gke-7dc55f4f5f-fdvkm                            Successfully pulled image "europe-west3-artifactregistry.gcr.io/gke-release/gke-release/event-exporter:event-exporter-v0.5.12-gke.13@sha256:5606eef17770435b56842f0759c47bd9a0da9dd8a61eaa7eae34aedceedf4d43" in 3.772s (19.275s including waiting). Image size: 30938128 bytes.
gke-managed-cim               34m         Normal    Pulled                                   pod/kube-state-metrics-0                                           Successfully pulled image "europe-west3-artifactregistry.gcr.io/gke-release/gke-release/gke-metrics-collector:20260113_2300_RC0@sha256:5eb81dc265af031294a413a32fde1b59d5b8480e3f131a09b5a1059294aefd99" in 2.63s (19.427s including waiting). Image size: 26332537 bytes.
kube-system                   34m         Normal    Pulled                                   pod/konnectivity-agent-5446844985-c46v8                            Successfully pulled image "europe-west3-artifactregistry.gcr.io/gke-release/gke-release/gke-metrics-collector:20260121_2300_RC0@sha256:3cbd2b897c681db94832b4e03e58e4e2168666259507ff8fb8ae43a01a3b5f5d" in 2.815s (16.591s including waiting). Image size: 26329267 bytes.
gke-managed-cim               34m         Normal    Started                                  pod/kube-state-metrics-0                                           Container started
gke-managed-cim               34m         Normal    Created                                  pod/kube-state-metrics-0                                           Container created
monitoring                    34m         Normal    Scheduled                                pod/prometheus-server-6858869b89-k2nmf                             Successfully assigned monitoring/prometheus-server-6858869b89-k2nmf to gke-portable-voting-default-pool-cc21b921-xfjv
monitoring                    34m         Normal    Scheduled                                pod/prometheus-prometheus-node-exporter-rt8nh                      Successfully assigned monitoring/prometheus-prometheus-node-exporter-rt8nh to gke-portable-voting-default-pool-cc21b921-xfjv
kube-system                   34m         Normal    Started                                  pod/konnectivity-agent-5446844985-c46v8                            Container started
kube-system                   34m         Normal    Created                                  pod/konnectivity-agent-5446844985-c46v8                            Container created
monitoring                    34m         Normal    ScalingReplicaSet                        deployment/prometheus-kube-state-metrics                           Scaled up replica set prometheus-kube-state-metrics-56c55854b6 from 0 to 1
monitoring                    34m         Normal    Scheduled                                pod/prometheus-prometheus-node-exporter-p6dcv                      Successfully assigned monitoring/prometheus-prometheus-node-exporter-p6dcv to gke-portable-voting-default-pool-cc21b921-hl2v
monitoring                    34m         Normal    ScalingReplicaSet                        deployment/prometheus-server                                       Scaled up replica set prometheus-server-6858869b89 from 0 to 1
monitoring                    34m         Normal    SuccessfulCreate                         replicaset/prometheus-server-6858869b89                            Created pod: prometheus-server-6858869b89-k2nmf
monitoring                    34m         Normal    Scheduled                                pod/prometheus-kube-state-metrics-56c55854b6-2fr9p                 Successfully assigned monitoring/prometheus-kube-state-metrics-56c55854b6-2fr9p to gke-portable-voting-default-pool-cc21b921-xfjv
monitoring                    34m         Normal    SuccessfulCreate                         replicaset/prometheus-kube-state-metrics-56c55854b6                Created pod: prometheus-kube-state-metrics-56c55854b6-2fr9p
monitoring                    34m         Normal    SuccessfulCreate                         daemonset/prometheus-prometheus-node-exporter                      Created pod: prometheus-prometheus-node-exporter-rt8nh
monitoring                    34m         Normal    SuccessfulCreate                         daemonset/prometheus-prometheus-node-exporter                      Created pod: prometheus-prometheus-node-exporter-p6dcv
gmp-system                    34m         Normal    Pulling                                  pod/collector-n9zbf                                                Pulling image "europe-west3-artifactregistry.gcr.io/gke-release/gke-release/gke-distroless/bash:gke_distroless_20260715.00_p0@sha256:31d0dbad107b5a78e7c824250a9912aec521846b0813c48921d445fb204b197d"
monitoring                    34m         Normal    Pulling                                  pod/prometheus-prometheus-node-exporter-p6dcv                      Pulling image "quay.io/prometheus/node-exporter:v1.11.1"
kube-system                   34m         Normal    Pulled                                   pod/kube-dns-78d5d95979-h7bfv                                      Successfully pulled image "europe-west3-artifactregistry.gcr.io/gke-release/gke-release/k8s-dns-dnsmasq-nanny:1.26.8-gke.3@sha256:b5a2a5d776d611873573087f2caae2655122eb6354ca33856358331a1dcb9f2a" in 334ms (10.16s including waiting). Image size: 33471642 bytes.
kube-system                   34m         Normal    Created                                  pod/kube-dns-78d5d95979-t7tnw                                      Container created
kube-system                   34m         Normal    Created                                  pod/fluentbit-gke-mqlk7                                            Container created
kube-system                   34m         Normal    Started                                  pod/fluentbit-gke-mqlk7                                            Container started
kube-system                   34m         Normal    Pulled                                   pod/kube-dns-78d5d95979-t7tnw                                      Successfully pulled image "europe-west3-artifactregistry.gcr.io/gke-release/gke-release/k8s-dns-dnsmasq-nanny:1.26.8-gke.3@sha256:b5a2a5d776d611873573087f2caae2655122eb6354ca33856358331a1dcb9f2a" in 2.728s (14.324s including waiting). Image size: 33471642 bytes.
kube-system                   34m         Normal    Pulled                                   pod/fluentbit-gke-mqlk7                                            Successfully pulled image "europe-west3-artifactregistry.gcr.io/gke-release/gke-release/fluent-bit-gke-exporter:v0.27.17-gke.20@sha256:67269cb89dbf9cf4e76e199a634c178eec76e74ae45694e8000893f7cae6179e" in 3.58s (18.307s including waiting). Image size: 36248865 bytes.
kube-system                   34m         Normal    Pulled                                   pod/fluentbit-gke-mqlk7                                            Container image "europe-west3-artifactregistry.gcr.io/gke-release/gke-release/gke-metrics-collector:20260617_2300_RC0@sha256:c8cd71f5cd9f076b55e3f1db733e6adacd6ad3cfabaa9eb467b0ece8e691d73b" already present on machine and can be accessed by the pod
kube-system                   34m         Normal    Created                                  pod/kube-dns-78d5d95979-h7bfv                                      Container created
kube-system                   34m         Normal    Started                                  pod/kube-dns-78d5d95979-t7tnw                                      Container started
kube-system                   34m         Normal    Pulling                                  pod/kube-dns-78d5d95979-t7tnw                                      Pulling image "europe-west3-artifactregistry.gcr.io/gke-release/gke-release/k8s-dns-sidecar:1.26.8-gke.3@sha256:58eed94278e7b43ad2f4c302fd7457e4b5429e1296854d75c75ad45646e259d0"
kube-system                   34m         Normal    Created                                  pod/fluentbit-gke-mqlk7                                            Container created
kube-system                   34m         Normal    Started                                  pod/kube-dns-78d5d95979-h7bfv                                      Container started
kube-system                   34m         Normal    Started                                  pod/fluentbit-gke-mqlk7                                            Container started
kube-system                   34m         Normal    Pulling                                  pod/kube-dns-78d5d95979-h7bfv                                      Pulling image "europe-west3-artifactregistry.gcr.io/gke-release/gke-release/k8s-dns-sidecar:1.26.8-gke.3@sha256:58eed94278e7b43ad2f4c302fd7457e4b5429e1296854d75c75ad45646e259d0"
traefik                       34m         Normal    SuccessfulCreate                         replicaset/traefik-586855547c                                      Created pod: traefik-586855547c-5snh2
monitoring                    34m         Normal    Pulling                                  pod/prometheus-prometheus-node-exporter-rt8nh                      Pulling image "quay.io/prometheus/node-exporter:v1.11.1"
kube-system                   34m         Normal    Pulled                                   pod/pdcsi-node-xbn5r                                               Successfully pulled image "europe-west3-artifactregistry.gcr.io/gke-release/gke-release/csi-node-driver-registrar:v2.15.0-gke.34@sha256:b38f4e46ad46c1f83f550d695812296b8d2d6a211c3fc0633f28979b0e958516" in 1.983s (10.781s including waiting). Image size: 14461369 bytes.
traefik                       33m         Normal    EnsuringLoadBalancer                     service/traefik                                                    Ensuring load balancer
traefik                       34m         Normal    ScalingReplicaSet                        deployment/traefik                                                 Scaled up replica set traefik-586855547c from 0 to 1
traefik                       34m         Normal    Scheduled                                pod/traefik-586855547c-5snh2                                       Successfully assigned traefik/traefik-586855547c-5snh2 to gke-portable-voting-default-pool-cc21b921-xfjv
kube-system                   34m         Normal    Created                                  pod/pdcsi-node-xbn5r                                               Container created
kube-system                   34m         Normal    Pulled                                   pod/node-local-dns-vmlt6                                           Successfully pulled image "europe-west3-artifactregistry.gcr.io/gke-release/gke-release/gke-metrics-collector:20260422_2300_RC0@sha256:70625564549ccc35d34e119dd3e3d5e2f841be9c309940d3ed5bb4e649a3c59f" in 2.441s (8.636s including waiting). Image size: 26354407 bytes.
kube-system                   34m         Normal    Started                                  pod/node-local-dns-vmlt6                                           Container started
kube-system                   34m         Normal    Created                                  pod/node-local-dns-vmlt6                                           Container created
kube-system                   34m         Normal    Started                                  pod/pdcsi-node-xbn5r                                               Container started
kube-system                   34m         Normal    Pulled                                   pod/fluentbit-gke-dwjg6                                            Successfully pulled image "europe-west3-artifactregistry.gcr.io/gke-release/gke-release/fluent-bit:v0.0.422-gke.2@sha256:4b5df304074c9f2842f16ef4869c0ec253c2d91d6478e5aa42d2f8dce9146b45" in 16.125s (21.732s including waiting). Image size: 66344763 bytes.
monitoring                    34m         Normal    Started                                  pod/prometheus-prometheus-node-exporter-p6dcv                      Container started
kube-system                   34m         Normal    Started                                  pod/event-exporter-gke-7dc55f4f5f-fdvkm                            Container started
kube-system                   34m         Normal    Pulled                                   pod/event-exporter-gke-7dc55f4f5f-fdvkm                            Successfully pulled image "europe-west3-artifactregistry.gcr.io/gke-release/gke-release/prometheus-to-sd:v0.12.4-gke.17@sha256:36bac51a639457b58b840088d23513eaf4ee0c3fcfcf0e0fe655434a78ee6745" in 2.58s (9.733s including waiting). Image size: 27311602 bytes.
monitoring                    34m         Normal    Created                                  pod/prometheus-prometheus-node-exporter-p6dcv                      Container created
monitoring                    34m         Normal    Pulled                                   pod/prometheus-prometheus-node-exporter-p6dcv                      Successfully pulled image "quay.io/prometheus/node-exporter:v1.11.1" in 2.401s (5.893s including waiting). Image size: 13308798 bytes.
kube-system                   34m         Normal    Created                                  pod/event-exporter-gke-7dc55f4f5f-fdvkm                            Container created
kube-system                   34m         Normal    Created                                  pod/fluentbit-gke-dwjg6                                            Container created
gmp-system                    34m         Normal    Started                                  pod/collector-n9zbf                                                Container started
gmp-system                    34m         Normal    Created                                  pod/collector-n9zbf                                                Container created
gmp-system                    34m         Normal    Pulled                                   pod/collector-n9zbf                                                Successfully pulled image "europe-west3-artifactregistry.gcr.io/gke-release/gke-release/gke-distroless/bash:gke_distroless_20260715.00_p0@sha256:31d0dbad107b5a78e7c824250a9912aec521846b0813c48921d445fb204b197d" in 2.025s (7.267s including waiting). Image size: 18866468 bytes.
kube-system                   34m         Normal    Started                                  pod/fluentbit-gke-dwjg6                                            Container started
kube-system                   34m         Normal    Pulling                                  pod/fluentbit-gke-dwjg6                                            Pulling image "europe-west3-artifactregistry.gcr.io/gke-release/gke-release/fluent-bit-gke-exporter:v0.27.17-gke.20@sha256:67269cb89dbf9cf4e76e199a634c178eec76e74ae45694e8000893f7cae6179e"
kube-system                   34m         Normal    Pulled                                   pod/node-local-dns-2zchx                                           Successfully pulled image "europe-west3-artifactregistry.gcr.io/gke-release/gke-release/node_token_broker/init:gke_node_token_broker_init_20260422.00_p0@sha256:4ceac22ea251c0996e6f58165c9b79b44bd98de251a4b38ffaf072a89974671c" in 1.175s (21.419s including waiting). Image size: 3374191 bytes.
kube-system                   34m         Normal    Created                                  pod/node-local-dns-2zchx                                           Container created
kube-system                   34m         Normal    Started                                  pod/node-local-dns-2zchx                                           Container started
kube-system                   34m         Normal    Pulled                                   pod/kube-dns-78d5d95979-h7bfv                                      Successfully pulled image "europe-west3-artifactregistry.gcr.io/gke-release/gke-release/k8s-dns-sidecar:1.26.8-gke.3@sha256:58eed94278e7b43ad2f4c302fd7457e4b5429e1296854d75c75ad45646e259d0" in 2.999s (8.83s including waiting). Image size: 27137227 bytes.
kube-system                   34m         Normal    Pulled                                   pod/kube-dns-78d5d95979-t7tnw                                      Successfully pulled image "europe-west3-artifactregistry.gcr.io/gke-release/gke-release/k8s-dns-sidecar:1.26.8-gke.3@sha256:58eed94278e7b43ad2f4c302fd7457e4b5429e1296854d75c75ad45646e259d0" in 4.466s (9.081s including waiting). Image size: 27137227 bytes.
kube-system                   34m         Normal    Pulling                                  pod/kube-dns-78d5d95979-t7tnw                                      Pulling image "europe-west3-artifactregistry.gcr.io/gke-release/gke-release/gke-metrics-collector:20260412_2300_RC0@sha256:fbc30ed703e17c3ae5622888145452d22865bb4f273db05321929a0fda0019a2"
kube-system                   34m         Normal    Pulling                                  pod/kube-dns-78d5d95979-h7bfv                                      Pulling image "europe-west3-artifactregistry.gcr.io/gke-release/gke-release/gke-metrics-collector:20260412_2300_RC0@sha256:fbc30ed703e17c3ae5622888145452d22865bb4f273db05321929a0fda0019a2"
kube-system                   34m         Normal    Created                                  pod/kube-dns-78d5d95979-h7bfv                                      Container created
gmp-system                    34m         Normal    Pulling                                  pod/collector-n9zbf                                                Pulling image "europe-west3-artifactregistry.gcr.io/gke-release/gke-release/node_token_broker/init:gke_node_token_broker_init_20260714.00_p0@sha256:e3c8889fcbb07392d3b8a8ff0d4cf80310cb116628c7742061d7c71855c326cb"
kube-system                   34m         Normal    Started                                  pod/kube-dns-78d5d95979-h7bfv                                      Container started
kube-system                   34m         Normal    Created                                  pod/kube-dns-78d5d95979-t7tnw                                      Container created
kube-system                   34m         Normal    Pulling                                  pod/node-local-dns-2zchx                                           Pulling image "europe-west3-artifactregistry.gcr.io/gke-release/gke-release/k8s-dns-node-cache:1.26.8-gke.5@sha256:b466bc19f519bf5eb7ee278a57d33f9fdf253db8dd4e78677bd7b0373afcfea7"
kube-system                   34m         Normal    Started                                  pod/kube-dns-78d5d95979-t7tnw                                      Container started
gmp-system                    34m         Normal    Created                                  pod/collector-n9zbf                                                Container created
kube-system                   34m         Normal    Pulling                                  pod/pdcsi-node-vxdw7                                               Pulling image "europe-west3-artifactregistry.gcr.io/gke-release/gke-release/gke-metrics-collector:20250311_2300_RC0@sha256:e6713a8266629d9e103f7b2c7715bf510170fe28ebe2dc341327fa5e6a0facde"
gmp-system                    34m         Normal    Pulled                                   pod/collector-n9zbf                                                Successfully pulled image "europe-west3-artifactregistry.gcr.io/gke-release/gke-release/node_token_broker/init:gke_node_token_broker_init_20260714.00_p0@sha256:e3c8889fcbb07392d3b8a8ff0d4cf80310cb116628c7742061d7c71855c326cb" in 619ms (620ms including waiting). Image size: 3337442 bytes.
kube-system                   34m         Normal    Created                                  pod/pdcsi-node-vxdw7                                               Container created
gmp-system                    34m         Normal    Started                                  pod/collector-n9zbf                                                Container started
kube-system                   34m         Normal    Started                                  pod/pdcsi-node-vxdw7                                               Container started
kube-system                   34m         Normal    Pulled                                   pod/pdcsi-node-vxdw7                                               Successfully pulled image "europe-west3-artifactregistry.gcr.io/gke-release/gke-release/gcp-compute-persistent-disk-csi-driver:v1.23.1-gke.20@sha256:fc65b739e47e804ec6c93f4a2a8d8a2dbcaa2c1dd91f082fdb0c4266856d12ce" in 42.938s (42.938s including waiting). Image size: 124338789 bytes.
gmp-system                    34m         Normal    Created                                  pod/collector-hxvls                                                Container created
kube-system                   34m         Normal    Created                                  pod/kube-dns-78d5d95979-t7tnw                                      Container created
kube-system                   34m         Normal    Pulled                                   pod/kube-dns-78d5d95979-t7tnw                                      Successfully pulled image "europe-west3-artifactregistry.gcr.io/gke-release/gke-release/gke-metrics-collector:20260412_2300_RC0@sha256:fbc30ed703e17c3ae5622888145452d22865bb4f273db05321929a0fda0019a2" in 1.688s (1.688s including waiting). Image size: 26315860 bytes.
gmp-system                    34m         Normal    Pulled                                   pod/collector-hxvls                                                Successfully pulled image "europe-west3-artifactregistry.gcr.io/gke-release/gke-release/gke-distroless/bash:gke_distroless_20260715.00_p0@sha256:31d0dbad107b5a78e7c824250a9912aec521846b0813c48921d445fb204b197d" in 6.534s (27.143s including waiting). Image size: 18866468 bytes.
kube-system                   34m         Normal    Created                                  pod/kube-dns-78d5d95979-h7bfv                                      Container created
kube-system                   34m         Normal    Pulled                                   pod/kube-dns-78d5d95979-h7bfv                                      Successfully pulled image "europe-west3-artifactregistry.gcr.io/gke-release/gke-release/gke-metrics-collector:20260412_2300_RC0@sha256:fbc30ed703e17c3ae5622888145452d22865bb4f273db05321929a0fda0019a2" in 1.122s (1.683s including waiting). Image size: 26315860 bytes.
gmp-system                    34m         Normal    Pulling                                  pod/collector-n9zbf                                                Pulling image "europe-west3-artifactregistry.gcr.io/gke-release/gke-release/prometheus-engine/prometheus:v2.53.5-gmp.5-gke.1@sha256:68038912eddca33347de1e85ffae8b785832303875957bd58d579a52ce8b6f93"
kube-system                   34m         Normal    Started                                  pod/kube-dns-78d5d95979-h7bfv                                      Container started
kube-system                   34m         Normal    Started                                  pod/kube-dns-78d5d95979-t7tnw                                      Container started
gmp-system                    34m         Normal    Started                                  pod/collector-hxvls                                                Container started
gmp-system                    34m         Normal    Pulling                                  pod/collector-hxvls                                                Pulling image "europe-west3-artifactregistry.gcr.io/gke-release/gke-release/node_token_broker/init:gke_node_token_broker_init_20260714.00_p0@sha256:e3c8889fcbb07392d3b8a8ff0d4cf80310cb116628c7742061d7c71855c326cb"
monitoring                    34m         Normal    Pulling                                  pod/prometheus-server-6858869b89-k2nmf                             Pulling image "quay.io/prometheus-operator/prometheus-config-reloader:v0.91.0"
traefik                       34m         Normal    Pulling                                  pod/traefik-586855547c-5snh2                                       Pulling image "docker.io/traefik:v3.7.6"
monitoring                    34m         Normal    Pulling                                  pod/prometheus-kube-state-metrics-56c55854b6-2fr9p                 Pulling image "registry.k8s.io/kube-state-metrics/kube-state-metrics:v2.18.0"
kube-system                   34m         Normal    Created                                  pod/konnectivity-agent-5446844985-6p5d7                            Container created
kube-system                   34m         Normal    Pulled                                   pod/konnectivity-agent-5446844985-6p5d7                            Successfully pulled image "europe-west3-artifactregistry.gcr.io/gke-release/gke-release/proxy-agent:v0.35.0-gke.1@sha256:2065f91ef5b24b14f6b9da1f1eedf83895d5167918a93cb1770c1124e4ab038d" in 7.766s (31.787s including waiting). Image size: 29774159 bytes.
gmp-system                    34m         Normal    Started                                  pod/collector-n9zbf                                                Container started
kube-system                   34m         Normal    Created                                  pod/gke-metrics-agent-gmz45                                        Container created
kube-system                   34m         Normal    Pulling                                  pod/konnectivity-agent-5446844985-6p5d7                            Pulling image "europe-west3-artifactregistry.gcr.io/gke-release/gke-release/gke-metrics-collector:20260121_2300_RC0@sha256:3cbd2b897c681db94832b4e03e58e4e2168666259507ff8fb8ae43a01a3b5f5d"
gmp-system                    34m         Normal    Pulled                                   pod/collector-n9zbf                                                Successfully pulled image "europe-west3-artifactregistry.gcr.io/gke-release/gke-release/prometheus-engine/prometheus:v2.53.5-gmp.5-gke.1@sha256:68038912eddca33347de1e85ffae8b785832303875957bd58d579a52ce8b6f93" in 6.194s (6.194s including waiting). Image size: 146494435 bytes.
gmp-system                    34m         Normal    Created                                  pod/collector-n9zbf                                                Container created
gmp-system                    34m         Normal    Pulling                                  pod/collector-n9zbf                                                Pulling image "europe-west3-artifactregistry.gcr.io/gke-release/gke-release/prometheus-engine/config-reloader:v0.18.1-gke.2@sha256:25c40417469953bd29e297733293bc1bc34d297e80dea7acc408492ba0d166d9"
kube-system                   34m         Normal    Started                                  pod/konnectivity-agent-5446844985-6p5d7                            Container started
kube-system                   34m         Normal    Pulled                                   pod/gke-metrics-agent-gmz45                                        Successfully pulled image "europe-west3-artifactregistry.gcr.io/gke-release/gke-release/gke-metrics-collector:20250807_2300_RC0@sha256:aa1ed41571fa937da61b5bcd7cf842981c7f026b516c18655bc2f3a9362b1fa5" in 6.924s (26.777s including waiting). Image size: 25459396 bytes.
gmp-system                    34m         Normal    Pulled                                   pod/collector-n9zbf                                                Successfully pulled image "europe-west3-artifactregistry.gcr.io/gke-release/gke-release/prometheus-engine/config-reloader:v0.18.1-gke.2@sha256:25c40417469953bd29e297733293bc1bc34d297e80dea7acc408492ba0d166d9" in 1.035s (1.035s including waiting). Image size: 25952761 bytes.
kube-system                   34m         Normal    Started                                  pod/gke-metrics-agent-gmz45                                        Container started
gmp-system                    34m         Normal    Started                                  pod/collector-n9zbf                                                Container started
gmp-system                    34m         Normal    Created                                  pod/collector-n9zbf                                                Container created
monitoring                    34m         Normal    Started                                  pod/prometheus-prometheus-node-exporter-rt8nh                      Container started
monitoring                    34m         Normal    Pulled                                   pod/prometheus-prometheus-node-exporter-rt8nh                      Successfully pulled image "quay.io/prometheus/node-exporter:v1.11.1" in 3.274s (21.172s including waiting). Image size: 13308798 bytes.
monitoring                    34m         Normal    Created                                  pod/prometheus-prometheus-node-exporter-rt8nh                      Container created
kube-system                   34m         Normal    Created                                  pod/fluentbit-gke-dwjg6                                            Container created
kube-system                   34m         Normal    Pulled                                   pod/fluentbit-gke-dwjg6                                            Successfully pulled image "europe-west3-artifactregistry.gcr.io/gke-release/gke-release/fluent-bit-gke-exporter:v0.27.17-gke.20@sha256:67269cb89dbf9cf4e76e199a634c178eec76e74ae45694e8000893f7cae6179e" in 6.154s (19.734s including waiting). Image size: 36248865 bytes.
kube-system                   34m         Normal    Started                                  pod/fluentbit-gke-dwjg6                                            Container started
kube-system                   34m         Normal    Created                                  pod/fluentbit-gke-dwjg6                                            Container created
kube-system                   34m         Normal    Pulled                                   pod/fluentbit-gke-dwjg6                                            Container image "europe-west3-artifactregistry.gcr.io/gke-release/gke-release/gke-metrics-collector:20260617_2300_RC0@sha256:c8cd71f5cd9f076b55e3f1db733e6adacd6ad3cfabaa9eb467b0ece8e691d73b" already present on machine and can be accessed by the pod
kube-system                   34m         Normal    Started                                  pod/fluentbit-gke-dwjg6                                            Container started
kube-system                   34m         Normal    Pulled                                   pod/pdcsi-node-vxdw7                                               Successfully pulled image "europe-west3-artifactregistry.gcr.io/gke-release/gke-release/gke-metrics-collector:20250311_2300_RC0@sha256:e6713a8266629d9e103f7b2c7715bf510170fe28ebe2dc341327fa5e6a0facde" in 5.772s (19.609s including waiting). Image size: 25809711 bytes.
kube-system                   34m         Normal    Created                                  pod/pdcsi-node-vxdw7                                               Container created
kube-system                   34m         Normal    Pulled                                   pod/node-local-dns-2zchx                                           Successfully pulled image "europe-west3-artifactregistry.gcr.io/gke-release/gke-release/k8s-dns-node-cache:1.26.8-gke.5@sha256:b466bc19f519bf5eb7ee278a57d33f9fdf253db8dd4e78677bd7b0373afcfea7" in 10.137s (21.477s including waiting). Image size: 52897804 bytes.
kube-system                   34m         Normal    Created                                  pod/node-local-dns-2zchx                                           Container created
kube-system                   34m         Normal    Started                                  pod/pdcsi-node-vxdw7                                               Container started
kube-system                   34m         Normal    Pulling                                  pod/node-local-dns-2zchx                                           Pulling image "europe-west3-artifactregistry.gcr.io/gke-release/gke-release/gke-metrics-collector:20260422_2300_RC0@sha256:70625564549ccc35d34e119dd3e3d5e2f841be9c309940d3ed5bb4e649a3c59f"
kube-system                   34m         Normal    Pulling                                  pod/pdcsi-node-vxdw7                                               Pulling image "europe-west3-artifactregistry.gcr.io/gke-release/gke-release/csi-node-driver-registrar:v2.15.0-gke.34@sha256:b38f4e46ad46c1f83f550d695812296b8d2d6a211c3fc0633f28979b0e958516"
kube-system                   34m         Normal    Started                                  pod/node-local-dns-2zchx                                           Container started
gmp-system                    34m         Normal    Pulled                                   pod/collector-hxvls                                                Successfully pulled image "europe-west3-artifactregistry.gcr.io/gke-release/gke-release/node_token_broker/init:gke_node_token_broker_init_20260714.00_p0@sha256:e3c8889fcbb07392d3b8a8ff0d4cf80310cb116628c7742061d7c71855c326cb" in 1.529s (17.819s including waiting). Image size: 3337442 bytes.
gmp-system                    34m         Normal    Created                                  pod/collector-hxvls                                                Container created
kube-system                   34m         Normal    SuccessfulDelete                         replicaset/metrics-server-v1.35.1-6559d8569d                       Deleted pod: metrics-server-v1.35.1-6559d8569d-vttnf
kube-system                   34m         Normal    ScalingReplicaSet                        deployment/metrics-server-v1.35.1                                  Scaled down replica set metrics-server-v1.35.1-6559d8569d from 1 to 0
kube-system                   34m         Normal    Killing                                  pod/metrics-server-v1.35.1-6559d8569d-vttnf                        Stopping container metrics-server
gmp-system                    34m         Normal    Started                                  pod/collector-hxvls                                                Container started
monitoring                    33m         Normal    Pulled                                   pod/prometheus-server-6858869b89-k2nmf                             Successfully pulled image "quay.io/prometheus-operator/prometheus-config-reloader:v0.91.0" in 7.018s (22.658s including waiting). Image size: 14230135 bytes.
monitoring                    33m         Normal    Created                                  pod/prometheus-server-6858869b89-k2nmf                             Container created
monitoring                    33m         Normal    Pulling                                  pod/prometheus-server-6858869b89-k2nmf                             Pulling image "quay.io/prometheus/prometheus:v3.11.3"
gmp-system                    33m         Normal    Pulling                                  pod/collector-hxvls                                                Pulling image "europe-west3-artifactregistry.gcr.io/gke-release/gke-release/prometheus-engine/prometheus:v2.53.5-gmp.5-gke.1@sha256:68038912eddca33347de1e85ffae8b785832303875957bd58d579a52ce8b6f93"
monitoring                    33m         Normal    Started                                  pod/prometheus-server-6858869b89-k2nmf                             Container started
traefik                       33m         Normal    EnsuredLoadBalancer                      service/traefik                                                    Ensured load balancer
monitoring                    33m         Normal    Created                                  pod/prometheus-kube-state-metrics-56c55854b6-2fr9p                 Container created
monitoring                    33m         Normal    Pulled                                   pod/prometheus-kube-state-metrics-56c55854b6-2fr9p                 Successfully pulled image "registry.k8s.io/kube-state-metrics/kube-state-metrics:v2.18.0" in 3.906s (25.895s including waiting). Image size: 19306162 bytes.
monitoring                    33m         Normal    Started                                  pod/prometheus-kube-state-metrics-56c55854b6-2fr9p                 Container started
traefik                       33m         Normal    Created                                  pod/traefik-586855547c-5snh2                                       Container created
traefik                       33m         Normal    Pulled                                   pod/traefik-586855547c-5snh2                                       Successfully pulled image "docker.io/traefik:v3.7.6" in 12.684s (28.449s including waiting). Image size: 53686680 bytes.
traefik                       33m         Normal    Started                                  pod/traefik-586855547c-5snh2                                       Container started
kube-system                   33m         Normal    Pulled                                   pod/konnectivity-agent-5446844985-6p5d7                            Successfully pulled image "europe-west3-artifactregistry.gcr.io/gke-release/gke-release/gke-metrics-collector:20260121_2300_RC0@sha256:3cbd2b897c681db94832b4e03e58e4e2168666259507ff8fb8ae43a01a3b5f5d" in 3.656s (27.198s including waiting). Image size: 26329267 bytes.
kube-system                   33m         Normal    Started                                  pod/konnectivity-agent-5446844985-6p5d7                            Container started
kube-system                   33m         Normal    Created                                  pod/konnectivity-agent-5446844985-6p5d7                            Container created
kube-system                   33m         Normal    Pulled                                   pod/node-local-dns-2zchx                                           Successfully pulled image "europe-west3-artifactregistry.gcr.io/gke-release/gke-release/gke-metrics-collector:20260422_2300_RC0@sha256:70625564549ccc35d34e119dd3e3d5e2f841be9c309940d3ed5bb4e649a3c59f" in 3.587s (15.843s including waiting). Image size: 26354407 bytes.
kube-system                   33m         Normal    Started                                  pod/pdcsi-node-vxdw7                                               Container started
kube-system                   33m         Normal    Created                                  pod/node-local-dns-2zchx                                           Container created
kube-system                   33m         Normal    Started                                  pod/node-local-dns-2zchx                                           Container started
kube-system                   33m         Normal    Pulled                                   pod/pdcsi-node-vxdw7                                               Successfully pulled image "europe-west3-artifactregistry.gcr.io/gke-release/gke-release/csi-node-driver-registrar:v2.15.0-gke.34@sha256:b38f4e46ad46c1f83f550d695812296b8d2d6a211c3fc0633f28979b0e958516" in 2.182s (15.241s including waiting). Image size: 14461369 bytes.
kube-system                   33m         Normal    Created                                  pod/pdcsi-node-vxdw7                                               Container created
voting                        33m         Normal    Provisioning                             persistentvolumeclaim/postgres-data-voting-voting-app-postgres-0   External provisioner is provisioning volume for claim "voting/postgres-data-voting-voting-app-postgres-0"
voting                        33m         Normal    Scheduled                                pod/voting-voting-app-result-5658d55654-lqfpp                      Successfully assigned voting/voting-voting-app-result-5658d55654-lqfpp to gke-portable-voting-default-pool-cc21b921-hl2v
voting                        33m         Normal    ScalingReplicaSet                        deployment/voting-voting-app-result                                Scaled up replica set voting-voting-app-result-5658d55654 from 0 to 2
voting                        33m         Normal    Scheduled                                pod/voting-voting-app-vote-66cf974bf6-4hzbd                        Successfully assigned voting/voting-voting-app-vote-66cf974bf6-4hzbd to gke-portable-voting-default-pool-cc21b921-hl2v
voting                        33m         Normal    ExternalProvisioning                     persistentvolumeclaim/postgres-data-voting-voting-app-postgres-0   Waiting for a volume to be created either by the external provisioner 'pd.csi.storage.gke.io' or manually by the system administrator. If volume creation is delayed, please verify that the provisioner is running and correctly registered.
voting                        33m         Normal    SuccessfulCreate                         replicaset/voting-voting-app-result-5658d55654                     Created pod: voting-voting-app-result-5658d55654-lqfpp
voting                        33m         Normal    SuccessfulCreate                         replicaset/voting-voting-app-worker-6fdd6777cc                     Created pod: voting-voting-app-worker-6fdd6777cc-nb882
voting                        33m         Normal    ScalingReplicaSet                        deployment/voting-voting-app-worker                                Scaled up replica set voting-voting-app-worker-6fdd6777cc from 0 to 1
voting                        33m         Normal    ScalingReplicaSet                        deployment/voting-voting-app-vote                                  Scaled up replica set voting-voting-app-vote-66cf974bf6 from 0 to 2
voting                        33m         Normal    SuccessfulCreate                         replicaset/voting-voting-app-vote-66cf974bf6                       Created pod: voting-voting-app-vote-66cf974bf6-4hzbd
voting                        33m         Normal    SuccessfulCreate                         replicaset/voting-voting-app-result-5658d55654                     Created pod: voting-voting-app-result-5658d55654-s67pv
voting                        33m         Normal    WaitForFirstConsumer                     persistentvolumeclaim/postgres-data-voting-voting-app-postgres-0   waiting for first consumer to be created before binding
voting                        33m         Normal    Scheduled                                pod/voting-voting-app-result-5658d55654-s67pv                      Successfully assigned voting/voting-voting-app-result-5658d55654-s67pv to gke-portable-voting-default-pool-cc21b921-xfjv
voting                        33m         Normal    SuccessfulCreate                         replicaset/voting-voting-app-vote-66cf974bf6                       Created pod: voting-voting-app-vote-66cf974bf6-cfccp
voting                        33m         Normal    Scheduled                                pod/voting-voting-app-vote-66cf974bf6-cfccp                        Successfully assigned voting/voting-voting-app-vote-66cf974bf6-cfccp to gke-portable-voting-default-pool-cc21b921-xfjv
voting                        33m         Normal    SuccessfulCreate                         statefulset/voting-voting-app-postgres                             Create Claim postgres-data-voting-voting-app-postgres-0 Pod voting-voting-app-postgres-0 in StatefulSet voting-voting-app-postgres success
voting                        33m         Normal    ScalingReplicaSet                        deployment/voting-voting-app-redis                                 Scaled up replica set voting-voting-app-redis-568f6f7d86 from 0 to 1
voting                        33m         Normal    Scheduled                                pod/voting-voting-app-worker-6fdd6777cc-nb882                      Successfully assigned voting/voting-voting-app-worker-6fdd6777cc-nb882 to gke-portable-voting-default-pool-cc21b921-xfjv
voting                        33m         Normal    SuccessfulCreate                         replicaset/voting-voting-app-redis-568f6f7d86                      Created pod: voting-voting-app-redis-568f6f7d86-np2sb
voting                        14m         Normal    SuccessfulCreate                         statefulset/voting-voting-app-postgres                             Create Pod voting-voting-app-postgres-0 in StatefulSet voting-voting-app-postgres successful
voting                        33m         Normal    Scheduled                                pod/voting-voting-app-redis-568f6f7d86-np2sb                       Successfully assigned voting/voting-voting-app-redis-568f6f7d86-np2sb to gke-portable-voting-default-pool-cc21b921-xfjv
voting                        33m         Normal    Pulling                                  pod/voting-voting-app-result-5658d55654-lqfpp                      Pulling image "ghcr.io/saudelm/kubernetes-portable-voting-app/result:0ababa3b5ff3d41b87d2094bbdd1994815fdefb4"
voting                        33m         Normal    Pulling                                  pod/voting-voting-app-vote-66cf974bf6-4hzbd                        Pulling image "ghcr.io/saudelm/kubernetes-portable-voting-app/vote:0ababa3b5ff3d41b87d2094bbdd1994815fdefb4"
voting                        33m         Normal    ProvisioningSucceeded                    persistentvolumeclaim/postgres-data-voting-voting-app-postgres-0   Successfully provisioned volume pvc-05060f0a-d593-4099-b0ea-b9a47296b845
voting                        33m         Normal    Pulling                                  pod/voting-voting-app-redis-568f6f7d86-np2sb                       Pulling image "redis:7.4.9-alpine"
voting                        33m         Normal    Scheduled                                pod/voting-voting-app-postgres-0                                   Successfully assigned voting/voting-voting-app-postgres-0 to gke-portable-voting-default-pool-cc21b921-xfjv
voting                        33m         Normal    Pulling                                  pod/voting-voting-app-vote-66cf974bf6-cfccp                        Pulling image "ghcr.io/saudelm/kubernetes-portable-voting-app/vote:0ababa3b5ff3d41b87d2094bbdd1994815fdefb4"
voting                        33m         Normal    Pulling                                  pod/voting-voting-app-result-5658d55654-s67pv                      Pulling image "ghcr.io/saudelm/kubernetes-portable-voting-app/result:0ababa3b5ff3d41b87d2094bbdd1994815fdefb4"
voting                        33m         Normal    Pulling                                  pod/voting-voting-app-worker-6fdd6777cc-nb882                      Pulling image "ghcr.io/saudelm/kubernetes-portable-voting-app/worker:0ababa3b5ff3d41b87d2094bbdd1994815fdefb4"
voting                        33m         Normal    SuccessfulAttachVolume                   pod/voting-voting-app-postgres-0                                   AttachVolume.Attach succeeded for volume "pvc-05060f0a-d593-4099-b0ea-b9a47296b845"
gmp-system                    33m         Normal    Pulling                                  pod/collector-hxvls                                                Pulling image "europe-west3-artifactregistry.gcr.io/gke-release/gke-release/prometheus-engine/config-reloader:v0.18.1-gke.2@sha256:25c40417469953bd29e297733293bc1bc34d297e80dea7acc408492ba0d166d9"
gmp-system                    33m         Normal    Pulled                                   pod/collector-hxvls                                                Successfully pulled image "europe-west3-artifactregistry.gcr.io/gke-release/gke-release/prometheus-engine/prometheus:v2.53.5-gmp.5-gke.1@sha256:68038912eddca33347de1e85ffae8b785832303875957bd58d579a52ce8b6f93" in 15.158s (24.92s including waiting). Image size: 146494435 bytes.
gmp-system                    33m         Normal    Created                                  pod/collector-hxvls                                                Container created
gmp-system                    33m         Normal    Started                                  pod/collector-hxvls                                                Container started
voting                        33m         Normal    Pulled                                   pod/voting-voting-app-vote-66cf974bf6-4hzbd                        Successfully pulled image "ghcr.io/saudelm/kubernetes-portable-voting-app/vote:0ababa3b5ff3d41b87d2094bbdd1994815fdefb4" in 9.14s (9.14s including waiting). Image size: 55415725 bytes.
voting                        25m         Normal    Created                                  pod/voting-voting-app-vote-66cf974bf6-4hzbd                        Container created
voting                        33m         Normal    Created                                  pod/voting-voting-app-result-5658d55654-lqfpp                      Container created
voting                        33m         Normal    Pulled                                   pod/voting-voting-app-result-5658d55654-lqfpp                      Successfully pulled image "ghcr.io/saudelm/kubernetes-portable-voting-app/result:0ababa3b5ff3d41b87d2094bbdd1994815fdefb4" in 10.292s (10.293s including waiting). Image size: 87788227 bytes.
voting                        25m         Normal    Started                                  pod/voting-voting-app-vote-66cf974bf6-4hzbd                        Container started
voting                        33m         Normal    Pulled                                   pod/voting-voting-app-redis-568f6f7d86-np2sb                       Successfully pulled image "redis:7.4.9-alpine" in 3.752s (9.992s including waiting). Image size: 16275739 bytes.
voting                        33m         Normal    Started                                  pod/voting-voting-app-result-5658d55654-lqfpp                      Container started
monitoring                    33m         Normal    Started                                  pod/prometheus-server-6858869b89-k2nmf                             Container started
voting                        33m         Normal    Pulling                                  pod/voting-voting-app-postgres-0                                   Pulling image "postgres:16.14-bookworm"
monitoring                    33m         Normal    Created                                  pod/prometheus-server-6858869b89-k2nmf                             Container created
voting                        33m         Normal    Created                                  pod/voting-voting-app-redis-568f6f7d86-np2sb                       Container created
voting                        33m         Normal    Started                                  pod/voting-voting-app-redis-568f6f7d86-np2sb                       Container started
monitoring                    33m         Normal    Pulled                                   pod/prometheus-server-6858869b89-k2nmf                             Successfully pulled image "quay.io/prometheus/prometheus:v3.11.3" in 18.968s (28.488s including waiting). Image size: 152919010 bytes.
voting                        28m         Warning   Unhealthy                                pod/voting-voting-app-vote-66cf974bf6-4hzbd                        Readiness probe failed: Get "http://10.68.0.16:8080/readyz": context deadline exceeded (Client.Timeout exceeded while awaiting headers)
voting                        33m         Normal    Started                                  pod/voting-voting-app-vote-66cf974bf6-cfccp                        Container started
voting                        33m         Normal    Created                                  pod/voting-voting-app-vote-66cf974bf6-cfccp                        Container created
voting                        33m         Normal    Pulled                                   pod/voting-voting-app-vote-66cf974bf6-cfccp                        Successfully pulled image "ghcr.io/saudelm/kubernetes-portable-voting-app/vote:0ababa3b5ff3d41b87d2094bbdd1994815fdefb4" in 11.783s (21.586s including waiting). Image size: 55415725 bytes.
voting                        33m         Normal    Created                                  pod/voting-voting-app-result-5658d55654-s67pv                      Container created
voting                        33m         Normal    Started                                  pod/voting-voting-app-result-5658d55654-s67pv                      Container started
voting                        28m         Warning   Unhealthy                                pod/voting-voting-app-result-5658d55654-lqfpp                      Readiness probe failed: Get "http://10.68.0.17:8080/readyz": context deadline exceeded (Client.Timeout exceeded while awaiting headers)
voting                        33m         Normal    Pulled                                   pod/voting-voting-app-result-5658d55654-s67pv                      Successfully pulled image "ghcr.io/saudelm/kubernetes-portable-voting-app/result:0ababa3b5ff3d41b87d2094bbdd1994815fdefb4" in 13.073s (22.68s including waiting). Image size: 87788227 bytes.
gmp-system                    33m         Normal    Pulled                                   pod/collector-hxvls                                                Successfully pulled image "europe-west3-artifactregistry.gcr.io/gke-release/gke-release/prometheus-engine/config-reloader:v0.18.1-gke.2@sha256:25c40417469953bd29e297733293bc1bc34d297e80dea7acc408492ba0d166d9" in 1.478s (17.653s including waiting). Image size: 25952761 bytes.
gmp-system                    33m         Normal    Created                                  pod/collector-hxvls                                                Container created
gmp-system                    33m         Normal    Started                                  pod/collector-hxvls                                                Container started
voting                        33m         Normal    Pulled                                   pod/voting-voting-app-worker-6fdd6777cc-nb882                      Successfully pulled image "ghcr.io/saudelm/kubernetes-portable-voting-app/worker:0ababa3b5ff3d41b87d2094bbdd1994815fdefb4" in 12.98s (34.433s including waiting). Image size: 84726050 bytes.
voting                        14m         Normal    Started                                  pod/voting-voting-app-worker-6fdd6777cc-nb882                      Container started
voting                        14m         Normal    Created                                  pod/voting-voting-app-worker-6fdd6777cc-nb882                      Container created
voting                        27m         Warning   Unhealthy                                pod/voting-voting-app-result-5658d55654-s67pv                      Readiness probe failed: Get "http://10.68.1.9:8080/readyz": context deadline exceeded (Client.Timeout exceeded while awaiting headers)
voting                        28m         Warning   Unhealthy                                pod/voting-voting-app-vote-66cf974bf6-cfccp                        Readiness probe failed: Get "http://10.68.1.10:8080/readyz": context deadline exceeded (Client.Timeout exceeded while awaiting headers)
voting                        33m         Normal    Created                                  pod/voting-voting-app-postgres-0                                   Container created
voting                        33m         Normal    Pulled                                   pod/voting-voting-app-postgres-0                                   Successfully pulled image "postgres:16.14-bookworm" in 16.409s (30.217s including waiting). Image size: 155087642 bytes.
voting                        32m         Normal    Started                                  pod/voting-voting-app-postgres-0                                   Container started
monitoring                    32m         Normal    ScalingReplicaSet                        deployment/grafana                                                 Scaled up replica set grafana-6c8cc49fbc from 0 to 1
monitoring                    32m         Normal    Scheduled                                pod/grafana-6c8cc49fbc-r4mqd                                       Successfully assigned monitoring/grafana-6c8cc49fbc-r4mqd to gke-portable-voting-default-pool-cc21b921-xfjv
monitoring                    32m         Normal    SuccessfulCreate                         replicaset/grafana-6c8cc49fbc                                      Created pod: grafana-6c8cc49fbc-r4mqd
monitoring                    32m         Normal    Pulling                                  pod/grafana-6c8cc49fbc-r4mqd                                       Pulling image "docker.io/curlimages/curl:8.9.1"
monitoring                    32m         Normal    Pulled                                   pod/grafana-6c8cc49fbc-r4mqd                                       Successfully pulled image "docker.io/curlimages/curl:8.9.1" in 1.226s (1.226s including waiting). Image size: 9384907 bytes.
monitoring                    32m         Normal    Started                                  pod/grafana-6c8cc49fbc-r4mqd                                       Container started
monitoring                    32m         Normal    Created                                  pod/grafana-6c8cc49fbc-r4mqd                                       Container created
monitoring                    32m         Normal    Pulling                                  pod/grafana-6c8cc49fbc-r4mqd                                       Pulling image "docker.io/grafana/grafana:12.3.1"
monitoring                    32m         Normal    Started                                  pod/grafana-6c8cc49fbc-r4mqd                                       Container started
monitoring                    32m         Normal    Created                                  pod/grafana-6c8cc49fbc-r4mqd                                       Container created
monitoring                    32m         Normal    Pulled                                   pod/grafana-6c8cc49fbc-r4mqd                                       Successfully pulled image "docker.io/grafana/grafana:12.3.1" in 14.75s (14.75s including waiting). Image size: 210410945 bytes.
monitoring                    32m         Warning   Unhealthy                                pod/grafana-6c8cc49fbc-r4mqd                                       Readiness probe failed: Get "http://10.68.1.13:3000/api/health": dial tcp 10.68.1.13:3000: connect: connection refused
voting                        32m         Warning   Unhealthy                                pod/voting-voting-app-vote-66cf974bf6-4hzbd                        Liveness probe failed: Get "http://10.68.0.16:8080/healthz": context deadline exceeded (Client.Timeout exceeded while awaiting headers)
voting                        32m         Warning   Unhealthy                                pod/voting-voting-app-vote-66cf974bf6-cfccp                        Liveness probe failed: Get "http://10.68.1.10:8080/healthz": context deadline exceeded (Client.Timeout exceeded while awaiting headers)
default                       28m         Warning   NodeRegistrationCheckerDidNotRunChecks   node/gke-portable-voting-default-pool-cc21b921-hl2v                Thu Aug 20 10:23:22 UTC 2026 - **     Node ready and registered. **
default                       28m         Warning   NodeRegistrationCheckerDidNotRunChecks   node/gke-portable-voting-default-pool-cc21b921-xfjv                Thu Aug 20 10:23:48 UTC 2026 - **     Node ready and registered. **
voting                        26m         Normal    Killing                                  pod/voting-voting-app-vote-66cf974bf6-4hzbd                        Container vote failed liveness probe, will be restarted
voting                        25m         Normal    Pulled                                   pod/voting-voting-app-vote-66cf974bf6-4hzbd                        Container image "ghcr.io/saudelm/kubernetes-portable-voting-app/vote:0ababa3b5ff3d41b87d2094bbdd1994815fdefb4" already present on machine and can be accessed by the pod
voting                        17m         Normal    ScalingReplicaSet                        deployment/voting-voting-app-vote                                  Scaled up replica set voting-voting-app-vote-6f8d556494 from 0 to 1
voting                        17m         Normal    Scheduled                                pod/voting-voting-app-vote-6f8d556494-vdfzh                        Successfully assigned voting/voting-voting-app-vote-6f8d556494-vdfzh to gke-portable-voting-default-pool-cc21b921-xfjv
voting                        17m         Normal    Scheduled                                pod/voting-voting-app-result-844994b44b-p7ml6                      Successfully assigned voting/voting-voting-app-result-844994b44b-p7ml6 to gke-portable-voting-default-pool-cc21b921-xfjv
voting                        17m         Normal    SuccessfulCreate                         replicaset/voting-voting-app-result-844994b44b                     Created pod: voting-voting-app-result-844994b44b-p7ml6
voting                        17m         Normal    SuccessfulCreate                         replicaset/voting-voting-app-vote-6f8d556494                       Created pod: voting-voting-app-vote-6f8d556494-vdfzh
voting                        17m         Normal    ScalingReplicaSet                        deployment/voting-voting-app-result                                Scaled up replica set voting-voting-app-result-844994b44b from 0 to 1
voting                        14m         Normal    Pulled                                   pod/voting-voting-app-result-844994b44b-p7ml6                      Container image "ghcr.io/saudelm/kubernetes-portable-voting-app/result:0ababa3b5ff3d41b87d2094bbdd1994815fdefb4" already present on machine and can be accessed by the pod
voting                        14m         Normal    Created                                  pod/voting-voting-app-result-844994b44b-p7ml6                      Container created
voting                        17m         Normal    Pulled                                   pod/voting-voting-app-vote-6f8d556494-vdfzh                        Container image "ghcr.io/saudelm/kubernetes-portable-voting-app/vote:0ababa3b5ff3d41b87d2094bbdd1994815fdefb4" already present on machine and can be accessed by the pod
voting                        17m         Normal    Created                                  pod/voting-voting-app-vote-6f8d556494-vdfzh                        Container created
voting                        17m         Normal    Started                                  pod/voting-voting-app-vote-6f8d556494-vdfzh                        Container started
voting                        14m         Normal    Started                                  pod/voting-voting-app-result-844994b44b-p7ml6                      Container started
voting                        17m         Normal    Scheduled                                pod/voting-voting-app-result-844994b44b-nvh6r                      Successfully assigned voting/voting-voting-app-result-844994b44b-nvh6r to gke-portable-voting-default-pool-cc21b921-hl2v
voting                        17m         Normal    SuccessfulDelete                         replicaset/voting-voting-app-result-5658d55654                     Deleted pod: voting-voting-app-result-5658d55654-s67pv
voting                        17m         Normal    ScalingReplicaSet                        deployment/voting-voting-app-vote                                  Scaled up replica set voting-voting-app-vote-6f8d556494 from 1 to 2
voting                        17m         Normal    Killing                                  pod/voting-voting-app-vote-66cf974bf6-cfccp                        Stopping container vote
voting                        17m         Normal    SuccessfulCreate                         replicaset/voting-voting-app-vote-6f8d556494                       Created pod: voting-voting-app-vote-6f8d556494-kll8g
voting                        17m         Normal    Killing                                  pod/voting-voting-app-result-5658d55654-s67pv                      Stopping container result
voting                        17m         Normal    ScalingReplicaSet                        deployment/voting-voting-app-vote                                  Scaled down replica set voting-voting-app-vote-66cf974bf6 from 2 to 1
voting                        17m         Normal    SuccessfulCreate                         replicaset/voting-voting-app-result-844994b44b                     Created pod: voting-voting-app-result-844994b44b-nvh6r
voting                        17m         Normal    SuccessfulDelete                         replicaset/voting-voting-app-vote-66cf974bf6                       Deleted pod: voting-voting-app-vote-66cf974bf6-cfccp
voting                        17m         Normal    ScalingReplicaSet                        deployment/voting-voting-app-result                                Scaled up replica set voting-voting-app-result-844994b44b from 1 to 2
voting                        17m         Normal    ScalingReplicaSet                        deployment/voting-voting-app-result                                Scaled down replica set voting-voting-app-result-5658d55654 from 2 to 1
voting                        17m         Normal    Scheduled                                pod/voting-voting-app-vote-6f8d556494-kll8g                        Successfully assigned voting/voting-voting-app-vote-6f8d556494-kll8g to gke-portable-voting-default-pool-cc21b921-hl2v
voting                        17m         Normal    Pulled                                   pod/voting-voting-app-vote-6f8d556494-kll8g                        Container image "ghcr.io/saudelm/kubernetes-portable-voting-app/vote:0ababa3b5ff3d41b87d2094bbdd1994815fdefb4" already present on machine and can be accessed by the pod
voting                        14m         Normal    Pulled                                   pod/voting-voting-app-result-844994b44b-nvh6r                      Container image "ghcr.io/saudelm/kubernetes-portable-voting-app/result:0ababa3b5ff3d41b87d2094bbdd1994815fdefb4" already present on machine and can be accessed by the pod
voting                        17m         Normal    Created                                  pod/voting-voting-app-vote-6f8d556494-kll8g                        Container created
voting                        14m         Normal    Started                                  pod/voting-voting-app-result-844994b44b-nvh6r                      Container started
voting                        17m         Normal    Started                                  pod/voting-voting-app-vote-6f8d556494-kll8g                        Container started
voting                        14m         Normal    Created                                  pod/voting-voting-app-result-844994b44b-nvh6r                      Container created
voting                        17m         Warning   Unhealthy                                pod/voting-voting-app-vote-66cf974bf6-cfccp                        Readiness probe failed: Get "http://10.68.1.10:8080/readyz": dial tcp 10.68.1.10:8080: connect: connection refused
voting                        17m         Normal    ScalingReplicaSet                        deployment/voting-voting-app-result                                Scaled down replica set voting-voting-app-result-5658d55654 from 1 to 0
voting                        17m         Normal    SuccessfulDelete                         replicaset/voting-voting-app-result-5658d55654                     Deleted pod: voting-voting-app-result-5658d55654-lqfpp
voting                        17m         Normal    Killing                                  pod/voting-voting-app-result-5658d55654-lqfpp                      Stopping container result
voting                        17m         Warning   Unhealthy                                pod/voting-voting-app-vote-6f8d556494-kll8g                        Readiness probe failed: Get "http://10.68.0.19:8080/readyz": context deadline exceeded (Client.Timeout exceeded while awaiting headers)
voting                        17m         Normal    SuccessfulDelete                         replicaset/voting-voting-app-vote-66cf974bf6                       Deleted pod: voting-voting-app-vote-66cf974bf6-4hzbd
voting                        17m         Normal    Killing                                  pod/voting-voting-app-vote-66cf974bf6-4hzbd                        Stopping container vote
voting                        17m         Normal    ScalingReplicaSet                        deployment/voting-voting-app-vote                                  Scaled down replica set voting-voting-app-vote-66cf974bf6 from 1 to 0
voting                        16m         Warning   Unhealthy                                pod/voting-voting-app-vote-66cf974bf6-4hzbd                        Readiness probe failed: Get "http://10.68.0.16:8080/readyz": dial tcp 10.68.0.16:8080: connect: connection refused
voting                        14m         Normal    Killing                                  pod/voting-voting-app-postgres-0                                   Stopping container postgres
voting                        14m         Normal    Scheduled                                pod/voting-voting-app-postgres-0                                   Successfully assigned voting/voting-voting-app-postgres-0 to gke-portable-voting-default-pool-cc21b921-xfjv
voting                        14m         Normal    Pulled                                   pod/voting-voting-app-worker-6fdd6777cc-nb882                      Container image "ghcr.io/saudelm/kubernetes-portable-voting-app/worker:0ababa3b5ff3d41b87d2094bbdd1994815fdefb4" already present on machine and can be accessed by the pod
voting                        14m         Normal    Created                                  pod/voting-voting-app-postgres-0                                   Container created
voting                        14m         Normal    Started                                  pod/voting-voting-app-postgres-0                                   Container started
voting                        14m         Normal    Pulled                                   pod/voting-voting-app-postgres-0                                   Container image "postgres:16.14-bookworm" already present on machine and can be accessed by the pod
voting                        14m         Warning   Unhealthy                                pod/voting-voting-app-result-844994b44b-p7ml6                      Readiness probe failed: Get "http://10.68.1.15:8080/readyz": context deadline exceeded (Client.Timeout exceeded while awaiting headers)
voting                        14m         Warning   Unhealthy                                pod/voting-voting-app-result-844994b44b-nvh6r                      Readiness probe failed: Get "http://10.68.0.18:8080/readyz": context deadline exceeded (Client.Timeout exceeded while awaiting headers)
voting                        13m         Normal    Killing                                  pod/voting-voting-app-vote-6f8d556494-vdfzh                        Stopping container vote
voting                        13m         Normal    SuccessfulCreate                         replicaset/voting-voting-app-vote-6f8d556494                       Created pod: voting-voting-app-vote-6f8d556494-fd6lw
voting                        13m         Normal    Killing                                  pod/voting-voting-app-vote-6f8d556494-kll8g                        Stopping container vote
voting                        13m         Normal    SuccessfulCreate                         replicaset/voting-voting-app-vote-6f8d556494                       Created pod: voting-voting-app-vote-6f8d556494-fjtn4
voting                        13m         Normal    Scheduled                                pod/voting-voting-app-vote-6f8d556494-fjtn4                        Successfully assigned voting/voting-voting-app-vote-6f8d556494-fjtn4 to gke-portable-voting-default-pool-cc21b921-hl2v
voting                        13m         Normal    Scheduled                                pod/voting-voting-app-vote-6f8d556494-fd6lw                        Successfully assigned voting/voting-voting-app-vote-6f8d556494-fd6lw to gke-portable-voting-default-pool-cc21b921-xfjv
voting                        13m         Warning   Unhealthy                                pod/voting-voting-app-vote-6f8d556494-vdfzh                        Readiness probe failed: Get "http://10.68.1.14:8080/readyz": context deadline exceeded (Client.Timeout exceeded while awaiting headers)
voting                        13m         Normal    Pulled                                   pod/voting-voting-app-vote-6f8d556494-fd6lw                        Container image "ghcr.io/saudelm/kubernetes-portable-voting-app/vote:0ababa3b5ff3d41b87d2094bbdd1994815fdefb4" already present on machine and can be accessed by the pod
voting                        13m         Normal    Created                                  pod/voting-voting-app-vote-6f8d556494-fd6lw                        Container created
voting                        13m         Normal    Started                                  pod/voting-voting-app-vote-6f8d556494-fd6lw                        Container started
voting                        13m         Normal    Created                                  pod/voting-voting-app-vote-6f8d556494-fjtn4                        Container created
voting                        13m         Normal    Pulled                                   pod/voting-voting-app-vote-6f8d556494-fjtn4                        Container image "ghcr.io/saudelm/kubernetes-portable-voting-app/vote:0ababa3b5ff3d41b87d2094bbdd1994815fdefb4" already present on machine and can be accessed by the pod
voting                        13m         Normal    Started                                  pod/voting-voting-app-vote-6f8d556494-fjtn4                        Container started
voting                        13m         Warning   Unhealthy                                pod/voting-voting-app-vote-6f8d556494-kll8g                        Readiness probe failed: Get "http://10.68.0.19:8080/readyz": dial tcp 10.68.0.19:8080: connect: connection refused
voting                        101s        Warning   Unhealthy                                pod/voting-voting-app-vote-6f8d556494-fd6lw                        Readiness probe failed: Get "http://10.68.1.17:8080/readyz": context deadline exceeded (Client.Timeout exceeded while awaiting headers)
voting                        87s         Warning   Unhealthy                                pod/voting-voting-app-vote-6f8d556494-fjtn4                        Readiness probe failed: Get "http://10.68.0.20:8080/readyz": context deadline exceeded (Client.Timeout exceeded while awaiting headers)
voting                        2m20s       Normal    Scheduled                                pod/voting-voting-app-vote-56985d774-vpxw6                         Successfully assigned voting/voting-voting-app-vote-56985d774-vpxw6 to gke-portable-voting-default-pool-cc21b921-xfjv
voting                        2m20s       Normal    ScalingReplicaSet                        deployment/voting-voting-app-vote                                  Scaled up replica set voting-voting-app-vote-56985d774 from 0 to 1
voting                        2m20s       Normal    ScalingReplicaSet                        deployment/voting-voting-app-result                                Scaled up replica set voting-voting-app-result-7b75bbbf4 from 0 to 1
voting                        2m20s       Normal    SuccessfulCreate                         replicaset/voting-voting-app-vote-56985d774                        Created pod: voting-voting-app-vote-56985d774-vpxw6
voting                        2m20s       Normal    Scheduled                                pod/voting-voting-app-result-7b75bbbf4-xwlcj                       Successfully assigned voting/voting-voting-app-result-7b75bbbf4-xwlcj to gke-portable-voting-default-pool-cc21b921-xfjv
voting                        2m20s       Normal    ScalingReplicaSet                        deployment/voting-voting-app-worker                                Scaled up replica set voting-voting-app-worker-7565f496d5 from 0 to 1
voting                        2m20s       Normal    SuccessfulCreate                         replicaset/voting-voting-app-worker-7565f496d5                     Created pod: voting-voting-app-worker-7565f496d5-xvjlv
voting                        2m20s       Normal    Scheduled                                pod/voting-voting-app-worker-7565f496d5-xvjlv                      Successfully assigned voting/voting-voting-app-worker-7565f496d5-xvjlv to gke-portable-voting-default-pool-cc21b921-xfjv
voting                        2m20s       Normal    SuccessfulCreate                         replicaset/voting-voting-app-result-7b75bbbf4                      Created pod: voting-voting-app-result-7b75bbbf4-xwlcj
voting                        2m18s       Normal    Pulling                                  pod/voting-voting-app-result-7b75bbbf4-xwlcj                       Pulling image "ghcr.io/saudelm/kubernetes-portable-voting-app/result:82cde44a838d36f07cc47d9f29351d039cdf0244"
voting                        2m17s       Normal    Pulling                                  pod/voting-voting-app-worker-7565f496d5-xvjlv                      Pulling image "ghcr.io/saudelm/kubernetes-portable-voting-app/worker:82cde44a838d36f07cc47d9f29351d039cdf0244"
voting                        2m17s       Normal    Pulling                                  pod/voting-voting-app-vote-56985d774-vpxw6                         Pulling image "ghcr.io/saudelm/kubernetes-portable-voting-app/vote:82cde44a838d36f07cc47d9f29351d039cdf0244"
voting                        2m10s       Normal    Pulled                                   pod/voting-voting-app-vote-56985d774-vpxw6                         Successfully pulled image "ghcr.io/saudelm/kubernetes-portable-voting-app/vote:82cde44a838d36f07cc47d9f29351d039cdf0244" in 7.687s (7.687s including waiting). Image size: 55415724 bytes.
voting                        2m10s       Normal    Pulled                                   pod/voting-voting-app-result-7b75bbbf4-xwlcj                       Successfully pulled image "ghcr.io/saudelm/kubernetes-portable-voting-app/result:82cde44a838d36f07cc47d9f29351d039cdf0244" in 8.079s (8.079s including waiting). Image size: 87788198 bytes.
voting                        2m9s        Normal    Created                                  pod/voting-voting-app-result-7b75bbbf4-xwlcj                       Container created
voting                        2m9s        Normal    Started                                  pod/voting-voting-app-result-7b75bbbf4-xwlcj                       Container started
voting                        2m9s        Normal    Started                                  pod/voting-voting-app-vote-56985d774-vpxw6                         Container started
voting                        2m9s        Normal    Created                                  pod/voting-voting-app-vote-56985d774-vpxw6                         Container created
voting                        2m7s        Normal    Pulled                                   pod/voting-voting-app-worker-7565f496d5-xvjlv                      Successfully pulled image "ghcr.io/saudelm/kubernetes-portable-voting-app/worker:82cde44a838d36f07cc47d9f29351d039cdf0244" in 3.011s (10.632s including waiting). Image size: 84726048 bytes.
voting                        2m6s        Normal    Started                                  pod/voting-voting-app-worker-7565f496d5-xvjlv                      Container started
voting                        2m6s        Normal    Created                                  pod/voting-voting-app-worker-7565f496d5-xvjlv                      Container created
voting                        2m5s        Normal    ScalingReplicaSet                        deployment/voting-voting-app-worker                                Scaled down replica set voting-voting-app-worker-6fdd6777cc from 1 to 0
voting                        2m5s        Normal    SuccessfulDelete                         replicaset/voting-voting-app-worker-6fdd6777cc                     Deleted pod: voting-voting-app-worker-6fdd6777cc-nb882
voting                        2m5s        Normal    Killing                                  pod/voting-voting-app-worker-6fdd6777cc-nb882                      Stopping container worker
voting                        116s        Normal    SuccessfulDelete                         replicaset/voting-voting-app-result-844994b44b                     Deleted pod: voting-voting-app-result-844994b44b-p7ml6
voting                        116s        Normal    SuccessfulCreate                         replicaset/voting-voting-app-result-7b75bbbf4                      Created pod: voting-voting-app-result-7b75bbbf4-xgj2g
voting                        116s        Warning   Unhealthy                                pod/voting-voting-app-vote-56985d774-vpxw6                         Readiness probe failed: Get "http://10.68.1.19:8080/readyz": context deadline exceeded (Client.Timeout exceeded while awaiting headers)
voting                        116s        Normal    ScalingReplicaSet                        deployment/voting-voting-app-result                                Scaled up replica set voting-voting-app-result-7b75bbbf4 from 1 to 2
voting                        116s        Normal    Scheduled                                pod/voting-voting-app-result-7b75bbbf4-xgj2g                       Successfully assigned voting/voting-voting-app-result-7b75bbbf4-xgj2g to gke-portable-voting-default-pool-cc21b921-hl2v
voting                        116s        Normal    Killing                                  pod/voting-voting-app-result-844994b44b-p7ml6                      Stopping container result
voting                        116s        Normal    ScalingReplicaSet                        deployment/voting-voting-app-result                                Scaled down replica set voting-voting-app-result-844994b44b from 2 to 1
voting                        115s        Normal    Pulling                                  pod/voting-voting-app-result-7b75bbbf4-xgj2g                       Pulling image "ghcr.io/saudelm/kubernetes-portable-voting-app/result:82cde44a838d36f07cc47d9f29351d039cdf0244"
voting                        110s        Normal    Started                                  pod/voting-voting-app-result-7b75bbbf4-xgj2g                       Container started
voting                        110s        Normal    Pulled                                   pod/voting-voting-app-result-7b75bbbf4-xgj2g                       Successfully pulled image "ghcr.io/saudelm/kubernetes-portable-voting-app/result:82cde44a838d36f07cc47d9f29351d039cdf0244" in 4.217s (4.217s including waiting). Image size: 87788198 bytes.
voting                        110s        Normal    Created                                  pod/voting-voting-app-result-7b75bbbf4-xgj2g                       Container created
voting                        107s        Normal    Scheduled                                pod/voting-voting-app-vote-56985d774-lqcp6                         Successfully assigned voting/voting-voting-app-vote-56985d774-lqcp6 to gke-portable-voting-default-pool-cc21b921-hl2v
voting                        107s        Normal    SuccessfulCreate                         replicaset/voting-voting-app-vote-56985d774                        Created pod: voting-voting-app-vote-56985d774-lqcp6
voting                        107s        Normal    SuccessfulDelete                         replicaset/voting-voting-app-vote-6f8d556494                       Deleted pod: voting-voting-app-vote-6f8d556494-fd6lw
voting                        107s        Normal    Killing                                  pod/voting-voting-app-vote-6f8d556494-fd6lw                        Stopping container vote
voting                        107s        Normal    ScalingReplicaSet                        deployment/voting-voting-app-vote                                  Scaled down replica set voting-voting-app-vote-6f8d556494 from 2 to 1
voting                        107s        Normal    ScalingReplicaSet                        deployment/voting-voting-app-vote                                  Scaled up replica set voting-voting-app-vote-56985d774 from 1 to 2
voting                        106s        Normal    Pulling                                  pod/voting-voting-app-vote-56985d774-lqcp6                         Pulling image "ghcr.io/saudelm/kubernetes-portable-voting-app/vote:82cde44a838d36f07cc47d9f29351d039cdf0244"
voting                        102s        Normal    Created                                  pod/voting-voting-app-vote-56985d774-lqcp6                         Container created
voting                        102s        Normal    Pulled                                   pod/voting-voting-app-vote-56985d774-lqcp6                         Successfully pulled image "ghcr.io/saudelm/kubernetes-portable-voting-app/vote:82cde44a838d36f07cc47d9f29351d039cdf0244" in 4.014s (4.014s including waiting). Image size: 55415724 bytes.
voting                        101s        Normal    Started                                  pod/voting-voting-app-vote-56985d774-lqcp6                         Container started
voting                        97s         Normal    SuccessfulDelete                         replicaset/voting-voting-app-result-844994b44b                     Deleted pod: voting-voting-app-result-844994b44b-nvh6r
voting                        97s         Normal    ScalingReplicaSet                        deployment/voting-voting-app-result                                Scaled down replica set voting-voting-app-result-844994b44b from 1 to 0
voting                        97s         Normal    Killing                                  pod/voting-voting-app-result-844994b44b-nvh6r                      Stopping container result
voting                        89s         Normal    ScalingReplicaSet                        deployment/voting-voting-app-vote                                  Scaled down replica set voting-voting-app-vote-6f8d556494 from 1 to 0
voting                        89s         Normal    SuccessfulDelete                         replicaset/voting-voting-app-vote-6f8d556494                       Deleted pod: voting-voting-app-vote-6f8d556494-fjtn4
voting                        89s         Normal    Killing                                  pod/voting-voting-app-vote-6f8d556494-fjtn4                        Stopping container vote
